Workbook
Name _dbKpName: OFFSET(ダッシュボード!$W$3,0,0,MAX(1,COUNT(ダッシュボード!$X$3:$X$62)),1)
Name _dbKpVal: OFFSET(ダッシュボード!$X$3,0,0,MAX(1,COUNT(ダッシュボード!$X$3:$X$62)),1)
Name _dbMixLbl: OFFSET(ダッシュボード!$AZ$3,0,0,MAX(1,COUNT(ダッシュボード!$AX$3:$AX$5)),1)
Name _dbMixVal: OFFSET(ダッシュボード!$AX$3,0,0,MAX(1,COUNT(ダッシュボード!$AX$3:$AX$5)),1)
Name _dbPkName: OFFSET(ダッシュボード!$U$3,0,0,MAX(1,COUNT(ダッシュボード!$V$3:$V$62)),1)
Name _dbPkVal: OFFSET(ダッシュボード!$V$3,0,0,MAX(1,COUNT(ダッシュボード!$V$3:$V$62)),1)
Name _dbS1x: OFFSET(ダッシュボード!$AF$3,0,0,MAX(1,COUNT(ダッシュボード!$AF$3:$AF$62)),1)
Name _dbS1y: OFFSET(ダッシュボード!$AG$3,0,0,MAX(1,COUNT(ダッシュボード!$AF$3:$AF$62)),1)
Name _dbS2x: OFFSET(ダッシュボード!$AK$3,0,0,MAX(1,COUNT(ダッシュボード!$AK$3:$AK$62)),1)
Name _dbS2y: OFFSET(ダッシュボード!$AL$3,0,0,MAX(1,COUNT(ダッシュボード!$AK$3:$AK$62)),1)
Name _dbTopName: OFFSET(ダッシュボード!$AS$3,0,0,MAX(1,COUNT(ダッシュボード!$AU$3:$AU$14)),1)
Name _dbTopPure: OFFSET(ダッシュボード!$AU$3,0,0,MAX(1,COUNT(ダッシュボード!$AU$3:$AU$14)),1)
Name _dbTopRaw: OFFSET(ダッシュボード!$AT$3,0,0,MAX(1,COUNT(ダッシュボード!$AU$3:$AU$14)),1)
Name _dyLabel: OFFSET(日次!$C$8,0,0,MAX(1,COUNT(日次!$P$8:$P$28)),1)
Name _dyPackEff: OFFSET(日次!$K$8,0,0,MAX(1,COUNT(日次!$P$8:$P$28)),1)
Name _dyPickEff: OFFSET(日次!$G$8,0,0,MAX(1,COUNT(日次!$P$8:$P$28)),1)
Name _s1x: OFFSET(散布図!$AE$8,0,0,MAX(1,COUNT(散布図!$AE$8:$AE$67)),1)
Name _s1y: OFFSET(散布図!$AF$8,0,0,MAX(1,COUNT(散布図!$AE$8:$AE$67)),1)
Name _s2x: OFFSET(散布図!$AI$8,0,0,MAX(1,COUNT(散布図!$AI$8:$AI$67)),1)
Name _s2y: OFFSET(散布図!$AJ$8,0,0,MAX(1,COUNT(散布図!$AI$8:$AI$67)),1)
Name _s3x: OFFSET(散布図!$AM$8,0,0,MAX(1,COUNT(散布図!$AM$8:$AM$67)),1)
Name _s3y: OFFSET(散布図!$AN$8,0,0,MAX(1,COUNT(散布図!$AM$8:$AM$67)),1)
Name _s4x: OFFSET(散布図!$AQ$8,0,0,MAX(1,COUNT(散布図!$AQ$8:$AQ$67)),1)
Name _s4y: OFFSET(散布図!$AR$8,0,0,MAX(1,COUNT(散布図!$AQ$8:$AQ$67)),1)
Name _s5x: OFFSET(散布図!$BE$8,0,0,MAX(1,COUNT(散布図!$BE$8:$BE$67)),1)
Name _s5y: OFFSET(散布図!$BF$8,0,0,MAX(1,COUNT(散布図!$BE$8:$BE$67)),1)
Name _s6x: OFFSET(散布図!$BJ$8,0,0,MAX(1,COUNT(散布図!$BJ$8:$BJ$67)),1)
Name _s6y: OFFSET(散布図!$BK$8,0,0,MAX(1,COUNT(散布図!$BJ$8:$BJ$67)),1)
Name _s6z: OFFSET(散布図!$BL$8,0,0,MAX(1,COUNT(散布図!$BJ$8:$BJ$67)),1)

Sheet ダッシュボード
T1: ▼ グラフ用データ 消したり非表示にしたりしないでください
B2: 2026年4月 庫内作業レビュー | G2: 2026/04/01 – 2026/04/30 21日 | T2: 順位 | U2: PK 氏名 | V2: PK 効率 | W2: 梱包 氏名 | X2: 梱包 効率 | Z2: PK 社/件 | AA2: PK 素の秒/件 | AB2: PK 純速度 | AD2: 対フラグ | AE2: 対番号 | AF2: ① x | AG2: ① y | AI2: 対フラグ | AJ2: 対番号 | AK2: ② x | AL2: ② y | AN2: 件数キー | AO2: 上位12 氏名 | AP2: 上位12 素の秒/件 | AQ2: 上位12 純速度 | AR2: 純速度キー | AS2: 表示 氏名 | AT2: 表示 素の秒/件 | AU2: 表示 純速度 | AW2: 内訳 ラベル | AX2: 時間 | AY2: 割合 | AZ2: 凡例テキスト
B3: オペレーション概要 ピッキングと梱包を、段取り時間を切り分けて評価しています。 | G3: 対象 29名・45,716件・完全記録 21日分 | T3: 1 | U3: =IFERROR(INDEX(ピッキング!$B$7:$B$66,MATCH($T3,ピッキング!$A$7:$A$66,0)),"") -> 本吉有美子 | V3: =IFERROR(INDEX(ピッキング!$L$7:$L$66,MATCH($T3,ピッキング!$A$7:$A$66,0)),"") -> 127.28975 | W3: =IFERROR(INDEX(梱包!$B$7:$B$66,MATCH($T3,梱包!$A$7:$A$66,0)),"") -> 佐々木千恵 | X3: =IFERROR(INDEX(梱包!$L$7:$L$66,MATCH($T3,梱包!$A$7:$A$66,0)),"") -> 160.1084 | Z3: =IF(OR(ピッキング!$E$7="",ピッキング!$C$7=""),"",ピッキング!$E$7/ピッキング!$C$7) -> 0.42022008 | AA3: =IF(ピッキング!$G$7="","",ピッキング!$G$7) -> 83.686382 | AB3: =IF(ピッキング!$P$7="","",ピッキング!$P$7) -> 44.984113 | AD3: =IF(AND(ISNUMBER(Z3),ISNUMBER(AA3)),1,0) -> 1 | AE3: =IF(AD3=1,SUM($AD$3:AD3),"") -> 1 | AF3: =IFERROR(INDEX($Z$3:$Z$62,MATCH(T3,$AE$3:$AE$62,0)),"") -> 0.42022008 | AG3: =IFERROR(INDEX($AA$3:$AA$62,MATCH(T3,$AE$3:$AE$62,0)),"") -> 83.686382 | AI3: =IF(AND(ISNUMBER(Z3),ISNUMBER(AB3)),1,0) -> 1 | AJ3: =IF(AI3=1,SUM($AI$3:AI3),"") -> 1 | AK3: =IFERROR(INDEX($Z$3:$Z$62,MATCH(T3,$AJ$3:$AJ$62,0)),"") -> 0.42022008 | AL3: =IFERROR(INDEX($AB$3:$AB$62,MATCH(T3,$AJ$3:$AJ$62,0)),"") -> 44.984113 | AN3: =IF(ピッキング!$C$7="","",ピッキング!$C$7+ROW()/100000) -> 1454 | AO3: =IFERROR(INDEX(ピッキング!$B$7:$B$66,MATCH(LARGE($AN$3:$AN$62,ROW()-2),$AN$3:$AN$62,0)),"") -> 山本祥吉 | AP3: =IFERROR(INDEX(ピッキング!$G$7:$G$66,MATCH(LARGE($AN$3:$AN$62,ROW()-2),$AN$3:$AN$62,0)),"") -> 101.14608 | AQ3: =IFERROR(INDEX(ピッキング!$P$7:$P$66,MATCH(LARGE($AN$3:$AN$62,ROW()-2),$AN$3:$AN$62,0)),"") -> 69.306905 | AR3: =IF(AQ3="","",AQ3+ROW()/100000) -> 69.306935 | AS3: =IFERROR(INDEX($AO$3:$AO$14,MATCH(LARGE($AR$3:$AR$14,ROW()-2),$AR$3:$AR$14,0)),"") -> 上村和恵 | AT3: =IFERROR(INDEX($AP$3:$AP$14,MATCH(LARGE($AR$3:$AR$14,ROW()-2),$AR$3:$AR$14,0)),"") -> 143.79496 | AU3: =IFERROR(INDEX($AQ$3:$AQ$14,MATCH(LARGE($AR$3:$AR$14,ROW()-2),$AR$3:$AR$14,0)),"") -> 105.28192 | AW3: 段取り | AX3: 233.2 | AY3: =IFERROR(AX3/SUM($AX$3:$AX$5),"") -> 0.34324404 | AZ3: =AW3&" "&ROUND(AX3,1)&"h・"&ROUND(AY3*100,1)&"%" -> 段取り 233.2h・34.3%
B4: 件数だけで並べると、1社1個のリストを多く引いた人ほど不利に出ます。 | T4: 2 | U4: =IFERROR(INDEX(ピッキング!$B$7:$B$66,MATCH($T4,ピッキング!$A$7:$A$66,0)),"") -> 澤田凌 | V4: =IFERROR(INDEX(ピッキング!$L$7:$L$66,MATCH($T4,ピッキング!$A$7:$A$66,0)),"") -> 124.86053 | W4: =IFERROR(INDEX(梱包!$B$7:$B$66,MATCH($T4,梱包!$A$7:$A$66,0)),"") -> 本吉有美子 | X4: =IFERROR(INDEX(梱包!$L$7:$L$66,MATCH($T4,梱包!$A$7:$A$66,0)),"") -> 146.61995 | Z4: =IF(OR(ピッキング!$E$8="",ピッキング!$C$8=""),"",ピッキング!$E$8/ピッキング!$C$8) -> 0.60126582 | AA4: =IF(ピッキング!$G$8="","",ピッキング!$G$8) -> 94.556962 | AB4: =IF(ピッキング!$P$8="","",ピッキング!$P$8) -> 39.18038 | AD4: =IF(AND(ISNUMBER(Z4),ISNUMBER(AA4)),1,0) -> 1 | AE4: =IF(AD4=1,SUM($AD$3:AD4),"") -> 2 | AF4: =IFERROR(INDEX($Z$3:$Z$62,MATCH(T4,$AE$3:$AE$62,0)),"") -> 0.60126582 | AG4: =IFERROR(INDEX($AA$3:$AA$62,MATCH(T4,$AE$3:$AE$62,0)),"") -> 94.556962 | AI4: =IF(AND(ISNUMBER(Z4),ISNUMBER(AB4)),1,0) -> 1 | AJ4: =IF(AI4=1,SUM($AI$3:AI4),"") -> 2 | AK4: =IFERROR(INDEX($Z$3:$Z$62,MATCH(T4,$AJ$3:$AJ$62,0)),"") -> 0.60126582 | AL4: =IFERROR(INDEX($AB$3:$AB$62,MATCH(T4,$AJ$3:$AJ$62,0)),"") -> 39.18038 | AN4: =IF(ピッキング!$C$8="","",ピッキング!$C$8+ROW()/100000) -> 790.00004 | AO4: =IFERROR(INDEX(ピッキング!$B$7:$B$66,MATCH(LARGE($AN$3:$AN$62,ROW()-2),$AN$3:$AN$62,0)),"") -> 後藤克行 | AP4: =IFERROR(INDEX(ピッキング!$G$7:$G$66,MATCH(LARGE($AN$3:$AN$62,ROW()-2),$AN$3:$AN$62,0)),"") -> 107.17489 | AQ4: =IFERROR(INDEX(ピッキング!$P$7:$P$66,MATCH(LARGE($AN$3:$AN$62,ROW()-2),$AN$3:$AN$62,0)),"") -> 63.166966 | AR4: =IF(AQ4="","",AQ4+ROW()/100000) -> 63.167006 | AS4: =IFERROR(INDEX($AO$3:$AO$14,MATCH(LARGE($AR$3:$AR$14,ROW()-2),$AR$3:$AR$14,0)),"") -> 秋草文恵 | AT4: =IFERROR(INDEX($AP$3:$AP$14,MATCH(LARGE($AR$3:$AR$14,ROW()-2),$AR$3:$AR$14,0)),"") -> 146.43357 | AU4: =IFERROR(INDEX($AQ$3:$AQ$14,MATCH(LARGE($AR$3:$AR$14,ROW()-2),$AR$3:$AR$14,0)),"") -> 104.46259 | AW4: 移動 | AX4: 223.1 | AY4: =IFERROR(AX4/SUM($AX$3:$AX$5),"") -> 0.32837798 | AZ4: =AW4&" "&ROUND(AX4,1)&"h・"&ROUND(AY4*100,1)&"%" -> 移動 223.1h・32.8%
T5: 3 | U5: =IFERROR(INDEX(ピッキング!$B$7:$B$66,MATCH($T5,ピッキング!$A$7:$A$66,0)),"") -> 大江美記子 | V5: =IFERROR(INDEX(ピッキング!$L$7:$L$66,MATCH($T5,ピッキング!$A$7:$A$66,0)),"") -> 120.9542 | W5: =IFERROR(INDEX(梱包!$B$7:$B$66,MATCH($T5,梱包!$A$7:$A$66,0)),"") -> 北田倫子 | X5: =IFERROR(INDEX(梱包!$L$7:$L$66,MATCH($T5,梱包!$A$7:$A$66,0)),"") -> 133.19601 | Z5: =IF(OR(ピッキング!$E$9="",ピッキング!$C$9=""),"",ピッキング!$E$9/ピッキング!$C$9) -> 0.490316 | AA5: =IF(ピッキング!$G$9="","",ピッキング!$G$9) -> 93.883792 | AB5: =IF(ピッキング!$P$9="","",ピッキング!$P$9) -> 48.725688 | AD5: =IF(AND(ISNUMBER(Z5),ISNUMBER(AA5)),1,0) -> 1 | AE5: =IF(AD5=1,SUM($AD$3:AD5),"") -> 3 | AF5: =IFERROR(INDEX($Z$3:$Z$62,MATCH(T5,$AE$3:$AE$62,0)),"") -> 0.490316 | AG5: =IFERROR(INDEX($AA$3:$AA$62,MATCH(T5,$AE$3:$AE$62,0)),"") -> 93.883792 | AI5: =IF(AND(ISNUMBER(Z5),ISNUMBER(AB5)),1,0) -> 1 | AJ5: =IF(AI5=1,SUM($AI$3:AI5),"") -> 3 | AK5: =IFERROR(INDEX($Z$3:$Z$62,MATCH(T5,$AJ$3:$AJ$62,0)),"") -> 0.490316 | AL5: =IFERROR(INDEX($AB$3:$AB$62,MATCH(T5,$AJ$3:$AJ$62,0)),"") -> 48.725688 | AN5: =IF(ピッキング!$C$9="","",ピッキング!$C$9+ROW()/100000) -> 981.00005 | AO5: =IFERROR(INDEX(ピッキング!$B$7:$B$66,MATCH(LARGE($AN$3:$AN$62,ROW()-2),$AN$3:$AN$62,0)),"") -> 本吉有美子 | AP5: =IFERROR(INDEX(ピッキング!$G$7:$G$66,MATCH(LARGE($AN$3:$AN$62,ROW()-2),$AN$3:$AN$62,0)),"") -> 83.686382 | AQ5: =IFERROR(INDEX(ピッキング!$P$7:$P$66,MATCH(LARGE($AN$3:$AN$62,ROW()-2),$AN$3:$AN$62,0)),"") -> 44.984113 | AR5: =IF(AQ5="","",AQ5+ROW()/100000) -> 44.984163 | AS5: =IFERROR(INDEX($AO$3:$AO$14,MATCH(LARGE($AR$3:$AR$14,ROW()-2),$AR$3:$AR$14,0)),"") -> 高橋正美 | AT5: =IFERROR(INDEX($AP$3:$AP$14,MATCH(LARGE($AR$3:$AR$14,ROW()-2),$AR$3:$AR$14,0)),"") -> 138.16514 | AU5: =IFERROR(INDEX($AQ$3:$AQ$14,MATCH(LARGE($AR$3:$AR$14,ROW()-2),$AR$3:$AR$14,0)),"") -> 102.0011 | AW5: ピック | AX5: 223.1 | AY5: =IFERROR(AX5/SUM($AX$3:$AX$5),"") -> 0.32837798 | AZ5: =AW5&" "&ROUND(AX5,1)&"h・"&ROUND(AY5*100,1)&"%" -> ピック 223.1h・32.8%
B6: ① 実績を入力 | C6: ② ピッキング評価 | D6: ③ 梱包評価 | E6: ④ 日次データ | F6: ⑤ 散布図 | G6: ⑥ 配置マップ | H6: ⑦ 要員予測 | I6: ⚙ 係数の設定 | J6: ？ 使い方 | K6: ⑧ 印刷用（A4・1枚） | T6: 4 | U6: =IFERROR(INDEX(ピッキング!$B$7:$B$66,MATCH($T6,ピッキング!$A$7:$A$66,0)),"") -> 佐藤辰成 | V6: =IFERROR(INDEX(ピッキング!$L$7:$L$66,MATCH($T6,ピッキング!$A$7:$A$66,0)),"") -> 120.11755 | W6: =IFERROR(INDEX(梱包!$B$7:$B$66,MATCH($T6,梱包!$A$7:$A$66,0)),"") -> 大江美記子 | X6: =IFERROR(INDEX(梱包!$L$7:$L$66,MATCH($T6,梱包!$A$7:$A$66,0)),"") -> 131.00105 | Z6: =IF(OR(ピッキング!$E$10="",ピッキング!$C$10=""),"",ピッキング!$E$10/ピッキング!$C$10) -> 0.22188906 | AA6: =IF(ピッキング!$G$10="","",ピッキング!$G$10) -> 72.863568 | AB6: =IF(ピッキング!$P$10="","",ピッキング!$P$10) -> 52.427586 | AD6: =IF(AND(ISNUMBER(Z6),ISNUMBER(AA6)),1,0) -> 1 | AE6: =IF(AD6=1,SUM($AD$3:AD6),"") -> 4 | AF6: =IFERROR(INDEX($Z$3:$Z$62,MATCH(T6,$AE$3:$AE$62,0)),"") -> 0.22188906 | AG6: =IFERROR(INDEX($AA$3:$AA$62,MATCH(T6,$AE$3:$AE$62,0)),"") -> 72.863568 | AI6: =IF(AND(ISNUMBER(Z6),ISNUMBER(AB6)),1,0) -> 1 | AJ6: =IF(AI6=1,SUM($AI$3:AI6),"") -> 4 | AK6: =IFERROR(INDEX($Z$3:$Z$62,MATCH(T6,$AJ$3:$AJ$62,0)),"") -> 0.22188906 | AL6: =IFERROR(INDEX($AB$3:$AB$62,MATCH(T6,$AJ$3:$AJ$62,0)),"") -> 52.427586 | AN6: =IF(ピッキング!$C$10="","",ピッキング!$C$10+ROW()/100000) -> 667.00006 | AO6: =IFERROR(INDEX(ピッキング!$B$7:$B$66,MATCH(LARGE($AN$3:$AN$62,ROW()-2),$AN$3:$AN$62,0)),"") -> 中納沙織 | AP6: =IFERROR(INDEX(ピッキング!$G$7:$G$66,MATCH(LARGE($AN$3:$AN$62,ROW()-2),$AN$3:$AN$62,0)),"") -> 118.3727 | AQ6: =IFERROR(INDEX(ピッキング!$P$7:$P$66,MATCH(LARGE($AN$3:$AN$62,ROW()-2),$AN$3:$AN$62,0)),"") -> 73.571654 | AR6: =IF(AQ6="","",AQ6+ROW()/100000) -> 73.571714 | AS6: =IFERROR(INDEX($AO$3:$AO$14,MATCH(LARGE($AR$3:$AR$14,ROW()-2),$AR$3:$AR$14,0)),"") -> 向井ひかり | AT6: =IFERROR(INDEX($AP$3:$AP$14,MATCH(LARGE($AR$3:$AR$14,ROW()-2),$AR$3:$AR$14,0)),"") -> 129.97691 | AU6: =IFERROR(INDEX($AQ$3:$AQ$14,MATCH(LARGE($AR$3:$AR$14,ROW()-2),$AR$3:$AR$14,0)),"") -> 88.606351
T7: 5 | U7: =IFERROR(INDEX(ピッキング!$B$7:$B$66,MATCH($T7,ピッキング!$A$7:$A$66,0)),"") -> 春谷智子 | V7: =IFERROR(INDEX(ピッキング!$L$7:$L$66,MATCH($T7,ピッキング!$A$7:$A$66,0)),"") -> 111.86291 | W7: =IFERROR(INDEX(梱包!$B$7:$B$66,MATCH($T7,梱包!$A$7:$A$66,0)),"") -> 佐藤辰成 | X7: =IFERROR(INDEX(梱包!$L$7:$L$66,MATCH($T7,梱包!$A$7:$A$66,0)),"") -> 128.07757 | Z7: =IF(OR(ピッキング!$E$11="",ピッキング!$C$11=""),"",ピッキング!$E$11/ピッキング!$C$11) -> 0.59836066 | AA7: =IF(ピッキング!$G$11="","",ピッキング!$G$11) -> 103.27869 | AB7: =IF(ピッキング!$P$11="","",ピッキング!$P$11) -> 48.169672 | AD7: =IF(AND(ISNUMBER(Z7),ISNUMBER(AA7)),1,0) -> 1 | AE7: =IF(AD7=1,SUM($AD$3:AD7),"") -> 5 | AF7: =IFERROR(INDEX($Z$3:$Z$62,MATCH(T7,$AE$3:$AE$62,0)),"") -> 0.59836066 | AG7: =IFERROR(INDEX($AA$3:$AA$62,MATCH(T7,$AE$3:$AE$62,0)),"") -> 103.27869 | AI7: =IF(AND(ISNUMBER(Z7),ISNUMBER(AB7)),1,0) -> 1 | AJ7: =IF(AI7=1,SUM($AI$3:AI7),"") -> 5 | AK7: =IFERROR(INDEX($Z$3:$Z$62,MATCH(T7,$AJ$3:$AJ$62,0)),"") -> 0.59836066 | AL7: =IFERROR(INDEX($AB$3:$AB$62,MATCH(T7,$AJ$3:$AJ$62,0)),"") -> 48.169672 | AN7: =IF(ピッキング!$C$11="","",ピッキング!$C$11+ROW()/100000) -> 122.00007 | AO7: =IFERROR(INDEX(ピッキング!$B$7:$B$66,MATCH(LARGE($AN$3:$AN$62,ROW()-2),$AN$3:$AN$62,0)),"") -> 上村和恵 | AP7: =IFERROR(INDEX(ピッキング!$G$7:$G$66,MATCH(LARGE($AN$3:$AN$62,ROW()-2),$AN$3:$AN$62,0)),"") -> 143.79496 | AQ7: =IFERROR(INDEX(ピッキング!$P$7:$P$66,MATCH(LARGE($AN$3:$AN$62,ROW()-2),$AN$3:$AN$62,0)),"") -> 105.28192 | AR7: =IF(AQ7="","",AQ7+ROW()/100000) -> 105.28199 | AS7: =IFERROR(INDEX($AO$3:$AO$14,MATCH(LARGE($AR$3:$AR$14,ROW()-2),$AR$3:$AR$14,0)),"") -> 石戸谷亜子 | AT7: =IFERROR(INDEX($AP$3:$AP$14,MATCH(LARGE($AR$3:$AR$14,ROW()-2),$AR$3:$AR$14,0)),"") -> 105.67376 | AU7: =IFERROR(INDEX($AQ$3:$AQ$14,MATCH(LARGE($AR$3:$AR$14,ROW()-2),$AR$3:$AR$14,0)),"") -> 74.973759
B8: ● 1社ごとの段取りが 233.2 時間。ピッキング総時間の 34.3% を占めています。 | T8: 6 | U8: =IFERROR(INDEX(ピッキング!$B$7:$B$66,MATCH($T8,ピッキング!$A$7:$A$66,0)),"") -> 後藤克行 | V8: =IFERROR(INDEX(ピッキング!$L$7:$L$66,MATCH($T8,ピッキング!$A$7:$A$66,0)),"") -> 109.49438 | W8: =IFERROR(INDEX(梱包!$B$7:$B$66,MATCH($T8,梱包!$A$7:$A$66,0)),"") -> 飯田由加里 | X8: =IFERROR(INDEX(梱包!$L$7:$L$66,MATCH($T8,梱包!$A$7:$A$66,0)),"") -> 126.75846 | Z8: =IF(OR(ピッキング!$E$12="",ピッキング!$C$12=""),"",ピッキング!$E$12/ピッキング!$C$12) -> 0.4778276 | AA8: =IF(ピッキング!$G$12="","",ピッキング!$G$12) -> 107.17489 | AB8: =IF(ピッキング!$P$12="","",ピッキング!$P$12) -> 63.166966 | AD8: =IF(AND(ISNUMBER(Z8),ISNUMBER(AA8)),1,0) -> 1 | AE8: =IF(AD8=1,SUM($AD$3:AD8),"") -> 6 | AF8: =IFERROR(INDEX($Z$3:$Z$62,MATCH(T8,$AE$3:$AE$62,0)),"") -> 0.4778276 | AG8: =IFERROR(INDEX($AA$3:$AA$62,MATCH(T8,$AE$3:$AE$62,0)),"") -> 107.17489 | AI8: =IF(AND(ISNUMBER(Z8),ISNUMBER(AB8)),1,0) -> 1 | AJ8: =IF(AI8=1,SUM($AI$3:AI8),"") -> 6 | AK8: =IFERROR(INDEX($Z$3:$Z$62,MATCH(T8,$AJ$3:$AJ$62,0)),"") -> 0.4778276 | AL8: =IFERROR(INDEX($AB$3:$AB$62,MATCH(T8,$AJ$3:$AJ$62,0)),"") -> 63.166966 | AN8: =IF(ピッキング!$C$12="","",ピッキング!$C$12+ROW()/100000) -> 2007.0001 | AO8: =IFERROR(INDEX(ピッキング!$B$7:$B$66,MATCH(LARGE($AN$3:$AN$62,ROW()-2),$AN$3:$AN$62,0)),"") -> 高橋正美 | AP8: =IFERROR(INDEX(ピッキング!$G$7:$G$66,MATCH(LARGE($AN$3:$AN$62,ROW()-2),$AN$3:$AN$62,0)),"") -> 138.16514 | AQ8: =IFERROR(INDEX(ピッキング!$P$7:$P$66,MATCH(LARGE($AN$3:$AN$62,ROW()-2),$AN$3:$AN$62,0)),"") -> 102.0011 | AR8: =IF(AQ8="","",AQ8+ROW()/100000) -> 102.00118 | AS8: =IFERROR(INDEX($AO$3:$AO$14,MATCH(LARGE($AR$3:$AR$14,ROW()-2),$AR$3:$AR$14,0)),"") -> 中納沙織 | AT8: =IFERROR(INDEX($AP$3:$AP$14,MATCH(LARGE($AR$3:$AR$14,ROW()-2),$AR$3:$AR$14,0)),"") -> 118.3727 | AU8: =IFERROR(INDEX($AQ$3:$AQ$14,MATCH(LARGE($AR$3:$AR$14,ROW()-2),$AR$3:$AR$14,0)),"") -> 73.571654
T9: 7 | U9: =IFERROR(INDEX(ピッキング!$B$7:$B$66,MATCH($T9,ピッキング!$A$7:$A$66,0)),"") -> 中村美佳 | V9: =IFERROR(INDEX(ピッキング!$L$7:$L$66,MATCH($T9,ピッキング!$A$7:$A$66,0)),"") -> 108.83317 | W9: =IFERROR(INDEX(梱包!$B$7:$B$66,MATCH($T9,梱包!$A$7:$A$66,0)),"") -> 晩田恵美 | X9: =IFERROR(INDEX(梱包!$L$7:$L$66,MATCH($T9,梱包!$A$7:$A$66,0)),"") -> 120.1695 | Z9: =IF(OR(ピッキング!$E$13="",ピッキング!$C$13=""),"",ピッキング!$E$13/ピッキング!$C$13) -> 0.37974684 | AA9: =IF(ピッキング!$G$13="","",ピッキング!$G$13) -> 91.139241 | AB9: =IF(ピッキング!$P$13="","",ピッキング!$P$13) -> 56.164557 | AD9: =IF(AND(ISNUMBER(Z9),ISNUMBER(AA9)),1,0) -> 1 | AE9: =IF(AD9=1,SUM($AD$3:AD9),"") -> 7 | AF9: =IFERROR(INDEX($Z$3:$Z$62,MATCH(T9,$AE$3:$AE$62,0)),"") -> 0.37974684 | AG9: =IFERROR(INDEX($AA$3:$AA$62,MATCH(T9,$AE$3:$AE$62,0)),"") -> 91.139241 | AI9: =IF(AND(ISNUMBER(Z9),ISNUMBER(AB9)),1,0) -> 1 | AJ9: =IF(AI9=1,SUM($AI$3:AI9),"") -> 7 | AK9: =IFERROR(INDEX($Z$3:$Z$62,MATCH(T9,$AJ$3:$AJ$62,0)),"") -> 0.37974684 | AL9: =IFERROR(INDEX($AB$3:$AB$62,MATCH(T9,$AJ$3:$AJ$62,0)),"") -> 56.164557 | AN9: =IF(ピッキング!$C$13="","",ピッキング!$C$13+ROW()/100000) -> 79.00009 | AO9: =IFERROR(INDEX(ピッキング!$B$7:$B$66,MATCH(LARGE($AN$3:$AN$62,ROW()-2),$AN$3:$AN$62,0)),"") -> 大江美記子 | AP9: =IFERROR(INDEX(ピッキング!$G$7:$G$66,MATCH(LARGE($AN$3:$AN$62,ROW()-2),$AN$3:$AN$62,0)),"") -> 93.883792 | AQ9: =IFERROR(INDEX(ピッキング!$P$7:$P$66,MATCH(LARGE($AN$3:$AN$62,ROW()-2),$AN$3:$AN$62,0)),"") -> 48.725688 | AR9: =IF(AQ9="","",AQ9+ROW()/100000) -> 48.725778 | AS9: =IFERROR(INDEX($AO$3:$AO$14,MATCH(LARGE($AR$3:$AR$14,ROW()-2),$AR$3:$AR$14,0)),"") -> 山本祥吉 | AT9: =IFERROR(INDEX($AP$3:$AP$14,MATCH(LARGE($AR$3:$AR$14,ROW()-2),$AR$3:$AR$14,0)),"") -> 101.14608 | AU9: =IFERROR(INDEX($AQ$3:$AQ$14,MATCH(LARGE($AR$3:$AR$14,ROW()-2),$AR$3:$AR$14,0)),"") -> 69.306905
B10: 総処理件数 | F10: 平均効率 | T10: 8 | U10: =IFERROR(INDEX(ピッキング!$B$7:$B$66,MATCH($T10,ピッキング!$A$7:$A$66,0)),"") -> 晩田恵美 | V10: =IFERROR(INDEX(ピッキング!$L$7:$L$66,MATCH($T10,ピッキング!$A$7:$A$66,0)),"") -> 106.78994 | W10: =IFERROR(INDEX(梱包!$B$7:$B$66,MATCH($T10,梱包!$A$7:$A$66,0)),"") -> 河野忠 | X10: =IFERROR(INDEX(梱包!$L$7:$L$66,MATCH($T10,梱包!$A$7:$A$66,0)),"") -> 114.99641 | Z10: =IF(OR(ピッキング!$E$14="",ピッキング!$C$14=""),"",ピッキング!$E$14/ピッキング!$C$14) -> 0.26339795 | AA10: =IF(ピッキング!$G$14="","",ピッキング!$G$14) -> 92.086659 | AB10: =IF(ピッキング!$P$14="","",ピッキング!$P$14) -> 67.827708 | AD10: =IF(AND(ISNUMBER(Z10),ISNUMBER(AA10)),1,0) -> 1 | AE10: =IF(AD10=1,SUM($AD$3:AD10),"") -> 8 | AF10: =IFERROR(INDEX($Z$3:$Z$62,MATCH(T10,$AE$3:$AE$62,0)),"") -> 0.26339795 | AG10: =IFERROR(INDEX($AA$3:$AA$62,MATCH(T10,$AE$3:$AE$62,0)),"") -> 92.086659 | AI10: =IF(AND(ISNUMBER(Z10),ISNUMBER(AB10)),1,0) -> 1 | AJ10: =IF(AI10=1,SUM($AI$3:AI10),"") -> 8 | AK10: =IFERROR(INDEX($Z$3:$Z$62,MATCH(T10,$AJ$3:$AJ$62,0)),"") -> 0.26339795 | AL10: =IFERROR(INDEX($AB$3:$AB$62,MATCH(T10,$AJ$3:$AJ$62,0)),"") -> 67.827708 | AN10: =IF(ピッキング!$C$14="","",ピッキング!$C$14+ROW()/100000) -> 877.0001 | AO10: =IFERROR(INDEX(ピッキング!$B$7:$B$66,MATCH(LARGE($AN$3:$AN$62,ROW()-2),$AN$3:$AN$62,0)),"") -> 高橋佐織 | AP10: =IFERROR(INDEX(ピッキング!$G$7:$G$66,MATCH(LARGE($AN$3:$AN$62,ROW()-2),$AN$3:$AN$62,0)),"") -> 107.43889 | AQ10: =IFERROR(INDEX(ピッキング!$P$7:$P$66,MATCH(LARGE($AN$3:$AN$62,ROW()-2),$AN$3:$AN$62,0)),"") -> 68.289054 | AR10: =IF(AQ10="","",AQ10+ROW()/100000) -> 68.289154 | AS10: =IFERROR(INDEX($AO$3:$AO$14,MATCH(LARGE($AR$3:$AR$14,ROW()-2),$AR$3:$AR$14,0)),"") -> 高橋佐織 | AT10: =IFERROR(INDEX($AP$3:$AP$14,MATCH(LARGE($AR$3:$AR$14,ROW()-2),$AR$3:$AR$14,0)),"") -> 107.43889 | AU10: =IFERROR(INDEX($AQ$3:$AQ$14,MATCH(LARGE($AR$3:$AR$14,ROW()-2),$AR$3:$AR$14,0)),"") -> 68.289054
B11: =ピッキング!$T$10+梱包!$T$10 -> 45716 | F11: =IFERROR((ピッキング!$T$14+梱包!$T$14)/(ピッキング!$T$12+梱包!$T$12)*100,"") -> 99.981977 | T11: 9 | U11: =IFERROR(INDEX(ピッキング!$B$7:$B$66,MATCH($T11,ピッキング!$A$7:$A$66,0)),"") -> 高橋佐織 | V11: =IFERROR(INDEX(ピッキング!$L$7:$L$66,MATCH($T11,ピッキング!$A$7:$A$66,0)),"") -> 105.7972 | W11: =IFERROR(INDEX(梱包!$B$7:$B$66,MATCH($T11,梱包!$A$7:$A$66,0)),"") -> 森本久美 | X11: =IFERROR(INDEX(梱包!$L$7:$L$66,MATCH($T11,梱包!$A$7:$A$66,0)),"") -> 102.18959 | Z11: =IF(OR(ピッキング!$E$15="",ピッキング!$C$15=""),"",ピッキング!$E$15/ピッキング!$C$15) -> 0.4250797 | AA11: =IF(ピッキング!$G$15="","",ピッキング!$G$15) -> 107.43889 | AB11: =IF(ピッキング!$P$15="","",ピッキング!$P$15) -> 68.289054 | AD11: =IF(AND(ISNUMBER(Z11),ISNUMBER(AA11)),1,0) -> 1 | AE11: =IF(AD11=1,SUM($AD$3:AD11),"") -> 9 | AF11: =IFERROR(INDEX($Z$3:$Z$62,MATCH(T11,$AE$3:$AE$62,0)),"") -> 0.4250797 | AG11: =IFERROR(INDEX($AA$3:$AA$62,MATCH(T11,$AE$3:$AE$62,0)),"") -> 107.43889 | AI11: =IF(AND(ISNUMBER(Z11),ISNUMBER(AB11)),1,0) -> 1 | AJ11: =IF(AI11=1,SUM($AI$3:AI11),"") -> 9 | AK11: =IFERROR(INDEX($Z$3:$Z$62,MATCH(T11,$AJ$3:$AJ$62,0)),"") -> 0.4250797 | AL11: =IFERROR(INDEX($AB$3:$AB$62,MATCH(T11,$AJ$3:$AJ$62,0)),"") -> 68.289054 | AN11: =IF(ピッキング!$C$15="","",ピッキング!$C$15+ROW()/100000) -> 941.00011 | AO11: =IFERROR(INDEX(ピッキング!$B$7:$B$66,MATCH(LARGE($AN$3:$AN$62,ROW()-2),$AN$3:$AN$62,0)),"") -> 晩田恵美 | AP11: =IFERROR(INDEX(ピッキング!$G$7:$G$66,MATCH(LARGE($AN$3:$AN$62,ROW()-2),$AN$3:$AN$62,0)),"") -> 92.086659 | AQ11: =IFERROR(INDEX(ピッキング!$P$7:$P$66,MATCH(LARGE($AN$3:$AN$62,ROW()-2),$AN$3:$AN$62,0)),"") -> 67.827708 | AR11: =IF(AQ11="","",AQ11+ROW()/100000) -> 67.827818 | AS11: =IFERROR(INDEX($AO$3:$AO$14,MATCH(LARGE($AR$3:$AR$14,ROW()-2),$AR$3:$AR$14,0)),"") -> 晩田恵美 | AT11: =IFERROR(INDEX($AP$3:$AP$14,MATCH(LARGE($AR$3:$AR$14,ROW()-2),$AR$3:$AR$14,0)),"") -> 92.086659 | AU11: =IFERROR(INDEX($AQ$3:$AQ$14,MATCH(LARGE($AR$3:$AR$14,ROW()-2),$AR$3:$AR$14,0)),"") -> 67.827708
B12: 0.294 | F12: 0.067 | T12: 10 | U12: =IFERROR(INDEX(ピッキング!$B$7:$B$66,MATCH($T12,ピッキング!$A$7:$A$66,0)),"") -> 山本祥吉 | V12: =IFERROR(INDEX(ピッキング!$L$7:$L$66,MATCH($T12,ピッキング!$A$7:$A$66,0)),"") -> 105.515 | W12: =IFERROR(INDEX(梱包!$B$7:$B$66,MATCH($T12,梱包!$A$7:$A$66,0)),"") -> 鈴木香織 | X12: =IFERROR(INDEX(梱包!$L$7:$L$66,MATCH($T12,梱包!$A$7:$A$66,0)),"") -> 98.746785 | Z12: =IF(OR(ピッキング!$E$16="",ピッキング!$C$16=""),"",ピッキング!$E$16/ピッキング!$C$16) -> 0.34570221 | AA12: =IF(ピッキング!$G$16="","",ピッキング!$G$16) -> 101.14608 | AB12: =IF(ピッキング!$P$16="","",ピッキング!$P$16) -> 69.306905 | AD12: =IF(AND(ISNUMBER(Z12),ISNUMBER(AA12)),1,0) -> 1 | AE12: =IF(AD12=1,SUM($AD$3:AD12),"") -> 10 | AF12: =IFERROR(INDEX($Z$3:$Z$62,MATCH(T12,$AE$3:$AE$62,0)),"") -> 0.34570221 | AG12: =IFERROR(INDEX($AA$3:$AA$62,MATCH(T12,$AE$3:$AE$62,0)),"") -> 101.14608 | AI12: =IF(AND(ISNUMBER(Z12),ISNUMBER(AB12)),1,0) -> 1 | AJ12: =IF(AI12=1,SUM($AI$3:AI12),"") -> 10 | AK12: =IFERROR(INDEX($Z$3:$Z$62,MATCH(T12,$AJ$3:$AJ$62,0)),"") -> 0.34570221 | AL12: =IFERROR(INDEX($AB$3:$AB$62,MATCH(T12,$AJ$3:$AJ$62,0)),"") -> 69.306905 | AN12: =IF(ピッキング!$C$16="","",ピッキング!$C$16+ROW()/100000) -> 2129.0001 | AO12: =IFERROR(INDEX(ピッキング!$B$7:$B$66,MATCH(LARGE($AN$3:$AN$62,ROW()-2),$AN$3:$AN$62,0)),"") -> 向井ひかり | AP12: =IFERROR(INDEX(ピッキング!$G$7:$G$66,MATCH(LARGE($AN$3:$AN$62,ROW()-2),$AN$3:$AN$62,0)),"") -> 129.97691 | AQ12: =IFERROR(INDEX(ピッキング!$P$7:$P$66,MATCH(LARGE($AN$3:$AN$62,ROW()-2),$AN$3:$AN$62,0)),"") -> 88.606351 | AR12: =IF(AQ12="","",AQ12+ROW()/100000) -> 88.606471 | AS12: =IFERROR(INDEX($AO$3:$AO$14,MATCH(LARGE($AR$3:$AR$14,ROW()-2),$AR$3:$AR$14,0)),"") -> 後藤克行 | AT12: =IFERROR(INDEX($AP$3:$AP$14,MATCH(LARGE($AR$3:$AR$14,ROW()-2),$AR$3:$AR$14,0)),"") -> 107.17489 | AU12: =IFERROR(INDEX($AQ$3:$AQ$14,MATCH(LARGE($AR$3:$AR$14,ROW()-2),$AR$3:$AR$14,0)),"") -> 63.166966
B13: ピッキング 21,249件 ＋ 梱包 24,467件。物量は需要であって成績ではない | F13: 標準時間 ÷ 実測時間。100 が標準どおり | T13: 11 | U13: =IFERROR(INDEX(ピッキング!$B$7:$B$66,MATCH($T13,ピッキング!$A$7:$A$66,0)),"") -> 佐々木千恵 | V13: =IFERROR(INDEX(ピッキング!$L$7:$L$66,MATCH($T13,ピッキング!$A$7:$A$66,0)),"") -> 105.20453 | W13: =IFERROR(INDEX(梱包!$B$7:$B$66,MATCH($T13,梱包!$A$7:$A$66,0)),"") -> 高橋佐織 | X13: =IFERROR(INDEX(梱包!$L$7:$L$66,MATCH($T13,梱包!$A$7:$A$66,0)),"") -> 94.989156 | Z13: =IF(OR(ピッキング!$E$17="",ピッキング!$C$17=""),"",ピッキング!$E$17/ピッキング!$C$17) -> 0.2804699 | AA13: =IF(ピッキング!$G$17="","",ピッキング!$G$17) -> 95.330396 | AB13: =IF(ピッキング!$P$17="","",ピッキング!$P$17) -> 69.499119 | AD13: =IF(AND(ISNUMBER(Z13),ISNUMBER(AA13)),1,0) -> 1 | AE13: =IF(AD13=1,SUM($AD$3:AD13),"") -> 11 | AF13: =IFERROR(INDEX($Z$3:$Z$62,MATCH(T13,$AE$3:$AE$62,0)),"") -> 0.2804699 | AG13: =IFERROR(INDEX($AA$3:$AA$62,MATCH(T13,$AE$3:$AE$62,0)),"") -> 95.330396 | AI13: =IF(AND(ISNUMBER(Z13),ISNUMBER(AB13)),1,0) -> 1 | AJ13: =IF(AI13=1,SUM($AI$3:AI13),"") -> 11 | AK13: =IFERROR(INDEX($Z$3:$Z$62,MATCH(T13,$AJ$3:$AJ$62,0)),"") -> 0.2804699 | AL13: =IFERROR(INDEX($AB$3:$AB$62,MATCH(T13,$AJ$3:$AJ$62,0)),"") -> 69.499119 | AN13: =IF(ピッキング!$C$17="","",ピッキング!$C$17+ROW()/100000) -> 681.00013 | AO13: =IFERROR(INDEX(ピッキング!$B$7:$B$66,MATCH(LARGE($AN$3:$AN$62,ROW()-2),$AN$3:$AN$62,0)),"") -> 秋草文恵 | AP13: =IFERROR(INDEX(ピッキング!$G$7:$G$66,MATCH(LARGE($AN$3:$AN$62,ROW()-2),$AN$3:$AN$62,0)),"") -> 146.43357 | AQ13: =IFERROR(INDEX(ピッキング!$P$7:$P$66,MATCH(LARGE($AN$3:$AN$62,ROW()-2),$AN$3:$AN$62,0)),"") -> 104.46259 | AR13: =IF(AQ13="","",AQ13+ROW()/100000) -> 104.46272 | AS13: =IFERROR(INDEX($AO$3:$AO$14,MATCH(LARGE($AR$3:$AR$14,ROW()-2),$AR$3:$AR$14,0)),"") -> 大江美記子 | AT13: =IFERROR(INDEX($AP$3:$AP$14,MATCH(LARGE($AR$3:$AR$14,ROW()-2),$AR$3:$AR$14,0)),"") -> 93.883792 | AU13: =IFERROR(INDEX($AQ$3:$AQ$14,MATCH(LARGE($AR$3:$AR$14,ROW()-2),$AR$3:$AR$14,0)),"") -> 48.725688
T14: 12 | U14: =IFERROR(INDEX(ピッキング!$B$7:$B$66,MATCH($T14,ピッキング!$A$7:$A$66,0)),"") -> 北田倫子 | V14: =IFERROR(INDEX(ピッキング!$L$7:$L$66,MATCH($T14,ピッキング!$A$7:$A$66,0)),"") -> 102.50307 | W14: =IFERROR(INDEX(梱包!$B$7:$B$66,MATCH($T14,梱包!$A$7:$A$66,0)),"") -> 中村美佳 | X14: =IFERROR(INDEX(梱包!$L$7:$L$66,MATCH($T14,梱包!$A$7:$A$66,0)),"") -> 89.601445 | Z14: =IF(OR(ピッキング!$E$18="",ピッキング!$C$18=""),"",ピッキング!$E$18/ピッキング!$C$18) -> 0.60042735 | AA14: =IF(ピッキング!$G$18="","",ピッキング!$G$18) -> 128.33333 | AB14: =IF(ピッキング!$P$18="","",ピッキング!$P$18) -> 73.033974 | AD14: =IF(AND(ISNUMBER(Z14),ISNUMBER(AA14)),1,0) -> 1 | AE14: =IF(AD14=1,SUM($AD$3:AD14),"") -> 12 | AF14: =IFERROR(INDEX($Z$3:$Z$62,MATCH(T14,$AE$3:$AE$62,0)),"") -> 0.60042735 | AG14: =IFERROR(INDEX($AA$3:$AA$62,MATCH(T14,$AE$3:$AE$62,0)),"") -> 128.33333 | AI14: =IF(AND(ISNUMBER(Z14),ISNUMBER(AB14)),1,0) -> 1 | AJ14: =IF(AI14=1,SUM($AI$3:AI14),"") -> 12 | AK14: =IFERROR(INDEX($Z$3:$Z$62,MATCH(T14,$AJ$3:$AJ$62,0)),"") -> 0.60042735 | AL14: =IFERROR(INDEX($AB$3:$AB$62,MATCH(T14,$AJ$3:$AJ$62,0)),"") -> 73.033974 | AN14: =IF(ピッキング!$C$18="","",ピッキング!$C$18+ROW()/100000) -> 468.00014 | AO14: =IFERROR(INDEX(ピッキング!$B$7:$B$66,MATCH(LARGE($AN$3:$AN$62,ROW()-2),$AN$3:$AN$62,0)),"") -> 石戸谷亜子 | AP14: =IFERROR(INDEX(ピッキング!$G$7:$G$66,MATCH(LARGE($AN$3:$AN$62,ROW()-2),$AN$3:$AN$62,0)),"") -> 105.67376 | AQ14: =IFERROR(INDEX(ピッキング!$P$7:$P$66,MATCH(LARGE($AN$3:$AN$62,ROW()-2),$AN$3:$AN$62,0)),"") -> 74.973759 | AR14: =IF(AQ14="","",AQ14+ROW()/100000) -> 74.973899 | AS14: =IFERROR(INDEX($AO$3:$AO$14,MATCH(LARGE($AR$3:$AR$14,ROW()-2),$AR$3:$AR$14,0)),"") -> 本吉有美子 | AT14: =IFERROR(INDEX($AP$3:$AP$14,MATCH(LARGE($AR$3:$AR$14,ROW()-2),$AR$3:$AR$14,0)),"") -> 83.686382 | AU14: =IFERROR(INDEX($AQ$3:$AQ$14,MATCH(LARGE($AR$3:$AR$14,ROW()-2),$AR$3:$AR$14,0)),"") -> 44.984113
B15: 段取り比率 | F15: 稼働時間 | T15: 13 | U15: =IFERROR(INDEX(ピッキング!$B$7:$B$66,MATCH($T15,ピッキング!$A$7:$A$66,0)),"") -> 中納沙織 | V15: =IFERROR(INDEX(ピッキング!$L$7:$L$66,MATCH($T15,ピッキング!$A$7:$A$66,0)),"") -> 102.49959 | W15: =IFERROR(INDEX(梱包!$B$7:$B$66,MATCH($T15,梱包!$A$7:$A$66,0)),"") -> 山本祥吉 | X15: =IFERROR(INDEX(梱包!$L$7:$L$66,MATCH($T15,梱包!$A$7:$A$66,0)),"") -> 86.545994 | Z15: =IF(OR(ピッキング!$E$19="",ピッキング!$C$19=""),"",ピッキング!$E$19/ピッキング!$C$19) -> 0.4864392 | AA15: =IF(ピッキング!$G$19="","",ピッキング!$G$19) -> 118.3727 | AB15: =IF(ピッキング!$P$19="","",ピッキング!$P$19) -> 73.571654 | AD15: =IF(AND(ISNUMBER(Z15),ISNUMBER(AA15)),1,0) -> 1 | AE15: =IF(AD15=1,SUM($AD$3:AD15),"") -> 13 | AF15: =IFERROR(INDEX($Z$3:$Z$62,MATCH(T15,$AE$3:$AE$62,0)),"") -> 0.4864392 | AG15: =IFERROR(INDEX($AA$3:$AA$62,MATCH(T15,$AE$3:$AE$62,0)),"") -> 118.3727 | AI15: =IF(AND(ISNUMBER(Z15),ISNUMBER(AB15)),1,0) -> 1 | AJ15: =IF(AI15=1,SUM($AI$3:AI15),"") -> 13 | AK15: =IFERROR(INDEX($Z$3:$Z$62,MATCH(T15,$AJ$3:$AJ$62,0)),"") -> 0.4864392 | AL15: =IFERROR(INDEX($AB$3:$AB$62,MATCH(T15,$AJ$3:$AJ$62,0)),"") -> 73.571654 | AN15: =IF(ピッキング!$C$19="","",ピッキング!$C$19+ROW()/100000) -> 1143.0002
B16: =IFERROR(ピッキング!$T$13/ピッキング!$T$12,"") -> 0.34303484 | F16: =IFERROR((ピッキング!$T$12+梱包!$T$12)/60,"") -> 1332.8333 | T16: 14 | U16: =IFERROR(INDEX(ピッキング!$B$7:$B$66,MATCH($T16,ピッキング!$A$7:$A$66,0)),"") -> 石戸谷亜子 | V16: =IFERROR(INDEX(ピッキング!$L$7:$L$66,MATCH($T16,ピッキング!$A$7:$A$66,0)),"") -> 101.9554 | W16: =IFERROR(INDEX(梱包!$B$7:$B$66,MATCH($T16,梱包!$A$7:$A$66,0)),"") -> 後藤克行 | X16: =IFERROR(INDEX(梱包!$L$7:$L$66,MATCH($T16,梱包!$A$7:$A$66,0)),"") -> 82.466184 | Z16: =IF(OR(ピッキング!$E$20="",ピッキング!$C$20=""),"",ピッキング!$E$20/ピッキング!$C$20) -> 0.33333333 | AA16: =IF(ピッキング!$G$20="","",ピッキング!$G$20) -> 105.67376 | AB16: =IF(ピッキング!$P$20="","",ピッキング!$P$20) -> 74.973759 | AD16: =IF(AND(ISNUMBER(Z16),ISNUMBER(AA16)),1,0) -> 1 | AE16: =IF(AD16=1,SUM($AD$3:AD16),"") -> 14 | AF16: =IFERROR(INDEX($Z$3:$Z$62,MATCH(T16,$AE$3:$AE$62,0)),"") -> 0.33333333 | AG16: =IFERROR(INDEX($AA$3:$AA$62,MATCH(T16,$AE$3:$AE$62,0)),"") -> 105.67376 | AI16: =IF(AND(ISNUMBER(Z16),ISNUMBER(AB16)),1,0) -> 1 | AJ16: =IF(AI16=1,SUM($AI$3:AI16),"") -> 14 | AK16: =IFERROR(INDEX($Z$3:$Z$62,MATCH(T16,$AJ$3:$AJ$62,0)),"") -> 0.33333333 | AL16: =IFERROR(INDEX($AB$3:$AB$62,MATCH(T16,$AJ$3:$AJ$62,0)),"") -> 74.973759 | AN16: =IF(ピッキング!$C$20="","",ピッキング!$C$20+ROW()/100000) -> 846.00016
B17: 0.095 | F17: 0.238 | T17: 15 | U17: =IFERROR(INDEX(ピッキング!$B$7:$B$66,MATCH($T17,ピッキング!$A$7:$A$66,0)),"") -> 森田美加 | V17: =IFERROR(INDEX(ピッキング!$L$7:$L$66,MATCH($T17,ピッキング!$A$7:$A$66,0)),"") -> 101.3098 | W17: =IFERROR(INDEX(梱包!$B$7:$B$66,MATCH($T17,梱包!$A$7:$A$66,0)),"") -> 中納沙織 | X17: =IFERROR(INDEX(梱包!$L$7:$L$66,MATCH($T17,梱包!$A$7:$A$66,0)),"") -> 81.623855 | Z17: =IF(OR(ピッキング!$E$21="",ピッキング!$C$21=""),"",ピッキング!$E$21/ピッキング!$C$21) -> 0.5 | AA17: =IF(ピッキング!$G$21="","",ピッキング!$G$21) -> 123.85321 | AB17: =IF(ピッキング!$P$21="","",ピッキング!$P$21) -> 77.803211 | AD17: =IF(AND(ISNUMBER(Z17),ISNUMBER(AA17)),1,0) -> 1 | AE17: =IF(AD17=1,SUM($AD$3:AD17),"") -> 15 | AF17: =IFERROR(INDEX($Z$3:$Z$62,MATCH(T17,$AE$3:$AE$62,0)),"") -> 0.5 | AG17: =IFERROR(INDEX($AA$3:$AA$62,MATCH(T17,$AE$3:$AE$62,0)),"") -> 123.85321 | AI17: =IF(AND(ISNUMBER(Z17),ISNUMBER(AB17)),1,0) -> 1 | AJ17: =IF(AI17=1,SUM($AI$3:AI17),"") -> 15 | AK17: =IFERROR(INDEX($Z$3:$Z$62,MATCH(T17,$AJ$3:$AJ$62,0)),"") -> 0.5 | AL17: =IFERROR(INDEX($AB$3:$AB$62,MATCH(T17,$AJ$3:$AJ$62,0)),"") -> 77.803211 | AN17: =IF(ピッキング!$C$21="","",ピッキング!$C$21+ROW()/100000) -> 218.00017
B18: 段取り 233.2h ÷ ピッキング実働 679.7h。下がるのは良いこと | F18: ピッキング 679.7h ＋ 梱包 653.1h | T18: 16 | U18: =IFERROR(INDEX(ピッキング!$B$7:$B$66,MATCH($T18,ピッキング!$A$7:$A$66,0)),"") -> 河野忠 | V18: =IFERROR(INDEX(ピッキング!$L$7:$L$66,MATCH($T18,ピッキング!$A$7:$A$66,0)),"") -> 101.02483 | W18: =IFERROR(INDEX(梱包!$B$7:$B$66,MATCH($T18,梱包!$A$7:$A$66,0)),"") -> 澤田凌 | X18: =IFERROR(INDEX(梱包!$L$7:$L$66,MATCH($T18,梱包!$A$7:$A$66,0)),"") -> 77.985419 | Z18: =IF(OR(ピッキング!$E$22="",ピッキング!$C$22=""),"",ピッキング!$E$22/ピッキング!$C$22) -> 0.43928571 | AA18: =IF(ピッキング!$G$22="","",ピッキング!$G$22) -> 118.28571 | AB18: =IF(ピッキング!$P$22="","",ピッキング!$P$22) -> 77.8275 | AD18: =IF(AND(ISNUMBER(Z18),ISNUMBER(AA18)),1,0) -> 1 | AE18: =IF(AD18=1,SUM($AD$3:AD18),"") -> 16 | AF18: =IFERROR(INDEX($Z$3:$Z$62,MATCH(T18,$AE$3:$AE$62,0)),"") -> 0.43928571 | AG18: =IFERROR(INDEX($AA$3:$AA$62,MATCH(T18,$AE$3:$AE$62,0)),"") -> 118.28571 | AI18: =IF(AND(ISNUMBER(Z18),ISNUMBER(AB18)),1,0) -> 1 | AJ18: =IF(AI18=1,SUM($AI$3:AI18),"") -> 16 | AK18: =IFERROR(INDEX($Z$3:$Z$62,MATCH(T18,$AJ$3:$AJ$62,0)),"") -> 0.43928571 | AL18: =IFERROR(INDEX($AB$3:$AB$62,MATCH(T18,$AJ$3:$AJ$62,0)),"") -> 77.8275 | AN18: =IF(ピッキング!$C$22="","",ピッキング!$C$22+ROW()/100000) -> 280.00018
T19: 17 | U19: =IFERROR(INDEX(ピッキング!$B$7:$B$66,MATCH($T19,ピッキング!$A$7:$A$66,0)),"") -> 木村千鶴 | V19: =IFERROR(INDEX(ピッキング!$L$7:$L$66,MATCH($T19,ピッキング!$A$7:$A$66,0)),"") -> 100.82289 | W19: =IFERROR(INDEX(梱包!$B$7:$B$66,MATCH($T19,梱包!$A$7:$A$66,0)),"") -> 木村千鶴 | X19: =IFERROR(INDEX(梱包!$L$7:$L$66,MATCH($T19,梱包!$A$7:$A$66,0)),"") -> 74.605827 | Z19: =IF(OR(ピッキング!$E$23="",ピッキング!$C$23=""),"",ピッキング!$E$23/ピッキング!$C$23) -> 0.49059334 | AA19: =IF(ピッキング!$G$23="","",ピッキング!$G$23) -> 121.21563 | AB19: =IF(ピッキング!$P$23="","",ピッキング!$P$23) -> 76.031983 | AD19: =IF(AND(ISNUMBER(Z19),ISNUMBER(AA19)),1,0) -> 1 | AE19: =IF(AD19=1,SUM($AD$3:AD19),"") -> 17 | AF19: =IFERROR(INDEX($Z$3:$Z$62,MATCH(T19,$AE$3:$AE$62,0)),"") -> 0.49059334 | AG19: =IFERROR(INDEX($AA$3:$AA$62,MATCH(T19,$AE$3:$AE$62,0)),"") -> 121.21563 | AI19: =IF(AND(ISNUMBER(Z19),ISNUMBER(AB19)),1,0) -> 1 | AJ19: =IF(AI19=1,SUM($AI$3:AI19),"") -> 17 | AK19: =IFERROR(INDEX($Z$3:$Z$62,MATCH(T19,$AJ$3:$AJ$62,0)),"") -> 0.49059334 | AL19: =IFERROR(INDEX($AB$3:$AB$62,MATCH(T19,$AJ$3:$AJ$62,0)),"") -> 76.031983 | AN19: =IF(ピッキング!$C$23="","",ピッキング!$C$23+ROW()/100000) -> 691.00019
B20: 3-4. 段取りの混入と、その補正 － この2枚がこのダッシュボードの主張そのものです | T20: 18 | U20: =IFERROR(INDEX(ピッキング!$B$7:$B$66,MATCH($T20,ピッキング!$A$7:$A$66,0)),"") -> 奥野愛海 | V20: =IFERROR(INDEX(ピッキング!$L$7:$L$66,MATCH($T20,ピッキング!$A$7:$A$66,0)),"") -> 99.87068 | W20: =IFERROR(INDEX(梱包!$B$7:$B$66,MATCH($T20,梱包!$A$7:$A$66,0)),"") -> 菊池敬 | X20: =IFERROR(INDEX(梱包!$L$7:$L$66,MATCH($T20,梱包!$A$7:$A$66,0)),"") -> 69.459989 | Z20: =IF(OR(ピッキング!$E$24="",ピッキング!$C$24=""),"",ピッキング!$E$24/ピッキング!$C$24) -> 0.50240385 | AA20: =IF(ピッキング!$G$24="","",ピッキング!$G$24) -> 133.41346 | AB20: =IF(ピッキング!$P$24="","",ピッキング!$P$24) -> 87.142067 | AD20: =IF(AND(ISNUMBER(Z20),ISNUMBER(AA20)),1,0) -> 1 | AE20: =IF(AD20=1,SUM($AD$3:AD20),"") -> 18 | AF20: =IFERROR(INDEX($Z$3:$Z$62,MATCH(T20,$AE$3:$AE$62,0)),"") -> 0.50240385 | AG20: =IFERROR(INDEX($AA$3:$AA$62,MATCH(T20,$AE$3:$AE$62,0)),"") -> 133.41346 | AI20: =IF(AND(ISNUMBER(Z20),ISNUMBER(AB20)),1,0) -> 1 | AJ20: =IF(AI20=1,SUM($AI$3:AI20),"") -> 18 | AK20: =IFERROR(INDEX($Z$3:$Z$62,MATCH(T20,$AJ$3:$AJ$62,0)),"") -> 0.50240385 | AL20: =IFERROR(INDEX($AB$3:$AB$62,MATCH(T20,$AJ$3:$AJ$62,0)),"") -> 87.142067 | AN20: =IF(ピッキング!$C$24="","",ピッキング!$C$24+ROW()/100000) -> 416.0002
B21: ① 素の秒/件 は、リストの構成で決まってしまう | T21: 19 | U21: =IFERROR(INDEX(ピッキング!$B$7:$B$66,MATCH($T21,ピッキング!$A$7:$A$66,0)),"") -> 鈴木香織 | V21: =IFERROR(INDEX(ピッキング!$L$7:$L$66,MATCH($T21,ピッキング!$A$7:$A$66,0)),"") -> 99.417763 | W21: =IFERROR(INDEX(梱包!$B$7:$B$66,MATCH($T21,梱包!$A$7:$A$66,0)),"") -> 森田美加 | X21: =IFERROR(INDEX(梱包!$L$7:$L$66,MATCH($T21,梱包!$A$7:$A$66,0)),"") -> 60.168472 | Z21: =IF(OR(ピッキング!$E$25="",ピッキング!$C$25=""),"",ピッキング!$E$25/ピッキング!$C$25) -> 0.55411255 | AA21: =IF(ピッキング!$G$25="","",ピッキング!$G$25) -> 131.16883 | AB21: =IF(ピッキング!$P$25="","",ピッキング!$P$25) -> 80.135065 | AD21: =IF(AND(ISNUMBER(Z21),ISNUMBER(AA21)),1,0) -> 1 | AE21: =IF(AD21=1,SUM($AD$3:AD21),"") -> 19 | AF21: =IFERROR(INDEX($Z$3:$Z$62,MATCH(T21,$AE$3:$AE$62,0)),"") -> 0.55411255 | AG21: =IFERROR(INDEX($AA$3:$AA$62,MATCH(T21,$AE$3:$AE$62,0)),"") -> 131.16883 | AI21: =IF(AND(ISNUMBER(Z21),ISNUMBER(AB21)),1,0) -> 1 | AJ21: =IF(AI21=1,SUM($AI$3:AI21),"") -> 19 | AK21: =IFERROR(INDEX($Z$3:$Z$62,MATCH(T21,$AJ$3:$AJ$62,0)),"") -> 0.55411255 | AL21: =IFERROR(INDEX($AB$3:$AB$62,MATCH(T21,$AJ$3:$AJ$62,0)),"") -> 80.135065 | AN21: =IF(ピッキング!$C$25="","",ピッキング!$C$25+ROW()/100000) -> 231.00021
B22: 右にいる人ほど「1社1個」のリストを多く引いた人。右上がりなら、速さではなく担当したリストの中身が数字を決めている。 | T22: 20 | U22: =IFERROR(INDEX(ピッキング!$B$7:$B$66,MATCH($T22,ピッキング!$A$7:$A$66,0)),"") -> 向井ひかり | V22: =IFERROR(INDEX(ピッキング!$L$7:$L$66,MATCH($T22,ピッキング!$A$7:$A$66,0)),"") -> 94.986666 | W22: =IFERROR(INDEX(梱包!$B$7:$B$66,MATCH($T22,梱包!$A$7:$A$66,0)),"") | X22: =IFERROR(INDEX(梱包!$L$7:$L$66,MATCH($T22,梱包!$A$7:$A$66,0)),"") | Z22: =IF(OR(ピッキング!$E$26="",ピッキング!$C$26=""),"",ピッキング!$E$26/ピッキング!$C$26) -> 0.44919169 | AA22: =IF(ピッキング!$G$26="","",ピッキング!$G$26) -> 129.97691 | AB22: =IF(ピッキング!$P$26="","",ピッキング!$P$26) -> 88.606351 | AD22: =IF(AND(ISNUMBER(Z22),ISNUMBER(AA22)),1,0) -> 1 | AE22: =IF(AD22=1,SUM($AD$3:AD22),"") -> 20 | AF22: =IFERROR(INDEX($Z$3:$Z$62,MATCH(T22,$AE$3:$AE$62,0)),"") -> 0.44919169 | AG22: =IFERROR(INDEX($AA$3:$AA$62,MATCH(T22,$AE$3:$AE$62,0)),"") -> 129.97691 | AI22: =IF(AND(ISNUMBER(Z22),ISNUMBER(AB22)),1,0) -> 1 | AJ22: =IF(AI22=1,SUM($AI$3:AI22),"") -> 20 | AK22: =IFERROR(INDEX($Z$3:$Z$62,MATCH(T22,$AJ$3:$AJ$62,0)),"") -> 0.44919169 | AL22: =IFERROR(INDEX($AB$3:$AB$62,MATCH(T22,$AJ$3:$AJ$62,0)),"") -> 88.606351 | AN22: =IF(ピッキング!$C$26="","",ピッキング!$C$26+ROW()/100000) -> 866.00022
B23: 相関 r | C23: =散布図!$C$10 -> 0.43394684 | D23: p 値 | E23: =散布図!$C$14 -> 0.018675329 | F23: n | G23: =散布図!$C$9 -> 29 | H23: 右上がりは偶然では説明できない | T23: 21 | U23: =IFERROR(INDEX(ピッキング!$B$7:$B$66,MATCH($T23,ピッキング!$A$7:$A$66,0)),"") -> 片岡達也 | V23: =IFERROR(INDEX(ピッキング!$L$7:$L$66,MATCH($T23,ピッキング!$A$7:$A$66,0)),"") -> 93.854517 | W23: =IFERROR(INDEX(梱包!$B$7:$B$66,MATCH($T23,梱包!$A$7:$A$66,0)),"") | X23: =IFERROR(INDEX(梱包!$L$7:$L$66,MATCH($T23,梱包!$A$7:$A$66,0)),"") | Z23: =IF(OR(ピッキング!$E$27="",ピッキング!$C$27=""),"",ピッキング!$E$27/ピッキング!$C$27) -> 0.71212121 | AA23: =IF(ピッキング!$G$27="","",ピッキング!$G$27) -> 183.63636 | AB23: =IF(ピッキング!$P$27="","",ピッキング!$P$27) -> 118.05 | AD23: =IF(AND(ISNUMBER(Z23),ISNUMBER(AA23)),1,0) -> 1 | AE23: =IF(AD23=1,SUM($AD$3:AD23),"") -> 21 | AF23: =IFERROR(INDEX($Z$3:$Z$62,MATCH(T23,$AE$3:$AE$62,0)),"") -> 0.71212121 | AG23: =IFERROR(INDEX($AA$3:$AA$62,MATCH(T23,$AE$3:$AE$62,0)),"") -> 183.63636 | AI23: =IF(AND(ISNUMBER(Z23),ISNUMBER(AB23)),1,0) -> 1 | AJ23: =IF(AI23=1,SUM($AI$3:AI23),"") -> 21 | AK23: =IFERROR(INDEX($Z$3:$Z$62,MATCH(T23,$AJ$3:$AJ$62,0)),"") -> 0.71212121 | AL23: =IFERROR(INDEX($AB$3:$AB$62,MATCH(T23,$AJ$3:$AJ$62,0)),"") -> 118.05 | AN23: =IF(ピッキング!$C$27="","",ピッキング!$C$27+ROW()/100000) -> 66.00023
T24: 22 | U24: =IFERROR(INDEX(ピッキング!$B$7:$B$66,MATCH($T24,ピッキング!$A$7:$A$66,0)),"") -> 廣瀬こずえ | V24: =IFERROR(INDEX(ピッキング!$L$7:$L$66,MATCH($T24,ピッキング!$A$7:$A$66,0)),"") -> 93.746745 | W24: =IFERROR(INDEX(梱包!$B$7:$B$66,MATCH($T24,梱包!$A$7:$A$66,0)),"") | X24: =IFERROR(INDEX(梱包!$L$7:$L$66,MATCH($T24,梱包!$A$7:$A$66,0)),"") | Z24: =IF(OR(ピッキング!$E$28="",ピッキング!$C$28=""),"",ピッキング!$E$28/ピッキング!$C$28) -> 0.52863962 | AA24: =IF(ピッキング!$G$28="","",ピッキング!$G$28) -> 141.19332 | AB24: =IF(ピッキング!$P$28="","",ピッキング!$P$28) -> 92.505609 | AD24: =IF(AND(ISNUMBER(Z24),ISNUMBER(AA24)),1,0) -> 1 | AE24: =IF(AD24=1,SUM($AD$3:AD24),"") -> 22 | AF24: =IFERROR(INDEX($Z$3:$Z$62,MATCH(T24,$AE$3:$AE$62,0)),"") -> 0.52863962 | AG24: =IFERROR(INDEX($AA$3:$AA$62,MATCH(T24,$AE$3:$AE$62,0)),"") -> 141.19332 | AI24: =IF(AND(ISNUMBER(Z24),ISNUMBER(AB24)),1,0) -> 1 | AJ24: =IF(AI24=1,SUM($AI$3:AI24),"") -> 22 | AK24: =IFERROR(INDEX($Z$3:$Z$62,MATCH(T24,$AJ$3:$AJ$62,0)),"") -> 0.52863962 | AL24: =IFERROR(INDEX($AB$3:$AB$62,MATCH(T24,$AJ$3:$AJ$62,0)),"") -> 92.505609 | AN24: =IF(ピッキング!$C$28="","",ピッキング!$C$28+ROW()/100000) -> 838.00024
T25: 23 | U25: =IFERROR(INDEX(ピッキング!$B$7:$B$66,MATCH($T25,ピッキング!$A$7:$A$66,0)),"") -> 森本久美 | V25: =IFERROR(INDEX(ピッキング!$L$7:$L$66,MATCH($T25,ピッキング!$A$7:$A$66,0)),"") -> 91.373442 | W25: =IFERROR(INDEX(梱包!$B$7:$B$66,MATCH($T25,梱包!$A$7:$A$66,0)),"") | X25: =IFERROR(INDEX(梱包!$L$7:$L$66,MATCH($T25,梱包!$A$7:$A$66,0)),"") | Z25: =IF(OR(ピッキング!$E$29="",ピッキング!$C$29=""),"",ピッキング!$E$29/ピッキング!$C$29) -> 0.31940299 | AA25: =IF(ピッキング!$G$29="","",ピッキング!$G$29) -> 128.23881 | AB25: =IF(ピッキング!$P$29="","",ピッキング!$P$29) -> 98.821791 | AD25: =IF(AND(ISNUMBER(Z25),ISNUMBER(AA25)),1,0) -> 1 | AE25: =IF(AD25=1,SUM($AD$3:AD25),"") -> 23 | AF25: =IFERROR(INDEX($Z$3:$Z$62,MATCH(T25,$AE$3:$AE$62,0)),"") -> 0.31940299 | AG25: =IFERROR(INDEX($AA$3:$AA$62,MATCH(T25,$AE$3:$AE$62,0)),"") -> 128.23881 | AI25: =IF(AND(ISNUMBER(Z25),ISNUMBER(AB25)),1,0) -> 1 | AJ25: =IF(AI25=1,SUM($AI$3:AI25),"") -> 23 | AK25: =IFERROR(INDEX($Z$3:$Z$62,MATCH(T25,$AJ$3:$AJ$62,0)),"") -> 0.31940299 | AL25: =IFERROR(INDEX($AB$3:$AB$62,MATCH(T25,$AJ$3:$AJ$62,0)),"") -> 98.821791 | AN25: =IF(ピッキング!$C$29="","",ピッキング!$C$29+ROW()/100000) -> 335.00025
T26: 24 | U26: =IFERROR(INDEX(ピッキング!$B$7:$B$66,MATCH($T26,ピッキング!$A$7:$A$66,0)),"") -> 菊池敬 | V26: =IFERROR(INDEX(ピッキング!$L$7:$L$66,MATCH($T26,ピッキング!$A$7:$A$66,0)),"") -> 91.026073 | W26: =IFERROR(INDEX(梱包!$B$7:$B$66,MATCH($T26,梱包!$A$7:$A$66,0)),"") | X26: =IFERROR(INDEX(梱包!$L$7:$L$66,MATCH($T26,梱包!$A$7:$A$66,0)),"") | Z26: =IF(OR(ピッキング!$E$30="",ピッキング!$C$30=""),"",ピッキング!$E$30/ピッキング!$C$30) -> 0.43838863 | AA26: =IF(ピッキング!$G$30="","",ピッキング!$G$30) -> 135.07109 | AB26: =IF(ピッキング!$P$30="","",ピッキング!$P$30) -> 94.695498 | AD26: =IF(AND(ISNUMBER(Z26),ISNUMBER(AA26)),1,0) -> 1 | AE26: =IF(AD26=1,SUM($AD$3:AD26),"") -> 24 | AF26: =IFERROR(INDEX($Z$3:$Z$62,MATCH(T26,$AE$3:$AE$62,0)),"") -> 0.43838863 | AG26: =IFERROR(INDEX($AA$3:$AA$62,MATCH(T26,$AE$3:$AE$62,0)),"") -> 135.07109 | AI26: =IF(AND(ISNUMBER(Z26),ISNUMBER(AB26)),1,0) -> 1 | AJ26: =IF(AI26=1,SUM($AI$3:AI26),"") -> 24 | AK26: =IFERROR(INDEX($Z$3:$Z$62,MATCH(T26,$AJ$3:$AJ$62,0)),"") -> 0.43838863 | AL26: =IFERROR(INDEX($AB$3:$AB$62,MATCH(T26,$AJ$3:$AJ$62,0)),"") -> 94.695498 | AN26: =IF(ピッキング!$C$30="","",ピッキング!$C$30+ROW()/100000) -> 422.00026
T27: 25 | U27: =IFERROR(INDEX(ピッキング!$B$7:$B$66,MATCH($T27,ピッキング!$A$7:$A$66,0)),"") -> 高橋正美 | V27: =IFERROR(INDEX(ピッキング!$L$7:$L$66,MATCH($T27,ピッキング!$A$7:$A$66,0)),"") -> 89.248471 | W27: =IFERROR(INDEX(梱包!$B$7:$B$66,MATCH($T27,梱包!$A$7:$A$66,0)),"") | X27: =IFERROR(INDEX(梱包!$L$7:$L$66,MATCH($T27,梱包!$A$7:$A$66,0)),"") | Z27: =IF(OR(ピッキング!$E$31="",ピッキング!$C$31=""),"",ピッキング!$E$31/ピッキング!$C$31) -> 0.39266055 | AA27: =IF(ピッキング!$G$31="","",ピッキング!$G$31) -> 138.16514 | AB27: =IF(ピッキング!$P$31="","",ピッキング!$P$31) -> 102.0011 | AD27: =IF(AND(ISNUMBER(Z27),ISNUMBER(AA27)),1,0) -> 1 | AE27: =IF(AD27=1,SUM($AD$3:AD27),"") -> 25 | AF27: =IFERROR(INDEX($Z$3:$Z$62,MATCH(T27,$AE$3:$AE$62,0)),"") -> 0.39266055 | AG27: =IFERROR(INDEX($AA$3:$AA$62,MATCH(T27,$AE$3:$AE$62,0)),"") -> 138.16514 | AI27: =IF(AND(ISNUMBER(Z27),ISNUMBER(AB27)),1,0) -> 1 | AJ27: =IF(AI27=1,SUM($AI$3:AI27),"") -> 25 | AK27: =IFERROR(INDEX($Z$3:$Z$62,MATCH(T27,$AJ$3:$AJ$62,0)),"") -> 0.39266055 | AL27: =IFERROR(INDEX($AB$3:$AB$62,MATCH(T27,$AJ$3:$AJ$62,0)),"") -> 102.0011 | AN27: =IF(ピッキング!$C$31="","",ピッキング!$C$31+ROW()/100000) -> 1090.0003
T28: 26 | U28: =IFERROR(INDEX(ピッキング!$B$7:$B$66,MATCH($T28,ピッキング!$A$7:$A$66,0)),"") -> 秋草文恵 | V28: =IFERROR(INDEX(ピッキング!$L$7:$L$66,MATCH($T28,ピッキング!$A$7:$A$66,0)),"") -> 88.868941 | W28: =IFERROR(INDEX(梱包!$B$7:$B$66,MATCH($T28,梱包!$A$7:$A$66,0)),"") | X28: =IFERROR(INDEX(梱包!$L$7:$L$66,MATCH($T28,梱包!$A$7:$A$66,0)),"") | Z28: =IF(OR(ピッキング!$E$32="",ピッキング!$C$32=""),"",ピッキング!$E$32/ピッキング!$C$32) -> 0.45571096 | AA28: =IF(ピッキング!$G$32="","",ピッキング!$G$32) -> 146.43357 | AB28: =IF(ピッキング!$P$32="","",ピッキング!$P$32) -> 104.46259 | AD28: =IF(AND(ISNUMBER(Z28),ISNUMBER(AA28)),1,0) -> 1 | AE28: =IF(AD28=1,SUM($AD$3:AD28),"") -> 26 | AF28: =IFERROR(INDEX($Z$3:$Z$62,MATCH(T28,$AE$3:$AE$62,0)),"") -> 0.45571096 | AG28: =IFERROR(INDEX($AA$3:$AA$62,MATCH(T28,$AE$3:$AE$62,0)),"") -> 146.43357 | AI28: =IF(AND(ISNUMBER(Z28),ISNUMBER(AB28)),1,0) -> 1 | AJ28: =IF(AI28=1,SUM($AI$3:AI28),"") -> 26 | AK28: =IFERROR(INDEX($Z$3:$Z$62,MATCH(T28,$AJ$3:$AJ$62,0)),"") -> 0.45571096 | AL28: =IFERROR(INDEX($AB$3:$AB$62,MATCH(T28,$AJ$3:$AJ$62,0)),"") -> 104.46259 | AN28: =IF(ピッキング!$C$32="","",ピッキング!$C$32+ROW()/100000) -> 858.00028
T29: 27 | U29: =IFERROR(INDEX(ピッキング!$B$7:$B$66,MATCH($T29,ピッキング!$A$7:$A$66,0)),"") -> 上村和恵 | V29: =IFERROR(INDEX(ピッキング!$L$7:$L$66,MATCH($T29,ピッキング!$A$7:$A$66,0)),"") -> 87.836269 | W29: =IFERROR(INDEX(梱包!$B$7:$B$66,MATCH($T29,梱包!$A$7:$A$66,0)),"") | X29: =IFERROR(INDEX(梱包!$L$7:$L$66,MATCH($T29,梱包!$A$7:$A$66,0)),"") | Z29: =IF(OR(ピッキング!$E$33="",ピッキング!$C$33=""),"",ピッキング!$E$33/ピッキング!$C$33) -> 0.41816547 | AA29: =IF(ピッキング!$G$33="","",ピッキング!$G$33) -> 143.79496 | AB29: =IF(ピッキング!$P$33="","",ピッキング!$P$33) -> 105.28192 | AD29: =IF(AND(ISNUMBER(Z29),ISNUMBER(AA29)),1,0) -> 1 | AE29: =IF(AD29=1,SUM($AD$3:AD29),"") -> 27 | AF29: =IFERROR(INDEX($Z$3:$Z$62,MATCH(T29,$AE$3:$AE$62,0)),"") -> 0.41816547 | AG29: =IFERROR(INDEX($AA$3:$AA$62,MATCH(T29,$AE$3:$AE$62,0)),"") -> 143.79496 | AI29: =IF(AND(ISNUMBER(Z29),ISNUMBER(AB29)),1,0) -> 1 | AJ29: =IF(AI29=1,SUM($AI$3:AI29),"") -> 27 | AK29: =IFERROR(INDEX($Z$3:$Z$62,MATCH(T29,$AJ$3:$AJ$62,0)),"") -> 0.41816547 | AL29: =IFERROR(INDEX($AB$3:$AB$62,MATCH(T29,$AJ$3:$AJ$62,0)),"") -> 105.28192 | AN29: =IF(ピッキング!$C$33="","",ピッキング!$C$33+ROW()/100000) -> 1112.0003
T30: 28 | U30: =IFERROR(INDEX(ピッキング!$B$7:$B$66,MATCH($T30,ピッキング!$A$7:$A$66,0)),"") -> 平田学 | V30: =IFERROR(INDEX(ピッキング!$L$7:$L$66,MATCH($T30,ピッキング!$A$7:$A$66,0)),"") -> 86.502214 | W30: =IFERROR(INDEX(梱包!$B$7:$B$66,MATCH($T30,梱包!$A$7:$A$66,0)),"") | X30: =IFERROR(INDEX(梱包!$L$7:$L$66,MATCH($T30,梱包!$A$7:$A$66,0)),"") | Z30: =IF(OR(ピッキング!$E$34="",ピッキング!$C$34=""),"",ピッキング!$E$34/ピッキング!$C$34) -> 0.4 | AA30: =IF(ピッキング!$G$34="","",ピッキング!$G$34) -> 198.64865 | AB30: =IF(ピッキング!$P$34="","",ピッキング!$P$34) -> 161.80865 | AD30: =IF(AND(ISNUMBER(Z30),ISNUMBER(AA30)),1,0) -> 1 | AE30: =IF(AD30=1,SUM($AD$3:AD30),"") -> 28 | AF30: =IFERROR(INDEX($Z$3:$Z$62,MATCH(T30,$AE$3:$AE$62,0)),"") -> 0.4 | AG30: =IFERROR(INDEX($AA$3:$AA$62,MATCH(T30,$AE$3:$AE$62,0)),"") -> 198.64865 | AI30: =IF(AND(ISNUMBER(Z30),ISNUMBER(AB30)),1,0) -> 1 | AJ30: =IF(AI30=1,SUM($AI$3:AI30),"") -> 28 | AK30: =IFERROR(INDEX($Z$3:$Z$62,MATCH(T30,$AJ$3:$AJ$62,0)),"") -> 0.4 | AL30: =IFERROR(INDEX($AB$3:$AB$62,MATCH(T30,$AJ$3:$AJ$62,0)),"") -> 161.80865 | AN30: =IF(ピッキング!$C$34="","",ピッキング!$C$34+ROW()/100000) -> 370.0003
T31: 29 | U31: =IFERROR(INDEX(ピッキング!$B$7:$B$66,MATCH($T31,ピッキング!$A$7:$A$66,0)),"") -> 飯田由加里 | V31: =IFERROR(INDEX(ピッキング!$L$7:$L$66,MATCH($T31,ピッキング!$A$7:$A$66,0)),"") -> 85.892657 | W31: =IFERROR(INDEX(梱包!$B$7:$B$66,MATCH($T31,梱包!$A$7:$A$66,0)),"") | X31: =IFERROR(INDEX(梱包!$L$7:$L$66,MATCH($T31,梱包!$A$7:$A$66,0)),"") | Z31: =IF(OR(ピッキング!$E$35="",ピッキング!$C$35=""),"",ピッキング!$E$35/ピッキング!$C$35) -> 0.5498155 | AA31: =IF(ピッキング!$G$35="","",ピッキング!$G$35) -> 169.15129 | AB31: =IF(ピッキング!$P$35="","",ピッキング!$P$35) -> 118.51328 | AD31: =IF(AND(ISNUMBER(Z31),ISNUMBER(AA31)),1,0) -> 1 | AE31: =IF(AD31=1,SUM($AD$3:AD31),"") -> 29 | AF31: =IFERROR(INDEX($Z$3:$Z$62,MATCH(T31,$AE$3:$AE$62,0)),"") -> 0.5498155 | AG31: =IFERROR(INDEX($AA$3:$AA$62,MATCH(T31,$AE$3:$AE$62,0)),"") -> 169.15129 | AI31: =IF(AND(ISNUMBER(Z31),ISNUMBER(AB31)),1,0) -> 1 | AJ31: =IF(AI31=1,SUM($AI$3:AI31),"") -> 29 | AK31: =IFERROR(INDEX($Z$3:$Z$62,MATCH(T31,$AJ$3:$AJ$62,0)),"") -> 0.5498155 | AL31: =IFERROR(INDEX($AB$3:$AB$62,MATCH(T31,$AJ$3:$AJ$62,0)),"") -> 118.51328 | AN31: =IF(ピッキング!$C$35="","",ピッキング!$C$35+ROW()/100000) -> 271.00031
T32: 30 | U32: =IFERROR(INDEX(ピッキング!$B$7:$B$66,MATCH($T32,ピッキング!$A$7:$A$66,0)),"") | V32: =IFERROR(INDEX(ピッキング!$L$7:$L$66,MATCH($T32,ピッキング!$A$7:$A$66,0)),"") | W32: =IFERROR(INDEX(梱包!$B$7:$B$66,MATCH($T32,梱包!$A$7:$A$66,0)),"") | X32: =IFERROR(INDEX(梱包!$L$7:$L$66,MATCH($T32,梱包!$A$7:$A$66,0)),"") | Z32: =IF(OR(ピッキング!$E$36="",ピッキング!$C$36=""),"",ピッキング!$E$36/ピッキング!$C$36) | AA32: =IF(ピッキング!$G$36="","",ピッキング!$G$36) | AB32: =IF(ピッキング!$P$36="","",ピッキング!$P$36) | AD32: =IF(AND(ISNUMBER(Z32),ISNUMBER(AA32)),1,0) -> 0 | AE32: =IF(AD32=1,SUM($AD$3:AD32),"") | AF32: =IFERROR(INDEX($Z$3:$Z$62,MATCH(T32,$AE$3:$AE$62,0)),"") | AG32: =IFERROR(INDEX($AA$3:$AA$62,MATCH(T32,$AE$3:$AE$62,0)),"") | AI32: =IF(AND(ISNUMBER(Z32),ISNUMBER(AB32)),1,0) -> 0 | AJ32: =IF(AI32=1,SUM($AI$3:AI32),"") | AK32: =IFERROR(INDEX($Z$3:$Z$62,MATCH(T32,$AJ$3:$AJ$62,0)),"") | AL32: =IFERROR(INDEX($AB$3:$AB$62,MATCH(T32,$AJ$3:$AJ$62,0)),"") | AN32: =IF(ピッキング!$C$36="","",ピッキング!$C$36+ROW()/100000)
T33: 31 | U33: =IFERROR(INDEX(ピッキング!$B$7:$B$66,MATCH($T33,ピッキング!$A$7:$A$66,0)),"") | V33: =IFERROR(INDEX(ピッキング!$L$7:$L$66,MATCH($T33,ピッキング!$A$7:$A$66,0)),"") | W33: =IFERROR(INDEX(梱包!$B$7:$B$66,MATCH($T33,梱包!$A$7:$A$66,0)),"") | X33: =IFERROR(INDEX(梱包!$L$7:$L$66,MATCH($T33,梱包!$A$7:$A$66,0)),"") | Z33: =IF(OR(ピッキング!$E$37="",ピッキング!$C$37=""),"",ピッキング!$E$37/ピッキング!$C$37) | AA33: =IF(ピッキング!$G$37="","",ピッキング!$G$37) | AB33: =IF(ピッキング!$P$37="","",ピッキング!$P$37) | AD33: =IF(AND(ISNUMBER(Z33),ISNUMBER(AA33)),1,0) -> 0 | AE33: =IF(AD33=1,SUM($AD$3:AD33),"") | AF33: =IFERROR(INDEX($Z$3:$Z$62,MATCH(T33,$AE$3:$AE$62,0)),"") | AG33: =IFERROR(INDEX($AA$3:$AA$62,MATCH(T33,$AE$3:$AE$62,0)),"") | AI33: =IF(AND(ISNUMBER(Z33),ISNUMBER(AB33)),1,0) -> 0 | AJ33: =IF(AI33=1,SUM($AI$3:AI33),"") | AK33: =IFERROR(INDEX($Z$3:$Z$62,MATCH(T33,$AJ$3:$AJ$62,0)),"") | AL33: =IFERROR(INDEX($AB$3:$AB$62,MATCH(T33,$AJ$3:$AJ$62,0)),"") | AN33: =IF(ピッキング!$C$37="","",ピッキング!$C$37+ROW()/100000)
T34: 32 | U34: =IFERROR(INDEX(ピッキング!$B$7:$B$66,MATCH($T34,ピッキング!$A$7:$A$66,0)),"") | V34: =IFERROR(INDEX(ピッキング!$L$7:$L$66,MATCH($T34,ピッキング!$A$7:$A$66,0)),"") | W34: =IFERROR(INDEX(梱包!$B$7:$B$66,MATCH($T34,梱包!$A$7:$A$66,0)),"") | X34: =IFERROR(INDEX(梱包!$L$7:$L$66,MATCH($T34,梱包!$A$7:$A$66,0)),"") | Z34: =IF(OR(ピッキング!$E$38="",ピッキング!$C$38=""),"",ピッキング!$E$38/ピッキング!$C$38) | AA34: =IF(ピッキング!$G$38="","",ピッキング!$G$38) | AB34: =IF(ピッキング!$P$38="","",ピッキング!$P$38) | AD34: =IF(AND(ISNUMBER(Z34),ISNUMBER(AA34)),1,0) -> 0 | AE34: =IF(AD34=1,SUM($AD$3:AD34),"") | AF34: =IFERROR(INDEX($Z$3:$Z$62,MATCH(T34,$AE$3:$AE$62,0)),"") | AG34: =IFERROR(INDEX($AA$3:$AA$62,MATCH(T34,$AE$3:$AE$62,0)),"") | AI34: =IF(AND(ISNUMBER(Z34),ISNUMBER(AB34)),1,0) -> 0 | AJ34: =IF(AI34=1,SUM($AI$3:AI34),"") | AK34: =IFERROR(INDEX($Z$3:$Z$62,MATCH(T34,$AJ$3:$AJ$62,0)),"") | AL34: =IFERROR(INDEX($AB$3:$AB$62,MATCH(T34,$AJ$3:$AJ$62,0)),"") | AN34: =IF(ピッキング!$C$38="","",ピッキング!$C$38+ROW()/100000)
T35: 33 | U35: =IFERROR(INDEX(ピッキング!$B$7:$B$66,MATCH($T35,ピッキング!$A$7:$A$66,0)),"") | V35: =IFERROR(INDEX(ピッキング!$L$7:$L$66,MATCH($T35,ピッキング!$A$7:$A$66,0)),"") | W35: =IFERROR(INDEX(梱包!$B$7:$B$66,MATCH($T35,梱包!$A$7:$A$66,0)),"") | X35: =IFERROR(INDEX(梱包!$L$7:$L$66,MATCH($T35,梱包!$A$7:$A$66,0)),"") | Z35: =IF(OR(ピッキング!$E$39="",ピッキング!$C$39=""),"",ピッキング!$E$39/ピッキング!$C$39) | AA35: =IF(ピッキング!$G$39="","",ピッキング!$G$39) | AB35: =IF(ピッキング!$P$39="","",ピッキング!$P$39) | AD35: =IF(AND(ISNUMBER(Z35),ISNUMBER(AA35)),1,0) -> 0 | AE35: =IF(AD35=1,SUM($AD$3:AD35),"") | AF35: =IFERROR(INDEX($Z$3:$Z$62,MATCH(T35,$AE$3:$AE$62,0)),"") | AG35: =IFERROR(INDEX($AA$3:$AA$62,MATCH(T35,$AE$3:$AE$62,0)),"") | AI35: =IF(AND(ISNUMBER(Z35),ISNUMBER(AB35)),1,0) -> 0 | AJ35: =IF(AI35=1,SUM($AI$3:AI35),"") | AK35: =IFERROR(INDEX($Z$3:$Z$62,MATCH(T35,$AJ$3:$AJ$62,0)),"") | AL35: =IFERROR(INDEX($AB$3:$AB$62,MATCH(T35,$AJ$3:$AJ$62,0)),"") | AN35: =IF(ピッキング!$C$39="","",ピッキング!$C$39+ROW()/100000)
T36: 34 | U36: =IFERROR(INDEX(ピッキング!$B$7:$B$66,MATCH($T36,ピッキング!$A$7:$A$66,0)),"") | V36: =IFERROR(INDEX(ピッキング!$L$7:$L$66,MATCH($T36,ピッキング!$A$7:$A$66,0)),"") | W36: =IFERROR(INDEX(梱包!$B$7:$B$66,MATCH($T36,梱包!$A$7:$A$66,0)),"") | X36: =IFERROR(INDEX(梱包!$L$7:$L$66,MATCH($T36,梱包!$A$7:$A$66,0)),"") | Z36: =IF(OR(ピッキング!$E$40="",ピッキング!$C$40=""),"",ピッキング!$E$40/ピッキング!$C$40) | AA36: =IF(ピッキング!$G$40="","",ピッキング!$G$40) | AB36: =IF(ピッキング!$P$40="","",ピッキング!$P$40) | AD36: =IF(AND(ISNUMBER(Z36),ISNUMBER(AA36)),1,0) -> 0 | AE36: =IF(AD36=1,SUM($AD$3:AD36),"") | AF36: =IFERROR(INDEX($Z$3:$Z$62,MATCH(T36,$AE$3:$AE$62,0)),"") | AG36: =IFERROR(INDEX($AA$3:$AA$62,MATCH(T36,$AE$3:$AE$62,0)),"") | AI36: =IF(AND(ISNUMBER(Z36),ISNUMBER(AB36)),1,0) -> 0 | AJ36: =IF(AI36=1,SUM($AI$3:AI36),"") | AK36: =IFERROR(INDEX($Z$3:$Z$62,MATCH(T36,$AJ$3:$AJ$62,0)),"") | AL36: =IFERROR(INDEX($AB$3:$AB$62,MATCH(T36,$AJ$3:$AJ$62,0)),"") | AN36: =IF(ピッキング!$C$40="","",ピッキング!$C$40+ROW()/100000)
T37: 35 | U37: =IFERROR(INDEX(ピッキング!$B$7:$B$66,MATCH($T37,ピッキング!$A$7:$A$66,0)),"") | V37: =IFERROR(INDEX(ピッキング!$L$7:$L$66,MATCH($T37,ピッキング!$A$7:$A$66,0)),"") | W37: =IFERROR(INDEX(梱包!$B$7:$B$66,MATCH($T37,梱包!$A$7:$A$66,0)),"") | X37: =IFERROR(INDEX(梱包!$L$7:$L$66,MATCH($T37,梱包!$A$7:$A$66,0)),"") | Z37: =IF(OR(ピッキング!$E$41="",ピッキング!$C$41=""),"",ピッキング!$E$41/ピッキング!$C$41) | AA37: =IF(ピッキング!$G$41="","",ピッキング!$G$41) | AB37: =IF(ピッキング!$P$41="","",ピッキング!$P$41) | AD37: =IF(AND(ISNUMBER(Z37),ISNUMBER(AA37)),1,0) -> 0 | AE37: =IF(AD37=1,SUM($AD$3:AD37),"") | AF37: =IFERROR(INDEX($Z$3:$Z$62,MATCH(T37,$AE$3:$AE$62,0)),"") | AG37: =IFERROR(INDEX($AA$3:$AA$62,MATCH(T37,$AE$3:$AE$62,0)),"") | AI37: =IF(AND(ISNUMBER(Z37),ISNUMBER(AB37)),1,0) -> 0 | AJ37: =IF(AI37=1,SUM($AI$3:AI37),"") | AK37: =IFERROR(INDEX($Z$3:$Z$62,MATCH(T37,$AJ$3:$AJ$62,0)),"") | AL37: =IFERROR(INDEX($AB$3:$AB$62,MATCH(T37,$AJ$3:$AJ$62,0)),"") | AN37: =IF(ピッキング!$C$41="","",ピッキング!$C$41+ROW()/100000)
T38: 36 | U38: =IFERROR(INDEX(ピッキング!$B$7:$B$66,MATCH($T38,ピッキング!$A$7:$A$66,0)),"") | V38: =IFERROR(INDEX(ピッキング!$L$7:$L$66,MATCH($T38,ピッキング!$A$7:$A$66,0)),"") | W38: =IFERROR(INDEX(梱包!$B$7:$B$66,MATCH($T38,梱包!$A$7:$A$66,0)),"") | X38: =IFERROR(INDEX(梱包!$L$7:$L$66,MATCH($T38,梱包!$A$7:$A$66,0)),"") | Z38: =IF(OR(ピッキング!$E$42="",ピッキング!$C$42=""),"",ピッキング!$E$42/ピッキング!$C$42) | AA38: =IF(ピッキング!$G$42="","",ピッキング!$G$42) | AB38: =IF(ピッキング!$P$42="","",ピッキング!$P$42) | AD38: =IF(AND(ISNUMBER(Z38),ISNUMBER(AA38)),1,0) -> 0 | AE38: =IF(AD38=1,SUM($AD$3:AD38),"") | AF38: =IFERROR(INDEX($Z$3:$Z$62,MATCH(T38,$AE$3:$AE$62,0)),"") | AG38: =IFERROR(INDEX($AA$3:$AA$62,MATCH(T38,$AE$3:$AE$62,0)),"") | AI38: =IF(AND(ISNUMBER(Z38),ISNUMBER(AB38)),1,0) -> 0 | AJ38: =IF(AI38=1,SUM($AI$3:AI38),"") | AK38: =IFERROR(INDEX($Z$3:$Z$62,MATCH(T38,$AJ$3:$AJ$62,0)),"") | AL38: =IFERROR(INDEX($AB$3:$AB$62,MATCH(T38,$AJ$3:$AJ$62,0)),"") | AN38: =IF(ピッキング!$C$42="","",ピッキング!$C$42+ROW()/100000)
T39: 37 | U39: =IFERROR(INDEX(ピッキング!$B$7:$B$66,MATCH($T39,ピッキング!$A$7:$A$66,0)),"") | V39: =IFERROR(INDEX(ピッキング!$L$7:$L$66,MATCH($T39,ピッキング!$A$7:$A$66,0)),"") | W39: =IFERROR(INDEX(梱包!$B$7:$B$66,MATCH($T39,梱包!$A$7:$A$66,0)),"") | X39: =IFERROR(INDEX(梱包!$L$7:$L$66,MATCH($T39,梱包!$A$7:$A$66,0)),"") | Z39: =IF(OR(ピッキング!$E$43="",ピッキング!$C$43=""),"",ピッキング!$E$43/ピッキング!$C$43) | AA39: =IF(ピッキング!$G$43="","",ピッキング!$G$43) | AB39: =IF(ピッキング!$P$43="","",ピッキング!$P$43) | AD39: =IF(AND(ISNUMBER(Z39),ISNUMBER(AA39)),1,0) -> 0 | AE39: =IF(AD39=1,SUM($AD$3:AD39),"") | AF39: =IFERROR(INDEX($Z$3:$Z$62,MATCH(T39,$AE$3:$AE$62,0)),"") | AG39: =IFERROR(INDEX($AA$3:$AA$62,MATCH(T39,$AE$3:$AE$62,0)),"") | AI39: =IF(AND(ISNUMBER(Z39),ISNUMBER(AB39)),1,0) -> 0 | AJ39: =IF(AI39=1,SUM($AI$3:AI39),"") | AK39: =IFERROR(INDEX($Z$3:$Z$62,MATCH(T39,$AJ$3:$AJ$62,0)),"") | AL39: =IFERROR(INDEX($AB$3:$AB$62,MATCH(T39,$AJ$3:$AJ$62,0)),"") | AN39: =IF(ピッキング!$C$43="","",ピッキング!$C$43+ROW()/100000)
T40: 38 | U40: =IFERROR(INDEX(ピッキング!$B$7:$B$66,MATCH($T40,ピッキング!$A$7:$A$66,0)),"") | V40: =IFERROR(INDEX(ピッキング!$L$7:$L$66,MATCH($T40,ピッキング!$A$7:$A$66,0)),"") | W40: =IFERROR(INDEX(梱包!$B$7:$B$66,MATCH($T40,梱包!$A$7:$A$66,0)),"") | X40: =IFERROR(INDEX(梱包!$L$7:$L$66,MATCH($T40,梱包!$A$7:$A$66,0)),"") | Z40: =IF(OR(ピッキング!$E$44="",ピッキング!$C$44=""),"",ピッキング!$E$44/ピッキング!$C$44) | AA40: =IF(ピッキング!$G$44="","",ピッキング!$G$44) | AB40: =IF(ピッキング!$P$44="","",ピッキング!$P$44) | AD40: =IF(AND(ISNUMBER(Z40),ISNUMBER(AA40)),1,0) -> 0 | AE40: =IF(AD40=1,SUM($AD$3:AD40),"") | AF40: =IFERROR(INDEX($Z$3:$Z$62,MATCH(T40,$AE$3:$AE$62,0)),"") | AG40: =IFERROR(INDEX($AA$3:$AA$62,MATCH(T40,$AE$3:$AE$62,0)),"") | AI40: =IF(AND(ISNUMBER(Z40),ISNUMBER(AB40)),1,0) -> 0 | AJ40: =IF(AI40=1,SUM($AI$3:AI40),"") | AK40: =IFERROR(INDEX($Z$3:$Z$62,MATCH(T40,$AJ$3:$AJ$62,0)),"") | AL40: =IFERROR(INDEX($AB$3:$AB$62,MATCH(T40,$AJ$3:$AJ$62,0)),"") | AN40: =IF(ピッキング!$C$44="","",ピッキング!$C$44+ROW()/100000)
...

Sheet 印刷用
B1: 個人別 作業達成度と改善分析（2026年4月） | T1: 達成率 ＝ 標準時間合計 ÷ 実測時間合計 × 100（100%が目標ライン）
B3: ="① 個人別 総合達成率（全員 "&COUNT(印刷用データ!$AS$3:$AS$62)&"名）" -> ① 個人別 総合達成率（全員 29名） | M3: ="④ 改善優先順位（全員 "&COUNT(印刷用データ!$AS$3:$AS$62)&"名）" -> ④ 改善優先順位（全員 29名） | T3: ="② ピッキング・梱包 内訳比較（両工程 "&COUNT(印刷用データ!$Q$3:$Q$62)&"名）" -> ② ピッキング・梱包 内訳比較（両工程 19名）
M4: 順位 | N4: 担当者 | O4: 工程 | P4: 総合達成率 | Q4: 目標との差 (pt) | R4: コメント
M5: =IFERROR(IF(SMALL(印刷用データ!$AM$3:$AM$62,1)>0,1,""),"") -> 1 | N5: =IFERROR(INDEX(印刷用データ!$AG$3:$AG$62,MATCH(SMALL(印刷用データ!$AM$3:$AM$62,1),印刷用データ!$AM$3:$AM$62,0)),"") -> 平田学 | O5: =IFERROR(INDEX(印刷用データ!$AK$3:$AK$62,MATCH(SMALL(印刷用データ!$AM$3:$AM$62,1),印刷用データ!$AM$3:$AM$62,0)),"") -> PKのみ | P5: =IFERROR(INDEX(印刷用データ!$AJ$3:$AJ$62,MATCH(SMALL(印刷用データ!$AM$3:$AM$62,1),印刷用データ!$AM$3:$AM$62,0)),"") -> 56.602449 | Q5: =IF(P5="","",P5-100) -> -43.397551 | R5: =IFERROR(INDEX(印刷用データ!$AL$3:$AL$62,MATCH(SMALL(印刷用データ!$AM$3:$AM$62,1),印刷用データ!$AM$3:$AM$62,0)),"") -> ピッキング改善
M6: =IFERROR(IF(SMALL(印刷用データ!$AM$3:$AM$62,2)>0,2,""),"") -> 2 | N6: =IFERROR(INDEX(印刷用データ!$AG$3:$AG$62,MATCH(SMALL(印刷用データ!$AM$3:$AM$62,2),印刷用データ!$AM$3:$AM$62,0)),"") -> 森田美加 | O6: =IFERROR(INDEX(印刷用データ!$AK$3:$AK$62,MATCH(SMALL(印刷用データ!$AM$3:$AM$62,2),印刷用データ!$AM$3:$AM$62,0)),"") -> 両方 | P6: =IFERROR(INDEX(印刷用データ!$AJ$3:$AJ$62,MATCH(SMALL(印刷用データ!$AM$3:$AM$62,2),印刷用データ!$AM$3:$AM$62,0)),"") -> 60.909812 | Q6: =IF(P6="","",P6-100) -> -39.090188 | R6: =IFERROR(INDEX(印刷用データ!$AL$3:$AL$62,MATCH(SMALL(印刷用データ!$AM$3:$AM$62,2),印刷用データ!$AM$3:$AM$62,0)),"") -> 両工程を見直し
M7: =IFERROR(IF(SMALL(印刷用データ!$AM$3:$AM$62,3)>0,3,""),"") -> 3 | N7: =IFERROR(INDEX(印刷用データ!$AG$3:$AG$62,MATCH(SMALL(印刷用データ!$AM$3:$AM$62,3),印刷用データ!$AM$3:$AM$62,0)),"") -> 菊池敬 | O7: =IFERROR(INDEX(印刷用データ!$AK$3:$AK$62,MATCH(SMALL(印刷用データ!$AM$3:$AM$62,3),印刷用データ!$AM$3:$AM$62,0)),"") -> 両方 | P7: =IFERROR(INDEX(印刷用データ!$AJ$3:$AJ$62,MATCH(SMALL(印刷用データ!$AM$3:$AM$62,3),印刷用データ!$AM$3:$AM$62,0)),"") -> 70.62287 | Q7: =IF(P7="","",P7-100) -> -29.37713 | R7: =IFERROR(INDEX(印刷用データ!$AL$3:$AL$62,MATCH(SMALL(印刷用データ!$AM$3:$AM$62,3),印刷用データ!$AM$3:$AM$62,0)),"") -> 両工程を見直し
M8: =IFERROR(IF(SMALL(印刷用データ!$AM$3:$AM$62,4)>0,4,""),"") -> 4 | N8: =IFERROR(INDEX(印刷用データ!$AG$3:$AG$62,MATCH(SMALL(印刷用データ!$AM$3:$AM$62,4),印刷用データ!$AM$3:$AM$62,0)),"") -> 片岡達也 | O8: =IFERROR(INDEX(印刷用データ!$AK$3:$AK$62,MATCH(SMALL(印刷用データ!$AM$3:$AM$62,4),印刷用データ!$AM$3:$AM$62,0)),"") -> PKのみ | P8: =IFERROR(INDEX(印刷用データ!$AJ$3:$AJ$62,MATCH(SMALL(印刷用データ!$AM$3:$AM$62,4),印刷用データ!$AM$3:$AM$62,0)),"") -> 76.883663 | Q8: =IF(P8="","",P8-100) -> -23.116337 | R8: =IFERROR(INDEX(印刷用データ!$AL$3:$AL$62,MATCH(SMALL(印刷用データ!$AM$3:$AM$62,4),印刷用データ!$AM$3:$AM$62,0)),"") -> ピッキング改善
M9: =IFERROR(IF(SMALL(印刷用データ!$AM$3:$AM$62,5)>0,5,""),"") -> 5 | N9: =IFERROR(INDEX(印刷用データ!$AG$3:$AG$62,MATCH(SMALL(印刷用データ!$AM$3:$AM$62,5),印刷用データ!$AM$3:$AM$62,0)),"") -> 木村千鶴 | O9: =IFERROR(INDEX(印刷用データ!$AK$3:$AK$62,MATCH(SMALL(印刷用データ!$AM$3:$AM$62,5),印刷用データ!$AM$3:$AM$62,0)),"") -> 両方 | P9: =IFERROR(INDEX(印刷用データ!$AJ$3:$AJ$62,MATCH(SMALL(印刷用データ!$AM$3:$AM$62,5),印刷用データ!$AM$3:$AM$62,0)),"") -> 79.319605 | Q9: =IF(P9="","",P9-100) -> -20.680395 | R9: =IFERROR(INDEX(印刷用データ!$AL$3:$AL$62,MATCH(SMALL(印刷用データ!$AM$3:$AM$62,5),印刷用データ!$AM$3:$AM$62,0)),"") -> 両工程を見直し
M10: =IFERROR(IF(SMALL(印刷用データ!$AM$3:$AM$62,6)>0,6,""),"") -> 6 | N10: =IFERROR(INDEX(印刷用データ!$AG$3:$AG$62,MATCH(SMALL(印刷用データ!$AM$3:$AM$62,6),印刷用データ!$AM$3:$AM$62,0)),"") -> 上村和恵 | O10: =IFERROR(INDEX(印刷用データ!$AK$3:$AK$62,MATCH(SMALL(印刷用データ!$AM$3:$AM$62,6),印刷用データ!$AM$3:$AM$62,0)),"") -> PKのみ | P10: =IFERROR(INDEX(印刷用データ!$AJ$3:$AJ$62,MATCH(SMALL(印刷用データ!$AM$3:$AM$62,6),印刷用データ!$AM$3:$AM$62,0)),"") -> 79.358161 | Q10: =IF(P10="","",P10-100) -> -20.641839 | R10: =IFERROR(INDEX(印刷用データ!$AL$3:$AL$62,MATCH(SMALL(印刷用データ!$AM$3:$AM$62,6),印刷用データ!$AM$3:$AM$62,0)),"") -> ピッキング改善
M11: =IFERROR(IF(SMALL(印刷用データ!$AM$3:$AM$62,7)>0,7,""),"") -> 7 | N11: =IFERROR(INDEX(印刷用データ!$AG$3:$AG$62,MATCH(SMALL(印刷用データ!$AM$3:$AM$62,7),印刷用データ!$AM$3:$AM$62,0)),"") -> 秋草文恵 | O11: =IFERROR(INDEX(印刷用データ!$AK$3:$AK$62,MATCH(SMALL(印刷用データ!$AM$3:$AM$62,7),印刷用データ!$AM$3:$AM$62,0)),"") -> PKのみ | P11: =IFERROR(INDEX(印刷用データ!$AJ$3:$AJ$62,MATCH(SMALL(印刷用データ!$AM$3:$AM$62,7),印刷用データ!$AM$3:$AM$62,0)),"") -> 80.289637 | Q11: =IF(P11="","",P11-100) -> -19.710363 | R11: =IFERROR(INDEX(印刷用データ!$AL$3:$AL$62,MATCH(SMALL(印刷用データ!$AM$3:$AM$62,7),印刷用データ!$AM$3:$AM$62,0)),"") -> ピッキング改善
M12: =IFERROR(IF(SMALL(印刷用データ!$AM$3:$AM$62,8)>0,8,""),"") -> 8 | N12: =IFERROR(INDEX(印刷用データ!$AG$3:$AG$62,MATCH(SMALL(印刷用データ!$AM$3:$AM$62,8),印刷用データ!$AM$3:$AM$62,0)),"") -> 高橋正美 | O12: =IFERROR(INDEX(印刷用データ!$AK$3:$AK$62,MATCH(SMALL(印刷用データ!$AM$3:$AM$62,8),印刷用データ!$AM$3:$AM$62,0)),"") -> PKのみ | P12: =IFERROR(INDEX(印刷用データ!$AJ$3:$AJ$62,MATCH(SMALL(印刷用データ!$AM$3:$AM$62,8),印刷用データ!$AM$3:$AM$62,0)),"") -> 80.891633 | Q12: =IF(P12="","",P12-100) -> -19.108367 | R12: =IFERROR(INDEX(印刷用データ!$AL$3:$AL$62,MATCH(SMALL(印刷用データ!$AM$3:$AM$62,8),印刷用データ!$AM$3:$AM$62,0)),"") -> ピッキング改善
M13: =IFERROR(IF(SMALL(印刷用データ!$AM$3:$AM$62,9)>0,9,""),"") -> 9 | N13: =IFERROR(INDEX(印刷用データ!$AG$3:$AG$62,MATCH(SMALL(印刷用データ!$AM$3:$AM$62,9),印刷用データ!$AM$3:$AM$62,0)),"") -> 中村美佳 | O13: =IFERROR(INDEX(印刷用データ!$AK$3:$AK$62,MATCH(SMALL(印刷用データ!$AM$3:$AM$62,9),印刷用データ!$AM$3:$AM$62,0)),"") -> 両方 | P13: =IFERROR(INDEX(印刷用データ!$AJ$3:$AJ$62,MATCH(SMALL(印刷用データ!$AM$3:$AM$62,9),印刷用データ!$AM$3:$AM$62,0)),"") -> 87.373529 | Q13: =IF(P13="","",P13-100) -> -12.626471 | R13: =IFERROR(INDEX(印刷用データ!$AL$3:$AL$62,MATCH(SMALL(印刷用データ!$AM$3:$AM$62,9),印刷用データ!$AM$3:$AM$62,0)),"") -> 梱包手順を改善
M14: =IFERROR(IF(SMALL(印刷用データ!$AM$3:$AM$62,10)>0,10,""),"") -> 10 | N14: =IFERROR(INDEX(印刷用データ!$AG$3:$AG$62,MATCH(SMALL(印刷用データ!$AM$3:$AM$62,10),印刷用データ!$AM$3:$AM$62,0)),"") -> 廣瀬こずえ | O14: =IFERROR(INDEX(印刷用データ!$AK$3:$AK$62,MATCH(SMALL(印刷用データ!$AM$3:$AM$62,10),印刷用データ!$AM$3:$AM$62,0)),"") -> PKのみ | P14: =IFERROR(INDEX(印刷用データ!$AJ$3:$AJ$62,MATCH(SMALL(印刷用データ!$AM$3:$AM$62,10),印刷用データ!$AM$3:$AM$62,0)),"") -> 88.026623 | Q14: =IF(P14="","",P14-100) -> -11.973377 | R14: =IFERROR(INDEX(印刷用データ!$AL$3:$AL$62,MATCH(SMALL(印刷用データ!$AM$3:$AM$62,10),印刷用データ!$AM$3:$AM$62,0)),"") -> ピッキング改善
M15: =IFERROR(IF(SMALL(印刷用データ!$AM$3:$AM$62,11)>0,11,""),"") -> 11 | N15: =IFERROR(INDEX(印刷用データ!$AG$3:$AG$62,MATCH(SMALL(印刷用データ!$AM$3:$AM$62,11),印刷用データ!$AM$3:$AM$62,0)),"") -> 向井ひかり | O15: =IFERROR(INDEX(印刷用データ!$AK$3:$AK$62,MATCH(SMALL(印刷用データ!$AM$3:$AM$62,11),印刷用データ!$AM$3:$AM$62,0)),"") -> PKのみ | P15: =IFERROR(INDEX(印刷用データ!$AJ$3:$AJ$62,MATCH(SMALL(印刷用データ!$AM$3:$AM$62,11),印刷用データ!$AM$3:$AM$62,0)),"") -> 89.993337 | Q15: =IF(P15="","",P15-100) -> -10.006663 | R15: =IFERROR(INDEX(印刷用データ!$AL$3:$AL$62,MATCH(SMALL(印刷用データ!$AM$3:$AM$62,11),印刷用データ!$AM$3:$AM$62,0)),"") -> ピッキング改善
