Workbook
Name dispNames: OFFSET(集計用!$A$2,0,0,MAX(COUNT(集計用!$Z$2:$Z$51),1),1)
Name packTgt: OFFSET(集計用!$AD$2,0,0,MAX(COUNT(集計用!$Z$2:$Z$51),1),1)
Name packVals: OFFSET(集計用!$C$2,0,0,MAX(COUNT(集計用!$Z$2:$Z$51),1),1)
Name pickTgt: OFFSET(集計用!$AC$2,0,0,MAX(COUNT(集計用!$Z$2:$Z$51),1),1)
Name pickVals: OFFSET(集計用!$B$2,0,0,MAX(COUNT(集計用!$Z$2:$Z$51),1),1)
Name rateNames: OFFSET(集計用!$Q$2,0,0,MAX(COUNT(集計用!$AB$2:$AB$51),1),1)
Name rateVals: OFFSET(集計用!$R$2,0,0,MAX(COUNT(集計用!$AB$2:$AB$51),1),1)

Sheet ダッシュボード
B1: 個人別 作業達成度と改善分析（Excelテンプレート）
B2: ="目標：ピッキング"&TEXT(入力!$B$5,"0.0")&"分 / 梱包"&TEXT(入力!$C$5,"0.0")&"分 / 合計"&TEXT(入力!$D$5,"0.0")&"分/個" -> 目標：ピッキング1.6分 / 梱包1.6分 / 合計3.2分/個
B3: 入力シートへ移動 | Q3: ="達成率 ＝ "&TEXT(入力!$D$5,"0.0")&" ÷ 実績合計 × 100"&CHAR(10)&"（実績合計＝ピッキング＋梱包）" -> 達成率 ＝ 3.2 ÷ 実績合計 × 100 （実績合計＝ピッキング＋梱包）
B4: ※このシートが最初に表示されます。入力は「入力」シートの黄色セルへ。
B5: 達成率 | D5: 目標達成人数 | F5: 要改善人数 | H5: 平均ピック | J5: 平均梱包 | L5: 平均合計
B6: =IFERROR(入力!$D$5/AVERAGE(入力!E9:E58),"") -> 1.0537262 | D6: =COUNTIF(入力!F9:F58,">=1") -> 12 | F6: =COUNTIF(入力!I9:I58,">0") -> 7 | H6: =IFERROR(AVERAGE(入力!C9:C58),"") -> 1.552 | J6: =IFERROR(AVERAGE(入力!D9:D58),"") -> 1.5368421 | L6: =IFERROR(AVERAGE(入力!E9:E58),"") -> 3.0368421
B9: ① 個人別 総合達成率
B10: 入力した全員（最大50人）を表示。達成率が高いほど良い。
B50: ② ピッキング・梱包 内訳比較（縦棒）
B51: 入力した全員を縦棒グラフで表示。50人でも崩れにくいよう、名前は縦向き表示。
B92: ③ 改善優先度マトリクス
B93: 入力した全員の名前を直接表示。ラベル位置を分散して重なりを軽減。
B140: ④ 改善優先順位
B141: 入力した全員を優先度順に一覧表示。
B143: 順位 | C143: 担当者 | E143: 合計実績 （分/個） | G143: 目標との差 （分） | I143: コメント
B145: 1 | C145: =集計用!I2 -> 菊池 敬 | E145: =集計用!L2 -> 4.2 | G145: =集計用!M2 -> 1 | I145: =集計用!O2 -> 両工程を見直し
B146: 2 | C146: =集計用!I3 -> 森田 美加 | E146: =集計用!L3 -> 4.2 | G146: =集計用!M3 -> 1 | I146: =集計用!O3 -> 梱包手順を改善
B147: 3 | C147: =集計用!I4 -> 木村 千鶴 | E147: =集計用!L4 -> 3.9 | G147: =集計用!M4 -> 0.7 | I147: =集計用!O4 -> 両工程を見直し
B148: 4 | C148: =集計用!I5 -> 片岡 達也 | E148: =集計用!L5 -> 3.7 | G148: =集計用!M5 -> 0.5 | I148: =集計用!O5 -> ピック導線を改善
B149: 5 | C149: =集計用!I6 -> 廣瀬 こずえ | E149: =集計用!L6 -> 2 | G149: =集計用!M6 -> 0.4 | I149: =集計用!O6 -> ピッキング改善（梱包未入力）
B150: 6 | C150: =集計用!I7 -> 高橋 正美 | E150: =集計用!L7 -> 1.9 | G150: =集計用!M7 -> 0.3 | I150: =集計用!O7 -> ピッキング改善（梱包未入力）
B151: 7 | C151: =集計用!I8 -> 高橋 佐織 | E151: =集計用!L8 -> 3.5 | G151: =集計用!M8 -> 0.3 | I151: =集計用!O8 -> 両工程を見直し
B152: 8 | C152: =集計用!I9 -> 秋草 文恵 | E152: =集計用!L9 -> 1.8 | G152: =集計用!M9 -> 0.2 | I152: =集計用!O9 -> ピッキング改善（梱包未入力）
B153: 9 | C153: =集計用!I10 -> 上村 和恵 | E153: =集計用!L10 -> 1.8 | G153: =集計用!M10 -> 0.2 | I153: =集計用!O10 -> ピッキング改善（梱包未入力）
B154: 10 | C154: =集計用!I11 -> 後藤 克行 | E154: =集計用!L11 -> 3.4 | G154: =集計用!M11 -> 0.2 | I154: =集計用!O11 -> 梱包手順を改善
B155: 11 | C155: =集計用!I12 -> 中納 沙織 | E155: =集計用!L12 -> 3.4 | G155: =集計用!M12 -> 0.2 | I155: =集計用!O12 -> 梱包手順を改善
B156: 12 | C156: =集計用!I13 -> 飯田 由加里 | E156: =集計用!L13 -> 3.2 | G156: =集計用!M13 -> 0 | I156: =集計用!O13 -> 目標達成
... B194: 50 | C194: =集計用!I51 | E194: =集計用!L51 | G194: =集計用!M51 | I194: =集計用!O51
B198: 読み取り方
B199: ① まず「総合達成率」で全員の達成度を確認 | F199: ② 縦棒グラフでピック・梱包のどちらが遅いかを確認 | J199: ③ マトリクスで全員の位置関係と改善方向を確認 | N199: ④ 最後に改善優先順位で、どの担当者から改善するかを決める
B204: ="※目標値：ピッキング"&TEXT(入力!$B$5,"0.0")&"分/個、梱包"&TEXT(入力!$C$5,"0.0")&"分/個、合計"&TEXT(入力!$D$5,"0.0")&"分/個 ／ 達成率＝"&TEXT(入力!$D$5,"0.0")&" ÷ 実績合計 × 100" -> ※目標値：ピッキング1.6分/個、梱包1.6分/個、合計3.2分/個 ／ 達成率＝3.2 ÷ 実績合計 × 100

Sheet 入力
A1: 個人別 作業実績入力シート
A3: 目標値（分/個） | F3: 黄色セルだけ入力してください。 B列=担当者名、C列=ピッキング実績、D列=梱包実績を入力すると、 ダッシュボードには入力した全員（最大50人）が反映されます。
A4: 単位 | B4: ピッキング目標 | C4: 梱包目標 | D4: 合計目標
A5: 分/個 | B5: 1.6 | C5: 1.6 | D5: =B5+C5 -> 3.2
F6: ダッシュボードへ戻る
A8: No | B8: 担当者 | C8: ピッキング実績 （分/個） | D8: 梱包実績 （分/個） | E8: 合計実績 （分/個） | F8: 達成率 | G8: ピック差 （分） | H8: 梱包差 （分） | I8: 目標との差 （分） | J8: 改善分類 | K8: コメント | L8: 優先キー | M8: 達成率キー | N8: 表示順キー | O8: ピッキング件数 | P8: 梱包件数
A9: 1 | B9: 佐藤 辰成 | C9: 1 | D9: 0.5 | E9: =IF(OR(B9="",NOT(ISNUMBER(C9)),NOT(ISNUMBER(D9))),"",C9+D9) -> 1.5 | F9: =IF(OR(E9="",E9=0),"",$D$5/E9) -> 2.1333333 | G9: =IF(OR(B9="",NOT(ISNUMBER(C9))),"",C9-$B$5) -> -0.6 | H9: =IF(OR(B9="",NOT(ISNUMBER(D9))),"",D9-$C$5) -> -1.1 | I9: =IF(OR(E9="",E9=0),"",E9-$D$5) -> -1.7 | J9: =IF(OR(E9="",E9=0),"",IF(AND(G9>0,H9>0),"要改善（両方遅い）",IF(G9>0,"ピッキング改善",IF(H9>0,"梱包改善","良好")))) -> 良好 | K9: =IF(OR(E9="",E9=0),"",IF(AND(G9>0,H9>0),IF(I9>=0.2,"両工程を見直し","両工程を微改善"),IF(AND(I9>0,G9>0),"ピック導線を改善",IF(AND(I9>0,H9>0),"梱包手順を改善",IF(AND(G9<0,H9<0),"良好","目標達成"))))) -> 良好 | L9: =IF(AND(ISNUMBER(C9),ISNUMBER(D9)),IF(OR(E9="",E9=0),-1E+99,I9+ROW()/100000),IF(B9="",-1E+99,IF(ISNUMBER(C9),G9+ROW()/100000,IF(ISNUMBER(D9),H9+ROW()/100000,-1E+99)))) -> -1.69991 | M9: =IF(OR(E9="",E9=0),-1E+99,F9-ROW()/100000) -> 2.1332433 | N9: =IF(B9="","",COUNTA($B$9:B9)) -> 1 | O9: 732 | P9: 505
A10: 2 | B10: 河野 忠 | C10: 1.2 | D10: 1 | E10: =IF(OR(B10="",NOT(ISNUMBER(C10)),NOT(ISNUMBER(D10))),"",C10+D10) -> 2.2 | F10: =IF(OR(E10="",E10=0),"",$D$5/E10) -> 1.4545455 | G10: =IF(OR(B10="",NOT(ISNUMBER(C10))),"",C10-$B$5) -> -0.4 | H10: =IF(OR(B10="",NOT(ISNUMBER(D10))),"",D10-$C$5) -> -0.6 | I10: =IF(OR(E10="",E10=0),"",E10-$D$5) -> -1 | J10: =IF(OR(E10="",E10=0),"",IF(AND(G10>0,H10>0),"要改善（両方遅い）",IF(G10>0,"ピッキング改善",IF(H10>0,"梱包改善","良好")))) -> 良好 | K10: =IF(OR(E10="",E10=0),"",IF(AND(G10>0,H10>0),IF(I10>=0.2,"両工程を見直し","両工程を微改善"),IF(AND(I10>0,G10>0),"ピック導線を改善",IF(AND(I10>0,H10>0),"梱包手順を改善",IF(AND(G10<0,H10<0),"良好","目標達成"))))) -> 良好 | L10: =IF(AND(ISNUMBER(C10),ISNUMBER(D10)),IF(OR(E10="",E10=0),-1E+99,I10+ROW()/100000),IF(B10="",-1E+99,IF(ISNUMBER(C10),G10+ROW()/100000,IF(ISNUMBER(D10),H10+ROW()/100000,-1E+99)))) -> -0.9999 | M10: =IF(OR(E10="",E10=0),-1E+99,F10-ROW()/100000) -> 1.4544455 | N10: =IF(B10="","",COUNTA($B$9:B10)) -> 2 | O10: 365 | P10: 656
A11: 3 | B11: 中納 沙織 | C11: 1.3 | D11: 2.1 | E11: =IF(OR(B11="",NOT(ISNUMBER(C11)),NOT(ISNUMBER(D11))),"",C11+D11) -> 3.4 | F11: =IF(OR(E11="",E11=0),"",$D$5/E11) -> 0.94117647 | G11: =IF(OR(B11="",NOT(ISNUMBER(C11))),"",C11-$B$5) -> -0.3 | H11: =IF(OR(B11="",NOT(ISNUMBER(D11))),"",D11-$C$5) -> 0.5 | I11: =IF(OR(E11="",E11=0),"",E11-$D$5) -> 0.2 | J11: =IF(OR(E11="",E11=0),"",IF(AND(G11>0,H11>0),"要改善（両方遅い）",IF(G11>0,"ピッキング改善",IF(H11>0,"梱包改善","良好")))) -> 梱包改善 | K11: =IF(OR(E11="",E11=0),"",IF(AND(G11>0,H11>0),IF(I11>=0.2,"両工程を見直し","両工程を微改善"),IF(AND(I11>0,G11>0),"ピック導線を改善",IF(AND(I11>0,H11>0),"梱包手順を改善",IF(AND(G11<0,H11<0),"良好","目標達成"))))) -> 梱包手順を改善 | L11: =IF(AND(ISNUMBER(C11),ISNUMBER(D11)),IF(OR(E11="",E11=0),-1E+99,I11+ROW()/100000),IF(B11="",-1E+99,IF(ISNUMBER(C11),G11+ROW()/100000,IF(ISNUMBER(D11),H11+ROW()/100000,-1E+99)))) -> 0.20011 | M11: =IF(OR(E11="",E11=0),-1E+99,F11-ROW()/100000) -> 0.94106647 | N11: =IF(B11="","",COUNTA($B$9:B11)) -> 3 | O11: 1143 | P11: 224
A12: 4 | B12: 澤田 凌 | C12: 1.6 | D12: 1.6 | E12: =IF(OR(B12="",NOT(ISNUMBER(C12)),NOT(ISNUMBER(D12))),"",C12+D12) -> 3.2 | F12: =IF(OR(E12="",E12=0),"",$D$5/E12) -> 1 | G12: =IF(OR(B12="",NOT(ISNUMBER(C12))),"",C12-$B$5) -> 0 | H12: =IF(OR(B12="",NOT(ISNUMBER(D12))),"",D12-$C$5) -> 0 | I12: =IF(OR(E12="",E12=0),"",E12-$D$5) -> 0 | J12: =IF(OR(E12="",E12=0),"",IF(AND(G12>0,H12>0),"要改善（両方遅い）",IF(G12>0,"ピッキング改善",IF(H12>0,"梱包改善","良好")))) -> 良好 | K12: =IF(OR(E12="",E12=0),"",IF(AND(G12>0,H12>0),IF(I12>=0.2,"両工程を見直し","両工程を微改善"),IF(AND(I12>0,G12>0),"ピック導線を改善",IF(AND(I12>0,H12>0),"梱包手順を改善",IF(AND(G12<0,H12<0),"良好","目標達成"))))) -> 目標達成 | L12: =IF(AND(ISNUMBER(C12),ISNUMBER(D12)),IF(OR(E12="",E12=0),-1E+99,I12+ROW()/100000),IF(B12="",-1E+99,IF(ISNUMBER(C12),G12+ROW()/100000,IF(ISNUMBER(D12),H12+ROW()/100000,-1E+99)))) -> 0.00012 | M12: =IF(OR(E12="",E12=0),-1E+99,F12-ROW()/100000) -> 0.99988 | N12: =IF(B12="","",COUNTA($B$9:B12)) -> 4 | O12: 847 | P12: 939
A13: 5 | B13: 佐々木 千恵 | C13: 1.7 | D13: 0.6 | E13: =IF(OR(B13="",NOT(ISNUMBER(C13)),NOT(ISNUMBER(D13))),"",C13+D13) -> 2.3 | F13: =IF(OR(E13="",E13=0),"",$D$5/E13) -> 1.3913043 | G13: =IF(OR(B13="",NOT(ISNUMBER(C13))),"",C13-$B$5) -> 0.1 | H13: =IF(OR(B13="",NOT(ISNUMBER(D13))),"",D13-$C$5) -> -1 | I13: =IF(OR(E13="",E13=0),"",E13-$D$5) -> -0.9 | J13: =IF(OR(E13="",E13=0),"",IF(AND(G13>0,H13>0),"要改善（両方遅い）",IF(G13>0,"ピッキング改善",IF(H13>0,"梱包改善","良好")))) -> ピッキング改善 | K13: =IF(OR(E13="",E13=0),"",IF(AND(G13>0,H13>0),IF(I13>=0.2,"両工程を見直し","両工程を微改善"),IF(AND(I13>0,G13>0),"ピック導線を改善",IF(AND(I13>0,H13>0),"梱包手順を改善",IF(AND(G13<0,H13<0),"良好","目標達成"))))) -> 目標達成 | L13: =IF(AND(ISNUMBER(C13),ISNUMBER(D13)),IF(OR(E13="",E13=0),-1E+99,I13+ROW()/100000),IF(B13="",-1E+99,IF(ISNUMBER(C13),G13+ROW()/100000,IF(ISNUMBER(D13),H13+ROW()/100000,-1E+99)))) -> -0.89987 | M13: =IF(OR(E13="",E13=0),-1E+99,F13-ROW()/100000) -> 1.3911743 | N13: =IF(B13="","",COUNTA($B$9:B13)) -> 5 | O13: 681 | P13: 1223
A14: 6 | B14: 片岡 達也 | C14: 3.1 | D14: 0.6 | E14: =IF(OR(B14="",NOT(ISNUMBER(C14)),NOT(ISNUMBER(D14))),"",C14+D14) -> 3.7 | F14: =IF(OR(E14="",E14=0),"",$D$5/E14) -> 0.86486486 | G14: =IF(OR(B14="",NOT(ISNUMBER(C14))),"",C14-$B$5) -> 1.5 | H14: =IF(OR(B14="",NOT(ISNUMBER(D14))),"",D14-$C$5) -> -1 | I14: =IF(OR(E14="",E14=0),"",E14-$D$5) -> 0.5 | J14: =IF(OR(E14="",E14=0),"",IF(AND(G14>0,H14>0),"要改善（両方遅い）",IF(G14>0,"ピッキング改善",IF(H14>0,"梱包改善","良好")))) -> ピッキング改善 | K14: =IF(OR(E14="",E14=0),"",IF(AND(G14>0,H14>0),IF(I14>=0.2,"両工程を見直し","両工程を微改善"),IF(AND(I14>0,G14>0),"ピック導線を改善",IF(AND(I14>0,H14>0),"梱包手順を改善",IF(AND(G14<0,H14<0),"良好","目標達成"))))) -> ピック導線を改善 | L14: =IF(AND(ISNUMBER(C14),ISNUMBER(D14)),IF(OR(E14="",E14=0),-1E+99,I14+ROW()/100000),IF(B14="",-1E+99,IF(ISNUMBER(C14),G14+ROW()/100000,IF(ISNUMBER(D14),H14+ROW()/100000,-1E+99)))) -> 0.50014 | M14: =IF(OR(E14="",E14=0),-1E+99,F14-ROW()/100000) -> 0.86472486 | N14: =IF(B14="","",COUNTA($B$9:B14)) -> 6 | O14: 66 | P14: 16
A15: 7 | B15: 後藤 克行 | C15: 1.5 | D15: 1.9 | E15: =IF(OR(B15="",NOT(ISNUMBER(C15)),NOT(ISNUMBER(D15))),"",C15+D15) -> 3.4 | F15: =IF(OR(E15="",E15=0),"",$D$5/E15) -> 0.94117647 | G15: =IF(OR(B15="",NOT(ISNUMBER(C15))),"",C15-$B$5) -> -0.1 | H15: =IF(OR(B15="",NOT(ISNUMBER(D15))),"",D15-$C$5) -> 0.3 | I15: =IF(OR(E15="",E15=0),"",E15-$D$5) -> 0.2 | J15: =IF(OR(E15="",E15=0),"",IF(AND(G15>0,H15>0),"要改善（両方遅い）",IF(G15>0,"ピッキング改善",IF(H15>0,"梱包改善","良好")))) -> 梱包改善 | K15: =IF(OR(E15="",E15=0),"",IF(AND(G15>0,H15>0),IF(I15>=0.2,"両工程を見直し","両工程を微改善"),IF(AND(I15>0,G15>0),"ピック導線を改善",IF(AND(I15>0,H15>0),"梱包手順を改善",IF(AND(G15<0,H15<0),"良好","目標達成"))))) -> 梱包手順を改善 | L15: =IF(AND(ISNUMBER(C15),ISNUMBER(D15)),IF(OR(E15="",E15=0),-1E+99,I15+ROW()/100000),IF(B15="",-1E+99,IF(ISNUMBER(C15),G15+ROW()/100000,IF(ISNUMBER(D15),H15+ROW()/100000,-1E+99)))) -> 0.20015 | M15: =IF(OR(E15="",E15=0),-1E+99,F15-ROW()/100000) -> 0.94102647 | N15: =IF(B15="","",COUNTA($B$9:B15)) -> 7 | O15: 2007 | P15: 1421
A16: 8 | B16: 山本 祥吉 | C16: 1.4 | D16: 1.8 | E16: =IF(OR(B16="",NOT(ISNUMBER(C16)),NOT(ISNUMBER(D16))),"",C16+D16) -> 3.2 | F16: =IF(OR(E16="",E16=0),"",$D$5/E16) -> 1 | G16: =IF(OR(B16="",NOT(ISNUMBER(C16))),"",C16-$B$5) -> -0.2 | H16: =IF(OR(B16="",NOT(ISNUMBER(D16))),"",D16-$C$5) -> 0.2 | I16: =IF(OR(E16="",E16=0),"",E16-$D$5) -> 0 | J16: =IF(OR(E16="",E16=0),"",IF(AND(G16>0,H16>0),"要改善（両方遅い）",IF(G16>0,"ピッキング改善",IF(H16>0,"梱包改善","良好")))) -> 梱包改善 | K16: =IF(OR(E16="",E16=0),"",IF(AND(G16>0,H16>0),IF(I16>=0.2,"両工程を見直し","両工程を微改善"),IF(AND(I16>0,G16>0),"ピック導線を改善",IF(AND(I16>0,H16>0),"梱包手順を改善",IF(AND(G16<0,H16<0),"良好","目標達成"))))) -> 目標達成 | L16: =IF(AND(ISNUMBER(C16),ISNUMBER(D16)),IF(OR(E16="",E16=0),-1E+99,I16+ROW()/100000),IF(B16="",-1E+99,IF(ISNUMBER(C16),G16+ROW()/100000,IF(ISNUMBER(D16),H16+ROW()/100000,-1E+99)))) -> 0.00016 | M16: =IF(OR(E16="",E16=0),-1E+99,F16-ROW()/100000) -> 0.99984 | N16: =IF(B16="","",COUNTA($B$9:B16)) -> 8 | O16: 2129 | P16: 1548
A17: 9 | B17: 本吉 有美子 | C17: 1.1 | D17: 1 | E17: =IF(OR(B17="",NOT(ISNUMBER(C17)),NOT(ISNUMBER(D17))),"",C17+D17) -> 2.1 | F17: =IF(OR(E17="",E17=0),"",$D$5/E17) -> 1.5238095 | G17: =IF(OR(B17="",NOT(ISNUMBER(C17))),"",C17-$B$5) -> -0.5 | H17: =IF(OR(B17="",NOT(ISNUMBER(D17))),"",D17-$C$5) -> -0.6 | I17: =IF(OR(E17="",E17=0),"",E17-$D$5) -> -1.1 | J17: =IF(OR(E17="",E17=0),"",IF(AND(G17>0,H17>0),"要改善（両方遅い）",IF(G17>0,"ピッキング改善",IF(H17>0,"梱包改善","良好")))) -> 良好 | K17: =IF(OR(E17="",E17=0),"",IF(AND(G17>0,H17>0),IF(I17>=0.2,"両工程を見直し","両工程を微改善"),IF(AND(I17>0,G17>0),"ピック導線を改善",IF(AND(I17>0,H17>0),"梱包手順を改善",IF(AND(G17<0,H17<0),"良好","目標達成"))))) -> 良好 | L17: =IF(AND(ISNUMBER(C17),ISNUMBER(D17)),IF(OR(E17="",E17=0),-1E+99,I17+ROW()/100000),IF(B17="",-1E+99,IF(ISNUMBER(C17),G17+ROW()/100000,IF(ISNUMBER(D17),H17+ROW()/100000,-1E+99)))) -> -1.09983 | M17: =IF(OR(E17="",E17=0),-1E+99,F17-ROW()/100000) -> 1.5236395 | N17: =IF(B17="","",COUNTA($B$9:B17)) -> 9 | O17: 1454 | P17: 2493
A18: 10 | B18: 屋宮 敬子 | E18: =IF(OR(B18="",NOT(ISNUMBER(C18)),NOT(ISNUMBER(D18))),"",C18+D18) | F18: =IF(OR(E18="",E18=0),"",$D$5/E18) | G18: =IF(OR(B18="",NOT(ISNUMBER(C18))),"",C18-$B$5) | H18: =IF(OR(B18="",NOT(ISNUMBER(D18))),"",D18-$C$5) | I18: =IF(OR(E18="",E18=0),"",E18-$D$5) | J18: =IF(OR(E18="",E18=0),"",IF(AND(G18>0,H18>0),"要改善（両方遅い）",IF(G18>0,"ピッキング改善",IF(H18>0,"梱包改善","良好")))) | K18: =IF(OR(E18="",E18=0),"",IF(AND(G18>0,H18>0),IF(I18>=0.2,"両工程を見直し","両工程を微改善"),IF(AND(I18>0,G18>0),"ピック導線を改善",IF(AND(I18>0,H18>0),"梱包手順を改善",IF(AND(G18<0,H18<0),"良好","目標達成"))))) | L18: =IF(AND(ISNUMBER(C18),ISNUMBER(D18)),IF(OR(E18="",E18=0),-1E+99,I18+ROW()/100000),IF(B18="",-1E+99,IF(ISNUMBER(C18),G18+ROW()/100000,IF(ISNUMBER(D18),H18+ROW()/100000,-1E+99)))) -> -1e+99 | M18: =IF(OR(E18="",E18=0),-1E+99,F18-ROW()/100000) -> -1e+99 | N18: =IF(B18="","",COUNTA($B$9:B18)) -> 10
A19: 11 | B19: 大江 美記子 | C19: 1.2 | D19: 1.2 | E19: =IF(OR(B19="",NOT(ISNUMBER(C19)),NOT(ISNUMBER(D19))),"",C19+D19) -> 2.4 | F19: =IF(OR(E19="",E19=0),"",$D$5/E19) -> 1.3333333 | G19: =IF(OR(B19="",NOT(ISNUMBER(C19))),"",C19-$B$5) -> -0.4 | H19: =IF(OR(B19="",NOT(ISNUMBER(D19))),"",D19-$C$5) -> -0.4 | I19: =IF(OR(E19="",E19=0),"",E19-$D$5) -> -0.8 | J19: =IF(OR(E19="",E19=0),"",IF(AND(G19>0,H19>0),"要改善（両方遅い）",IF(G19>0,"ピッキング改善",IF(H19>0,"梱包改善","良好")))) -> 良好 | K19: =IF(OR(E19="",E19=0),"",IF(AND(G19>0,H19>0),IF(I19>=0.2,"両工程を見直し","両工程を微改善"),IF(AND(I19>0,G19>0),"ピック導線を改善",IF(AND(I19>0,H19>0),"梱包手順を改善",IF(AND(G19<0,H19<0),"良好","目標達成"))))) -> 良好 | L19: =IF(AND(ISNUMBER(C19),ISNUMBER(D19)),IF(OR(E19="",E19=0),-1E+99,I19+ROW()/100000),IF(B19="",-1E+99,IF(ISNUMBER(C19),G19+ROW()/100000,IF(ISNUMBER(D19),H19+ROW()/100000,-1E+99)))) -> -0.79981 | M19: =IF(OR(E19="",E19=0),-1E+99,F19-ROW()/100000) -> 1.3331433 | N19: =IF(B19="","",COUNTA($B$9:B19)) -> 11 | O19: 1053 | P19: 2616
A20: 12 | B20: 木村 千鶴 | C20: 1.7 | D20: 2.2 | E20: =IF(OR(B20="",NOT(ISNUMBER(C20)),NOT(ISNUMBER(D20))),"",C20+D20) -> 3.9 | F20: =IF(OR(E20="",E20=0),"",$D$5/E20) -> 0.82051282 | G20: =IF(OR(B20="",NOT(ISNUMBER(C20))),"",C20-$B$5) -> 0.1 | H20: =IF(OR(B20="",NOT(ISNUMBER(D20))),"",D20-$C$5) -> 0.6 | I20: =IF(OR(E20="",E20=0),"",E20-$D$5) -> 0.7 | J20: =IF(OR(E20="",E20=0),"",IF(AND(G20>0,H20>0),"要改善（両方遅い）",IF(G20>0,"ピッキング改善",IF(H20>0,"梱包改善","良好")))) -> 要改善（両方遅い） | K20: =IF(OR(E20="",E20=0),"",IF(AND(G20>0,H20>0),IF(I20>=0.2,"両工程を見直し","両工程を微改善"),IF(AND(I20>0,G20>0),"ピック導線を改善",IF(AND(I20>0,H20>0),"梱包手順を改善",IF(AND(G20<0,H20<0),"良好","目標達成"))))) -> 両工程を見直し | L20: =IF(AND(ISNUMBER(C20),ISNUMBER(D20)),IF(OR(E20="",E20=0),-1E+99,I20+ROW()/100000),IF(B20="",-1E+99,IF(ISNUMBER(C20),G20+ROW()/100000,IF(ISNUMBER(D20),H20+ROW()/100000,-1E+99)))) -> 0.7002 | M20: =IF(OR(E20="",E20=0),-1E+99,F20-ROW()/100000) -> 0.82031282 | N20: =IF(B20="","",COUNTA($B$9:B20)) -> 12 | O20: 691 | P20: 1750
A21: 13 | B21: 晩田 恵美 | C21: 1.1 | D21: 1.4 | E21: =IF(OR(B21="",NOT(ISNUMBER(C21)),NOT(ISNUMBER(D21))),"",C21+D21) -> 2.5 | F21: =IF(OR(E21="",E21=0),"",$D$5/E21) -> 1.28 | G21: =IF(OR(B21="",NOT(ISNUMBER(C21))),"",C21-$B$5) -> -0.5 | H21: =IF(OR(B21="",NOT(ISNUMBER(D21))),"",D21-$C$5) -> -0.2 | I21: =IF(OR(E21="",E21=0),"",E21-$D$5) -> -0.7 | J21: =IF(OR(E21="",E21=0),"",IF(AND(G21>0,H21>0),"要改善（両方遅い）",IF(G21>0,"ピッキング改善",IF(H21>0,"梱包改善","良好")))) -> 良好 | K21: =IF(OR(E21="",E21=0),"",IF(AND(G21>0,H21>0),IF(I21>=0.2,"両工程を見直し","両工程を微改善"),IF(AND(I21>0,G21>0),"ピック導線を改善",IF(AND(I21>0,H21>0),"梱包手順を改善",IF(AND(G21<0,H21<0),"良好","目標達成"))))) -> 良好 | L21: =IF(AND(ISNUMBER(C21),ISNUMBER(D21)),IF(OR(E21="",E21=0),-1E+99,I21+ROW()/100000),IF(B21="",-1E+99,IF(ISNUMBER(C21),G21+ROW()/100000,IF(ISNUMBER(D21),H21+ROW()/100000,-1E+99)))) -> -0.69979 | M21: =IF(OR(E21="",E21=0),-1E+99,F21-ROW()/100000) -> 1.27979 | N21: =IF(B21="","",COUNTA($B$9:B21)) -> 13 | O21: 877 | P21: 2881
A22: 14 | B22: 森田 美加 | C22: 1.1 | D22: 3.1 | E22: =IF(OR(B22="",NOT(ISNUMBER(C22)),NOT(ISNUMBER(D22))),"",C22+D22) -> 4.2 | F22: =IF(OR(E22="",E22=0),"",$D$5/E22) -> 0.76190476 | G22: =IF(OR(B22="",NOT(ISNUMBER(C22))),"",C22-$B$5) -> -0.5 | H22: =IF(OR(B22="",NOT(ISNUMBER(D22))),"",D22-$C$5) -> 1.5 | I22: =IF(OR(E22="",E22=0),"",E22-$D$5) -> 1 | J22: =IF(OR(E22="",E22=0),"",IF(AND(G22>0,H22>0),"要改善（両方遅い）",IF(G22>0,"ピッキング改善",IF(H22>0,"梱包改善","良好")))) -> 梱包改善 | K22: =IF(OR(E22="",E22=0),"",IF(AND(G22>0,H22>0),IF(I22>=0.2,"両工程を見直し","両工程を微改善"),IF(AND(I22>0,G22>0),"ピック導線を改善",IF(AND(I22>0,H22>0),"梱包手順を改善",IF(AND(G22<0,H22<0),"良好","目標達成"))))) -> 梱包手順を改善 | L22: =IF(AND(ISNUMBER(C22),ISNUMBER(D22)),IF(OR(E22="",E22=0),-1E+99,I22+ROW()/100000),IF(B22="",-1E+99,IF(ISNUMBER(C22),G22+ROW()/100000,IF(ISNUMBER(D22),H22+ROW()/100000,-1E+99)))) -> 1.00022 | M22: =IF(OR(E22="",E22=0),-1E+99,F22-ROW()/100000) -> 0.76168476 | N22: =IF(B22="","",COUNTA($B$9:B22)) -> 14 | O22: 233 | P22: 630
A23: 15 | B23: 飯田 由加里 | C23: 1.8 | D23: 1.4 | E23: =IF(OR(B23="",NOT(ISNUMBER(C23)),NOT(ISNUMBER(D23))),"",C23+D23) -> 3.2 | F23: =IF(OR(E23="",E23=0),"",$D$5/E23) -> 1 | G23: =IF(OR(B23="",NOT(ISNUMBER(C23))),"",C23-$B$5) -> 0.2 | H23: =IF(OR(B23="",NOT(ISNUMBER(D23))),"",D23-$C$5) -> -0.2 | I23: =IF(OR(E23="",E23=0),"",E23-$D$5) -> 0 | J23: =IF(OR(E23="",E23=0),"",IF(AND(G23>0,H23>0),"要改善（両方遅い）",IF(G23>0,"ピッキング改善",IF(H23>0,"梱包改善","良好")))) -> ピッキング改善 | K23: =IF(OR(E23="",E23=0),"",IF(AND(G23>0,H23>0),IF(I23>=0.2,"両工程を見直し","両工程を微改善"),IF(AND(I23>0,G23>0),"ピック導線を改善",IF(AND(I23>0,H23>0),"梱包手順を改善",IF(AND(G23<0,H23<0),"良好","目標達成"))))) -> 目標達成 | L23: =IF(AND(ISNUMBER(C23),ISNUMBER(D23)),IF(OR(E23="",E23=0),-1E+99,I23+ROW()/100000),IF(B23="",-1E+99,IF(ISNUMBER(C23),G23+ROW()/100000,IF(ISNUMBER(D23),H23+ROW()/100000,-1E+99)))) -> 0.00023 | M23: =IF(OR(E23="",E23=0),-1E+99,F23-ROW()/100000) -> 0.99977 | N23: =IF(B23="","",COUNTA($B$9:B23)) -> 15 | O23: 271 | P23: 1061
A24: 16 | B24: 森本 久美 | C24: 1.4 | D24: 1.6 | E24: =IF(OR(B24="",NOT(ISNUMBER(C24)),NOT(ISNUMBER(D24))),"",C24+D24) -> 3 | F24: =IF(OR(E24="",E24=0),"",$D$5/E24) -> 1.0666667 | G24: =IF(OR(B24="",NOT(ISNUMBER(C24))),"",C24-$B$5) -> -0.2 | H24: =IF(OR(B24="",NOT(ISNUMBER(D24))),"",D24-$C$5) -> 0 | I24: =IF(OR(E24="",E24=0),"",E24-$D$5) -> -0.2 | J24: =IF(OR(E24="",E24=0),"",IF(AND(G24>0,H24>0),"要改善（両方遅い）",IF(G24>0,"ピッキング改善",IF(H24>0,"梱包改善","良好")))) -> 良好 | K24: =IF(OR(E24="",E24=0),"",IF(AND(G24>0,H24>0),IF(I24>=0.2,"両工程を見直し","両工程を微改善"),IF(AND(I24>0,G24>0),"ピック導線を改善",IF(AND(I24>0,H24>0),"梱包手順を改善",IF(AND(G24<0,H24<0),"良好","目標達成"))))) -> 目標達成 | L24: =IF(AND(ISNUMBER(C24),ISNUMBER(D24)),IF(OR(E24="",E24=0),-1E+99,I24+ROW()/100000),IF(B24="",-1E+99,IF(ISNUMBER(C24),G24+ROW()/100000,IF(ISNUMBER(D24),H24+ROW()/100000,-1E+99)))) -> -0.19976 | M24: =IF(OR(E24="",E24=0),-1E+99,F24-ROW()/100000) -> 1.0664267 | N24: =IF(B24="","",COUNTA($B$9:B24)) -> 16 | O24: 335 | P24: 970
A25: 17 | B25: 高橋 佐織 | C25: 1.8 | D25: 1.7 | E25: =IF(OR(B25="",NOT(ISNUMBER(C25)),NOT(ISNUMBER(D25))),"",C25+D25) -> 3.5 | F25: =IF(OR(E25="",E25=0),"",$D$5/E25) -> 0.91428571 | G25: =IF(OR(B25="",NOT(ISNUMBER(C25))),"",C25-$B$5) -> 0.2 | H25: =IF(OR(B25="",NOT(ISNUMBER(D25))),"",D25-$C$5) -> 0.1 | I25: =IF(OR(E25="",E25=0),"",E25-$D$5) -> 0.3 | J25: =IF(OR(E25="",E25=0),"",IF(AND(G25>0,H25>0),"要改善（両方遅い）",IF(G25>0,"ピッキング改善",IF(H25>0,"梱包改善","良好")))) -> 要改善（両方遅い） | K25: =IF(OR(E25="",E25=0),"",IF(AND(G25>0,H25>0),IF(I25>=0.2,"両工程を見直し","両工程を微改善"),IF(AND(I25>0,G25>0),"ピック導線を改善",IF(AND(I25>0,H25>0),"梱包手順を改善",IF(AND(G25<0,H25<0),"良好","目標達成"))))) -> 両工程を見直し | L25: =IF(AND(ISNUMBER(C25),ISNUMBER(D25)),IF(OR(E25="",E25=0),-1E+99,I25+ROW()/100000),IF(B25="",-1E+99,IF(ISNUMBER(C25),G25+ROW()/100000,IF(ISNUMBER(D25),H25+ROW()/100000,-1E+99)))) -> 0.30025 | M25: =IF(OR(E25="",E25=0),-1E+99,F25-ROW()/100000) -> 0.91403571 | N25: =IF(B25="","",COUNTA($B$9:B25)) -> 17 | O25: 941 | P25: 1183
A26: 18 | B26: 北田 倫子 | C26: 1.6 | D26: 1.2 | E26: =IF(OR(B26="",NOT(ISNUMBER(C26)),NOT(ISNUMBER(D26))),"",C26+D26) -> 2.8 | F26: =IF(OR(E26="",E26=0),"",$D$5/E26) -> 1.1428571 | G26: =IF(OR(B26="",NOT(ISNUMBER(C26))),"",C26-$B$5) -> 0 | H26: =IF(OR(B26="",NOT(ISNUMBER(D26))),"",D26-$C$5) -> -0.4 | I26: =IF(OR(E26="",E26=0),"",E26-$D$5) -> -0.4 | J26: =IF(OR(E26="",E26=0),"",IF(AND(G26>0,H26>0),"要改善（両方遅い）",IF(G26>0,"ピッキング改善",IF(H26>0,"梱包改善","良好")))) -> 良好 | K26: =IF(OR(E26="",E26=0),"",IF(AND(G26>0,H26>0),IF(I26>=0.2,"両工程を見直し","両工程を微改善"),IF(AND(I26>0,G26>0),"ピック導線を改善",IF(AND(I26>0,H26>0),"梱包手順を改善",IF(AND(G26<0,H26<0),"良好","目標達成"))))) -> 目標達成 | L26: =IF(AND(ISNUMBER(C26),ISNUMBER(D26)),IF(OR(E26="",E26=0),-1E+99,I26+ROW()/100000),IF(B26="",-1E+99,IF(ISNUMBER(C26),G26+ROW()/100000,IF(ISNUMBER(D26),H26+ROW()/100000,-1E+99)))) -> -0.39974 | M26: =IF(OR(E26="",E26=0),-1E+99,F26-ROW()/100000) -> 1.1425971 | N26: =IF(B26="","",COUNTA($B$9:B26)) -> 18 | O26: 468
A27: 19 | B27: 鈴木 香織 | C27: 1.2 | D27: 1.8 | E27: =IF(OR(B27="",NOT(ISNUMBER(C27)),NOT(ISNUMBER(D27))),"",C27+D27) -> 3 | F27: =IF(OR(E27="",E27=0),"",$D$5/E27) -> 1.0666667 | G27: =IF(OR(B27="",NOT(ISNUMBER(C27))),"",C27-$B$5) -> -0.4 | H27: =IF(OR(B27="",NOT(ISNUMBER(D27))),"",D27-$C$5) -> 0.2 | I27: =IF(OR(E27="",E27=0),"",E27-$D$5) -> -0.2 | J27: =IF(OR(E27="",E27=0),"",IF(AND(G27>0,H27>0),"要改善（両方遅い）",IF(G27>0,"ピッキング改善",IF(H27>0,"梱包改善","良好")))) -> 梱包改善 | K27: =IF(OR(E27="",E27=0),"",IF(AND(G27>0,H27>0),IF(I27>=0.2,"両工程を見直し","両工程を微改善"),IF(AND(I27>0,G27>0),"ピック導線を改善",IF(AND(I27>0,H27>0),"梱包手順を改善",IF(AND(G27<0,H27<0),"良好","目標達成"))))) -> 目標達成 | L27: =IF(AND(ISNUMBER(C27),ISNUMBER(D27)),IF(OR(E27="",E27=0),-1E+99,I27+ROW()/100000),IF(B27="",-1E+99,IF(ISNUMBER(C27),G27+ROW()/100000,IF(ISNUMBER(D27),H27+ROW()/100000,-1E+99)))) -> -0.19973 | M27: =IF(OR(E27="",E27=0),-1E+99,F27-ROW()/100000) -> 1.0663967 | N27: =IF(B27="","",COUNTA($B$9:B27)) -> 19 | O27: 260
A28: 20 | B28: 菊池 敬 | C28: 1.7 | D28: 2.5 | E28: =IF(OR(B28="",NOT(ISNUMBER(C28)),NOT(ISNUMBER(D28))),"",C28+D28) -> 4.2 | F28: =IF(OR(E28="",E28=0),"",$D$5/E28) -> 0.76190476 | G28: =IF(OR(B28="",NOT(ISNUMBER(C28))),"",C28-$B$5) -> 0.1 | H28: =IF(OR(B28="",NOT(ISNUMBER(D28))),"",D28-$C$5) -> 0.9 | I28: =IF(OR(E28="",E28=0),"",E28-$D$5) -> 1 | J28: =IF(OR(E28="",E28=0),"",IF(AND(G28>0,H28>0),"要改善（両方遅い）",IF(G28>0,"ピッキング改善",IF(H28>0,"梱包改善","良好")))) -> 要改善（両方遅い） | K28: =IF(OR(E28="",E28=0),"",IF(AND(G28>0,H28>0),IF(I28>=0.2,"両工程を見直し","両工程を微改善"),IF(AND(I28>0,G28>0),"ピック導線を改善",IF(AND(I28>0,H28>0),"梱包手順を改善",IF(AND(G28<0,H28<0),"良好","目標達成"))))) -> 両工程を見直し | L28: =IF(AND(ISNUMBER(C28),ISNUMBER(D28)),IF(OR(E28="",E28=0),-1E+99,I28+ROW()/100000),IF(B28="",-1E+99,IF(ISNUMBER(C28),G28+ROW()/100000,IF(ISNUMBER(D28),H28+ROW()/100000,-1E+99)))) -> 1.00028 | M28: =IF(OR(E28="",E28=0),-1E+99,F28-ROW()/100000) -> 0.76162476 | N28: =IF(B28="","",COUNTA($B$9:B28)) -> 20 | O28: 422
A29: 21 | B29: 上村 和恵 | C29: 1.8 | E29: =IF(OR(B29="",NOT(ISNUMBER(C29)),NOT(ISNUMBER(D29))),"",C29+D29) | F29: =IF(OR(E29="",E29=0),"",$D$5/E29) | G29: =IF(OR(B29="",NOT(ISNUMBER(C29))),"",C29-$B$5) -> 0.2 | H29: =IF(OR(B29="",NOT(ISNUMBER(D29))),"",D29-$C$5) | I29: =IF(OR(E29="",E29=0),"",E29-$D$5) | J29: =IF(OR(E29="",E29=0),"",IF(AND(G29>0,H29>0),"要改善（両方遅い）",IF(G29>0,"ピッキング改善",IF(H29>0,"梱包改善","良好")))) | K29: =IF(OR(E29="",E29=0),"",IF(AND(G29>0,H29>0),IF(I29>=0.2,"両工程を見直し","両工程を微改善"),IF(AND(I29>0,G29>0),"ピック導線を改善",IF(AND(I29>0,H29>0),"梱包手順を改善",IF(AND(G29<0,H29<0),"良好","目標達成"))))) | L29: =IF(AND(ISNUMBER(C29),ISNUMBER(D29)),IF(OR(E29="",E29=0),-1E+99,I29+ROW()/100000),IF(B29="",-1E+99,IF(ISNUMBER(C29),G29+ROW()/100000,IF(ISNUMBER(D29),H29+ROW()/100000,-1E+99)))) -> 0.20029 | M29: =IF(OR(E29="",E29=0),-1E+99,F29-ROW()/100000) -> -1e+99 | N29: =IF(B29="","",COUNTA($B$9:B29)) -> 21 | O29: 1112
A30: 22 | B30: 秋草 文恵 | C30: 1.8 | E30: =IF(OR(B30="",NOT(ISNUMBER(C30)),NOT(ISNUMBER(D30))),"",C30+D30) | F30: =IF(OR(E30="",E30=0),"",$D$5/E30) | G30: =IF(OR(B30="",NOT(ISNUMBER(C30))),"",C30-$B$5) -> 0.2 | H30: =IF(OR(B30="",NOT(ISNUMBER(D30))),"",D30-$C$5) | I30: =IF(OR(E30="",E30=0),"",E30-$D$5) | J30: =IF(OR(E30="",E30=0),"",IF(AND(G30>0,H30>0),"要改善（両方遅い）",IF(G30>0,"ピッキング改善",IF(H30>0,"梱包改善","良好")))) | K30: =IF(OR(E30="",E30=0),"",IF(AND(G30>0,H30>0),IF(I30>=0.2,"両工程を見直し","両工程を微改善"),IF(AND(I30>0,G30>0),"ピック導線を改善",IF(AND(I30>0,H30>0),"梱包手順を改善",IF(AND(G30<0,H30<0),"良好","目標達成"))))) | L30: =IF(AND(ISNUMBER(C30),ISNUMBER(D30)),IF(OR(E30="",E30=0),-1E+99,I30+ROW()/100000),IF(B30="",-1E+99,IF(ISNUMBER(C30),G30+ROW()/100000,IF(ISNUMBER(D30),H30+ROW()/100000,-1E+99)))) -> 0.2003 | M30: =IF(OR(E30="",E30=0),-1E+99,F30-ROW()/100000) -> -1e+99 | N30: =IF(B30="","",COUNTA($B$9:B30)) -> 22 | O30: 858
A31: 23 | B31: 向井 ひかり | C31: 1.5 | E31: =IF(OR(B31="",NOT(ISNUMBER(C31)),NOT(ISNUMBER(D31))),"",C31+D31) | F31: =IF(OR(E31="",E31=0),"",$D$5/E31) | G31: =IF(OR(B31="",NOT(ISNUMBER(C31))),"",C31-$B$5) -> -0.1 | H31: =IF(OR(B31="",NOT(ISNUMBER(D31))),"",D31-$C$5) | I31: =IF(OR(E31="",E31=0),"",E31-$D$5) | J31: =IF(OR(E31="",E31=0),"",IF(AND(G31>0,H31>0),"要改善（両方遅い）",IF(G31>0,"ピッキング改善",IF(H31>0,"梱包改善","良好")))) | K31: =IF(OR(E31="",E31=0),"",IF(AND(G31>0,H31>0),IF(I31>=0.2,"両工程を見直し","両工程を微改善"),IF(AND(I31>0,G31>0),"ピック導線を改善",IF(AND(I31>0,H31>0),"梱包手順を改善",IF(AND(G31<0,H31<0),"良好","目標達成"))))) | L31: =IF(AND(ISNUMBER(C31),ISNUMBER(D31)),IF(OR(E31="",E31=0),-1E+99,I31+ROW()/100000),IF(B31="",-1E+99,IF(ISNUMBER(C31),G31+ROW()/100000,IF(ISNUMBER(D31),H31+ROW()/100000,-1E+99)))) -> -0.09969 | M31: =IF(OR(E31="",E31=0),-1E+99,F31-ROW()/100000) -> -1e+99 | N31: =IF(B31="","",COUNTA($B$9:B31)) -> 23 | O31: 866
A32: 24 | B32: 高橋 正美 | C32: 1.9 | E32: =IF(OR(B32="",NOT(ISNUMBER(C32)),NOT(ISNUMBER(D32))),"",C32+D32) | F32: =IF(OR(E32="",E32=0),"",$D$5/E32) | G32: =IF(OR(B32="",NOT(ISNUMBER(C32))),"",C32-$B$5) -> 0.3 | H32: =IF(OR(B32="",NOT(ISNUMBER(D32))),"",D32-$C$5) | I32: =IF(OR(E32="",E32=0),"",E32-$D$5) | J32: =IF(OR(E32="",E32=0),"",IF(AND(G32>0,H32>0),"要改善（両方遅い）",IF(G32>0,"ピッキング改善",IF(H32>0,"梱包改善","良好")))) | K32: =IF(OR(E32="",E32=0),"",IF(AND(G32>0,H32>0),IF(I32>=0.2,"両工程を見直し","両工程を微改善"),IF(AND(I32>0,G32>0),"ピック導線を改善",IF(AND(I32>0,H32>0),"梱包手順を改善",IF(AND(G32<0,H32<0),"良好","目標達成"))))) | L32: =IF(AND(ISNUMBER(C32),ISNUMBER(D32)),IF(OR(E32="",E32=0),-1E+99,I32+ROW()/100000),IF(B32="",-1E+99,IF(ISNUMBER(C32),G32+ROW()/100000,IF(ISNUMBER(D32),H32+ROW()/100000,-1E+99)))) -> 0.30032 | M32: =IF(OR(E32="",E32=0),-1E+99,F32-ROW()/100000) -> -1e+99 | N32: =IF(B32="","",COUNTA($B$9:B32)) -> 24 | O32: 1090
A33: 25 | B33: 廣瀬 こずえ | C33: 2 | E33: =IF(OR(B33="",NOT(ISNUMBER(C33)),NOT(ISNUMBER(D33))),"",C33+D33) | F33: =IF(OR(E33="",E33=0),"",$D$5/E33) | G33: =IF(OR(B33="",NOT(ISNUMBER(C33))),"",C33-$B$5) -> 0.4 | H33: =IF(OR(B33="",NOT(ISNUMBER(D33))),"",D33-$C$5) | I33: =IF(OR(E33="",E33=0),"",E33-$D$5) | J33: =IF(OR(E33="",E33=0),"",IF(AND(G33>0,H33>0),"要改善（両方遅い）",IF(G33>0,"ピッキング改善",IF(H33>0,"梱包改善","良好")))) | K33: =IF(OR(E33="",E33=0),"",IF(AND(G33>0,H33>0),IF(I33>=0.2,"両工程を見直し","両工程を微改善"),IF(AND(I33>0,G33>0),"ピック導線を改善",IF(AND(I33>0,H33>0),"梱包手順を改善",IF(AND(G33<0,H33<0),"良好","目標達成"))))) | L33: =IF(AND(ISNUMBER(C33),ISNUMBER(D33)),IF(OR(E33="",E33=0),-1E+99,I33+ROW()/100000),IF(B33="",-1E+99,IF(ISNUMBER(C33),G33+ROW()/100000,IF(ISNUMBER(D33),H33+ROW()/100000,-1E+99)))) -> 0.40033 | M33: =IF(OR(E33="",E33=0),-1E+99,F33-ROW()/100000) -> -1e+99 | N33: =IF(B33="","",COUNTA($B$9:B33)) -> 25 | O33: 838
A34: 26 | B34: 石戸谷 亜子 | C34: 1.3 | E34: =IF(OR(B34="",NOT(ISNUMBER(C34)),NOT(ISNUMBER(D34))),"",C34+D34) | F34: =IF(OR(E34="",E34=0),"",$D$5/E34) | G34: =IF(OR(B34="",NOT(ISNUMBER(C34))),"",C34-$B$5) -> -0.3 | H34: =IF(OR(B34="",NOT(ISNUMBER(D34))),"",D34-$C$5) | I34: =IF(OR(E34="",E34=0),"",E34-$D$5) | J34: =IF(OR(E34="",E34=0),"",IF(AND(G34>0,H34>0),"要改善（両方遅い）",IF(G34>0,"ピッキング改善",IF(H34>0,"梱包改善","良好")))) | K34: =IF(OR(E34="",E34=0),"",IF(AND(G34>0,H34>0),IF(I34>=0.2,"両工程を見直し","両工程を微改善"),IF(AND(I34>0,G34>0),"ピック導線を改善",IF(AND(I34>0,H34>0),"梱包手順を改善",IF(AND(G34<0,H34<0),"良好","目標達成"))))) | L34: =IF(AND(ISNUMBER(C34),ISNUMBER(D34)),IF(OR(E34="",E34=0),-1E+99,I34+ROW()/100000),IF(B34="",-1E+99,IF(ISNUMBER(C34),G34+ROW()/100000,IF(ISNUMBER(D34),H34+ROW()/100000,-1E+99)))) -> -0.29966 | M34: =IF(OR(E34="",E34=0),-1E+99,F34-ROW()/100000) -> -1e+99 | N34: =IF(B34="","",COUNTA($B$9:B34)) -> 26
A35: 27 | B35: 奥野 愛海 | E35: =IF(OR(B35="",NOT(ISNUMBER(C35)),NOT(ISNUMBER(D35))),"",C35+D35) | F35: =IF(OR(E35="",E35=0),"",$D$5/E35) | G35: =IF(OR(B35="",NOT(ISNUMBER(C35))),"",C35-$B$5) | H35: =IF(OR(B35="",NOT(ISNUMBER(D35))),"",D35-$C$5) | I35: =IF(OR(E35="",E35=0),"",E35-$D$5) | J35: =IF(OR(E35="",E35=0),"",IF(AND(G35>0,H35>0),"要改善（両方遅い）",IF(G35>0,"ピッキング改善",IF(H35>0,"梱包改善","良好")))) | K35: =IF(OR(E35="",E35=0),"",IF(AND(G35>0,H35>0),IF(I35>=0.2,"両工程を見直し","両工程を微改善"),IF(AND(I35>0,G35>0),"ピック導線を改善",IF(AND(I35>0,H35>0),"梱包手順を改善",IF(AND(G35<0,H35<0),"良好","目標達成"))))) | L35: =IF(AND(ISNUMBER(C35),ISNUMBER(D35)),IF(OR(E35="",E35=0),-1E+99,I35+ROW()/100000),IF(B35="",-1E+99,IF(ISNUMBER(C35),G35+ROW()/100000,IF(ISNUMBER(D35),H35+ROW()/100000,-1E+99)))) -> -1e+99 | M35: =IF(OR(E35="",E35=0),-1E+99,F35-ROW()/100000) -> -1e+99 | N35: =IF(B35="","",COUNTA($B$9:B35)) -> 27
A36: 28 | B36: 平田 学 | E36: =IF(OR(B36="",NOT(ISNUMBER(C36)),NOT(ISNUMBER(D36))),"",C36+D36) | F36: =IF(OR(E36="",E36=0),"",$D$5/E36) | G36: =IF(OR(B36="",NOT(ISNUMBER(C36))),"",C36-$B$5) | H36: =IF(OR(B36="",NOT(ISNUMBER(D36))),"",D36-$C$5) | I36: =IF(OR(E36="",E36=0),"",E36-$D$5) | J36: =IF(OR(E36="",E36=0),"",IF(AND(G36>0,H36>0),"要改善（両方遅い）",IF(G36>0,"ピッキング改善",IF(H36>0,"梱包改善","良好")))) | K36: =IF(OR(E36="",E36=0),"",IF(AND(G36>0,H36>0),IF(I36>=0.2,"両工程を見直し","両工程を微改善"),IF(AND(I36>0,G36>0),"ピック導線を改善",IF(AND(I36>0,H36>0),"梱包手順を改善",IF(AND(G36<0,H36<0),"良好","目標達成"))))) | L36: =IF(AND(ISNUMBER(C36),ISNUMBER(D36)),IF(OR(E36="",E36=0),-1E+99,I36+ROW()/100000),IF(B36="",-1E+99,IF(ISNUMBER(C36),G36+ROW()/100000,IF(ISNUMBER(D36),H36+ROW()/100000,-1E+99)))) -> -1e+99 | M36: =IF(OR(E36="",E36=0),-1E+99,F36-ROW()/100000) -> -1e+99 | N36: =IF(B36="","",COUNTA($B$9:B36)) -> 28
A37: 29 | E37: =IF(OR(B37="",NOT(ISNUMBER(C37)),NOT(ISNUMBER(D37))),"",C37+D37) | F37: =IF(OR(E37="",E37=0),"",$D$5/E37) | G37: =IF(OR(B37="",NOT(ISNUMBER(C37))),"",C37-$B$5) | H37: =IF(OR(B37="",NOT(ISNUMBER(D37))),"",D37-$C$5) | I37: =IF(OR(E37="",E37=0),"",E37-$D$5) | J37: =IF(OR(E37="",E37=0),"",IF(AND(G37>0,H37>0),"要改善（両方遅い）",IF(G37>0,"ピッキング改善",IF(H37>0,"梱包改善","良好")))) | K37: =IF(OR(E37="",E37=0),"",IF(AND(G37>0,H37>0),IF(I37>=0.2,"両工程を見直し","両工程を微改善"),IF(AND(I37>0,G37>0),"ピック導線を改善",IF(AND(I37>0,H37>0),"梱包手順を改善",IF(AND(G37<0,H37<0),"良好","目標達成"))))) | L37: =IF(AND(ISNUMBER(C37),ISNUMBER(D37)),IF(OR(E37="",E37=0),-1E+99,I37+ROW()/100000),IF(B37="",-1E+99,IF(ISNUMBER(C37),G37+ROW()/100000,IF(ISNUMBER(D37),H37+ROW()/100000,-1E+99)))) -> -1e+99 | M37: =IF(OR(E37="",E37=0),-1E+99,F37-ROW()/100000) -> -1e+99 | N37: =IF(B37="","",COUNTA($B$9:B37))
A38: 30 | E38: =IF(OR(B38="",NOT(ISNUMBER(C38)),NOT(ISNUMBER(D38))),"",C38+D38) | F38: =IF(OR(E38="",E38=0),"",$D$5/E38) | G38: =IF(OR(B38="",NOT(ISNUMBER(C38))),"",C38-$B$5) | H38: =IF(OR(B38="",NOT(ISNUMBER(D38))),"",D38-$C$5) | I38: =IF(OR(E38="",E38=0),"",E38-$D$5) | J38: =IF(OR(E38="",E38=0),"",IF(AND(G38>0,H38>0),"要改善（両方遅い）",IF(G38>0,"ピッキング改善",IF(H38>0,"梱包改善","良好")))) | K38: =IF(OR(E38="",E38=0),"",IF(AND(G38>0,H38>0),IF(I38>=0.2,"両工程を見直し","両工程を微改善"),IF(AND(I38>0,G38>0),"ピック導線を改善",IF(AND(I38>0,H38>0),"梱包手順を改善",IF(AND(G38<0,H38<0),"良好","目標達成"))))) | L38: =IF(AND(ISNUMBER(C38),ISNUMBER(D38)),IF(OR(E38="",E38=0),-1E+99,I38+ROW()/100000),IF(B38="",-1E+99,IF(ISNUMBER(C38),G38+ROW()/100000,IF(ISNUMBER(D38),H38+ROW()/100000,-1E+99)))) -> -1e+99 | M38: =IF(OR(E38="",E38=0),-1E+99,F38-ROW()/100000) -> -1e+99 | N38: =IF(B38="","",COUNTA($B$9:B38))
A39: 31 | E39: =IF(OR(B39="",NOT(ISNUMBER(C39)),NOT(ISNUMBER(D39))),"",C39+D39) | F39: =IF(OR(E39="",E39=0),"",$D$5/E39) | G39: =IF(OR(B39="",NOT(ISNUMBER(C39))),"",C39-$B$5) | H39: =IF(OR(B39="",NOT(ISNUMBER(D39))),"",D39-$C$5) | I39: =IF(OR(E39="",E39=0),"",E39-$D$5) | J39: =IF(OR(E39="",E39=0),"",IF(AND(G39>0,H39>0),"要改善（両方遅い）",IF(G39>0,"ピッキング改善",IF(H39>0,"梱包改善","良好")))) | K39: =IF(OR(E39="",E39=0),"",IF(AND(G39>0,H39>0),IF(I39>=0.2,"両工程を見直し","両工程を微改善"),IF(AND(I39>0,G39>0),"ピック導線を改善",IF(AND(I39>0,H39>0),"梱包手順を改善",IF(AND(G39<0,H39<0),"良好","目標達成"))))) | L39: =IF(AND(ISNUMBER(C39),ISNUMBER(D39)),IF(OR(E39="",E39=0),-1E+99,I39+ROW()/100000),IF(B39="",-1E+99,IF(ISNUMBER(C39),G39+ROW()/100000,IF(ISNUMBER(D39),H39+ROW()/100000,-1E+99)))) -> -1e+99 | M39: =IF(OR(E39="",E39=0),-1E+99,F39-ROW()/100000) -> -1e+99 | N39: =IF(B39="","",COUNTA($B$9:B39))
A40: 32 | E40: =IF(OR(B40="",NOT(ISNUMBER(C40)),NOT(ISNUMBER(D40))),"",C40+D40) | F40: =IF(OR(E40="",E40=0),"",$D$5/E40) | G40: =IF(OR(B40="",NOT(ISNUMBER(C40))),"",C40-$B$5) | H40: =IF(OR(B40="",NOT(ISNUMBER(D40))),"",D40-$C$5) | I40: =IF(OR(E40="",E40=0),"",E40-$D$5) | J40: =IF(OR(E40="",E40=0),"",IF(AND(G40>0,H40>0),"要改善（両方遅い）",IF(G40>0,"ピッキング改善",IF(H40>0,"梱包改善","良好")))) | K40: =IF(OR(E40="",E40=0),"",IF(AND(G40>0,H40>0),IF(I40>=0.2,"両工程を見直し","両工程を微改善"),IF(AND(I40>0,G40>0),"ピック導線を改善",IF(AND(I40>0,H40>0),"梱包手順を改善",IF(AND(G40<0,H40<0),"良好","目標達成"))))) | L40: =IF(AND(ISNUMBER(C40),ISNUMBER(D40)),IF(OR(E40="",E40=0),-1E+99,I40+ROW()/100000),IF(B40="",-1E+99,IF(ISNUMBER(C40),G40+ROW()/100000,IF(ISNUMBER(D40),H40+ROW()/100000,-1E+99)))) -> -1e+99 | M40: =IF(OR(E40="",E40=0),-1E+99,F40-ROW()/100000) -> -1e+99 | N40: =IF(B40="","",COUNTA($B$9:B40))
A41: 33 | E41: =IF(OR(B41="",NOT(ISNUMBER(C41)),NOT(ISNUMBER(D41))),"",C41+D41) | F41: =IF(OR(E41="",E41=0),"",$D$5/E41) | G41: =IF(OR(B41="",NOT(ISNUMBER(C41))),"",C41-$B$5) | H41: =IF(OR(B41="",NOT(ISNUMBER(D41))),"",D41-$C$5) | I41: =IF(OR(E41="",E41=0),"",E41-$D$5) | J41: =IF(OR(E41="",E41=0),"",IF(AND(G41>0,H41>0),"要改善（両方遅い）",IF(G41>0,"ピッキング改善",IF(H41>0,"梱包改善","良好")))) | K41: =IF(OR(E41="",E41=0),"",IF(AND(G41>0,H41>0),IF(I41>=0.2,"両工程を見直し","両工程を微改善"),IF(AND(I41>0,G41>0),"ピック導線を改善",IF(AND(I41>0,H41>0),"梱包手順を改善",IF(AND(G41<0,H41<0),"良好","目標達成"))))) | L41: =IF(AND(ISNUMBER(C41),ISNUMBER(D41)),IF(OR(E41="",E41=0),-1E+99,I41+ROW()/100000),IF(B41="",-1E+99,IF(ISNUMBER(C41),G41+ROW()/100000,IF(ISNUMBER(D41),H41+ROW()/100000,-1E+99)))) -> -1e+99 | M41: =IF(OR(E41="",E41=0),-1E+99,F41-ROW()/100000) -> -1e+99 | N41: =IF(B41="","",COUNTA($B$9:B41))
A42: 34 | E42: =IF(OR(B42="",NOT(ISNUMBER(C42)),NOT(ISNUMBER(D42))),"",C42+D42) | F42: =IF(OR(E42="",E42=0),"",$D$5/E42) | G42: =IF(OR(B42="",NOT(ISNUMBER(C42))),"",C42-$B$5) | H42: =IF(OR(B42="",NOT(ISNUMBER(D42))),"",D42-$C$5) | I42: =IF(OR(E42="",E42=0),"",E42-$D$5) | J42: =IF(OR(E42="",E42=0),"",IF(AND(G42>0,H42>0),"要改善（両方遅い）",IF(G42>0,"ピッキング改善",IF(H42>0,"梱包改善","良好")))) | K42: =IF(OR(E42="",E42=0),"",IF(AND(G42>0,H42>0),IF(I42>=0.2,"両工程を見直し","両工程を微改善"),IF(AND(I42>0,G42>0),"ピック導線を改善",IF(AND(I42>0,H42>0),"梱包手順を改善",IF(AND(G42<0,H42<0),"良好","目標達成"))))) | L42: =IF(AND(ISNUMBER(C42),ISNUMBER(D42)),IF(OR(E42="",E42=0),-1E+99,I42+ROW()/100000),IF(B42="",-1E+99,IF(ISNUMBER(C42),G42+ROW()/100000,IF(ISNUMBER(D42),H42+ROW()/100000,-1E+99)))) -> -1e+99 | M42: =IF(OR(E42="",E42=0),-1E+99,F42-ROW()/100000) -> -1e+99 | N42: =IF(B42="","",COUNTA($B$9:B42))
...

Sheet 集計用
A1: 表示順_担当者 | B1: ピック | C1: 梱包 | D1: 合計 | E1: 達成率 | F1: 分類 | G1: コメント | I1: 優先順_担当者 | J1: ピック | K1: 梱包 | L1: 合計 | M1: 合計差 | N1: 分類 | O1: コメント | Q1: 達成率順_担当者 | R1: 達成率 | S1: ピック | T1: 梱包 | U1: 合計 | Z1: 表示用索引 | AA1: 優先順位索引 | AB1: 達成率順位索引 | AC1: 目標ピック | AD1: 目標梱包 | AE1: x基準 | AF1: y最小 | AG1: x最小 | AH1: y基準
A2: =IF($Z2="","",INDEX(入力!$B$9:$B$58,$Z2)) -> 佐藤 辰成 | B2: =IF($Z2="","",IF(INDEX(入力!$C$9:$C$58,$Z2)="","",INDEX(入力!$C$9:$C$58,$Z2))) -> 1 | C2: =IF($Z2="","",IF(INDEX(入力!$D$9:$D$58,$Z2)="","",INDEX(入力!$D$9:$D$58,$Z2))) -> 0.5 | D2: =IF($Z2="","",INDEX(入力!$E$9:$E$58,$Z2)) -> 1.5 | E2: =IF($Z2="","",INDEX(入力!$F$9:$F$58,$Z2)) -> 2.1333333 | F2: =IF($Z2="","",INDEX(入力!$J$9:$J$58,$Z2)) -> 良好 | G2: =IF($Z2="","",INDEX(入力!$K$9:$K$58,$Z2)) -> 良好 | I2: =IF($AA2="","",INDEX(入力!$B$9:$B$58,$AA2)) -> 菊池 敬 | J2: =IF($AA2="","",INDEX(入力!$C$9:$C$58,$AA2)) -> 1.7 | K2: =IF($AA2="","",INDEX(入力!$D$9:$D$58,$AA2)) -> 2.5 | L2: =IF($AA2="","",IF(INDEX(入力!$E$9:$E$58,$AA2)<>"",INDEX(入力!$E$9:$E$58,$AA2),IF(ISNUMBER(INDEX(入力!$C$9:$C$58,$AA2)),INDEX(入力!$C$9:$C$58,$AA2),INDEX(入力!$D$9:$D$58,$AA2)))) -> 4.2 | M2: =IF($AA2="","",IF(INDEX(入力!$I$9:$I$58,$AA2)<>"",INDEX(入力!$I$9:$I$58,$AA2),IF(ISNUMBER(INDEX(入力!$C$9:$C$58,$AA2)),INDEX(入力!$C$9:$C$58,$AA2)-入力!$B$5,INDEX(入力!$D$9:$D$58,$AA2)-入力!$C$5))) -> 1 | N2: =IF($AA2="","",INDEX(入力!$J$9:$J$58,$AA2)) -> 要改善（両方遅い） | O2: =IF($AA2="","",IF(INDEX(入力!$K$9:$K$58,$AA2)<>"",INDEX(入力!$K$9:$K$58,$AA2),IF(ISNUMBER(INDEX(入力!$C$9:$C$58,$AA2)),IF(INDEX(入力!$C$9:$C$58,$AA2)-入力!$B$5>0,"ピッキング改善（梱包未入力）","良好（梱包未入力）"),IF(INDEX(入力!$D$9:$D$58,$AA2)-入力!$C$5>0,"梱包改善（ピッキング未入力）","良好（ピッキング未入力）")))) -> 両工程を見直し | Q2: =IF($AB2="","",INDEX(入力!$B$9:$B$58,$AB2)) -> 佐藤 辰成 | R2: =IF($AB2="","",INDEX(入力!$F$9:$F$58,$AB2)) -> 2.1333333 | S2: =IF($AB2="","",INDEX(入力!$C$9:$C$58,$AB2)) -> 1 | T2: =IF($AB2="","",INDEX(入力!$D$9:$D$58,$AB2)) -> 0.5 | U2: =IF($AB2="","",INDEX(入力!$E$9:$E$58,$AB2)) -> 1.5 | V2: =IF($Z2="","",IF($B2<>"",$B2,IF($C2<>"",入力!$B$5,""))) -> 1 | W2: =IF($Z2="","",IF($C2<>"",$C2,IF($B2<>"",入力!$C$5,""))) -> 0.5 | Z2: =IFERROR(MATCH(ROW()-1,入力!$N$9:$N$58,0),"") -> 1 | AA2: =IF(ROW()-1>COUNTIF(入力!$L$9:$L$58,">-9.9E+98"),"",IFERROR(MATCH(LARGE(入力!$L$9:$L$58,ROW()-1),入力!$L$9:$L$58,0),"")) -> 20 | AB2: =IF(ROW()-1>COUNTIF(入力!$M$9:$M$58,">-9.9E+98"),"",IFERROR(MATCH(LARGE(入力!$M$9:$M$58,ROW()-1),入力!$M$9:$M$58,0),"")) -> 1 | AC2: =入力!$B$5 -> 1.6 | AD2: =入力!$C$5 -> 1.6 | AE2: =入力!$B$5 -> 1.6 | AF2: 1 | AG2: 1 | AH2: =入力!$C$5 -> 1.6
A3: =IF($Z3="","",INDEX(入力!$B$9:$B$58,$Z3)) -> 河野 忠 | B3: =IF($Z3="","",IF(INDEX(入力!$C$9:$C$58,$Z3)="","",INDEX(入力!$C$9:$C$58,$Z3))) -> 1.2 | C3: =IF($Z3="","",IF(INDEX(入力!$D$9:$D$58,$Z3)="","",INDEX(入力!$D$9:$D$58,$Z3))) -> 1 | D3: =IF($Z3="","",INDEX(入力!$E$9:$E$58,$Z3)) -> 2.2 | E3: =IF($Z3="","",INDEX(入力!$F$9:$F$58,$Z3)) -> 1.4545455 | F3: =IF($Z3="","",INDEX(入力!$J$9:$J$58,$Z3)) -> 良好 | G3: =IF($Z3="","",INDEX(入力!$K$9:$K$58,$Z3)) -> 良好 | I3: =IF($AA3="","",INDEX(入力!$B$9:$B$58,$AA3)) -> 森田 美加 | J3: =IF($AA3="","",INDEX(入力!$C$9:$C$58,$AA3)) -> 1.1 | K3: =IF($AA3="","",INDEX(入力!$D$9:$D$58,$AA3)) -> 3.1 | L3: =IF($AA3="","",IF(INDEX(入力!$E$9:$E$58,$AA3)<>"",INDEX(入力!$E$9:$E$58,$AA3),IF(ISNUMBER(INDEX(入力!$C$9:$C$58,$AA3)),INDEX(入力!$C$9:$C$58,$AA3),INDEX(入力!$D$9:$D$58,$AA3)))) -> 4.2 | M3: =IF($AA3="","",IF(INDEX(入力!$I$9:$I$58,$AA3)<>"",INDEX(入力!$I$9:$I$58,$AA3),IF(ISNUMBER(INDEX(入力!$C$9:$C$58,$AA3)),INDEX(入力!$C$9:$C$58,$AA3)-入力!$B$5,INDEX(入力!$D$9:$D$58,$AA3)-入力!$C$5))) -> 1 | N3: =IF($AA3="","",INDEX(入力!$J$9:$J$58,$AA3)) -> 梱包改善 | O3: =IF($AA3="","",IF(INDEX(入力!$K$9:$K$58,$AA3)<>"",INDEX(入力!$K$9:$K$58,$AA3),IF(ISNUMBER(INDEX(入力!$C$9:$C$58,$AA3)),IF(INDEX(入力!$C$9:$C$58,$AA3)-入力!$B$5>0,"ピッキング改善（梱包未入力）","良好（梱包未入力）"),IF(INDEX(入力!$D$9:$D$58,$AA3)-入力!$C$5>0,"梱包改善（ピッキング未入力）","良好（ピッキング未入力）")))) -> 梱包手順を改善 | Q3: =IF($AB3="","",INDEX(入力!$B$9:$B$58,$AB3)) -> 本吉 有美子 | R3: =IF($AB3="","",INDEX(入力!$F$9:$F$58,$AB3)) -> 1.5238095 | S3: =IF($AB3="","",INDEX(入力!$C$9:$C$58,$AB3)) -> 1.1 | T3: =IF($AB3="","",INDEX(入力!$D$9:$D$58,$AB3)) -> 1 | U3: =IF($AB3="","",INDEX(入力!$E$9:$E$58,$AB3)) -> 2.1 | V3: =IF($Z3="","",IF($B3<>"",$B3,IF($C3<>"",入力!$B$5,""))) -> 1.2 | W3: =IF($Z3="","",IF($C3<>"",$C3,IF($B3<>"",入力!$C$5,""))) -> 1 | Z3: =IFERROR(MATCH(ROW()-1,入力!$N$9:$N$58,0),"") -> 2 | AA3: =IF(ROW()-1>COUNTIF(入力!$L$9:$L$58,">-9.9E+98"),"",IFERROR(MATCH(LARGE(入力!$L$9:$L$58,ROW()-1),入力!$L$9:$L$58,0),"")) -> 14 | AB3: =IF(ROW()-1>COUNTIF(入力!$M$9:$M$58,">-9.9E+98"),"",IFERROR(MATCH(LARGE(入力!$M$9:$M$58,ROW()-1),入力!$M$9:$M$58,0),"")) -> 9 | AC3: =入力!$B$5 -> 1.6 | AD3: =入力!$C$5 -> 1.6 | AE3: =入力!$B$5 -> 1.6 | AF3: 2.4 | AG3: 2.4 | AH3: =入力!$C$5 -> 1.6
A4: =IF($Z4="","",INDEX(入力!$B$9:$B$58,$Z4)) -> 中納 沙織 | B4: =IF($Z4="","",IF(INDEX(入力!$C$9:$C$58,$Z4)="","",INDEX(入力!$C$9:$C$58,$Z4))) -> 1.3 | C4: =IF($Z4="","",IF(INDEX(入力!$D$9:$D$58,$Z4)="","",INDEX(入力!$D$9:$D$58,$Z4))) -> 2.1 | D4: =IF($Z4="","",INDEX(入力!$E$9:$E$58,$Z4)) -> 3.4 | E4: =IF($Z4="","",INDEX(入力!$F$9:$F$58,$Z4)) -> 0.94117647 | F4: =IF($Z4="","",INDEX(入力!$J$9:$J$58,$Z4)) -> 梱包改善 | G4: =IF($Z4="","",INDEX(入力!$K$9:$K$58,$Z4)) -> 梱包手順を改善 | I4: =IF($AA4="","",INDEX(入力!$B$9:$B$58,$AA4)) -> 木村 千鶴 | J4: =IF($AA4="","",INDEX(入力!$C$9:$C$58,$AA4)) -> 1.7 | K4: =IF($AA4="","",INDEX(入力!$D$9:$D$58,$AA4)) -> 2.2 | L4: =IF($AA4="","",IF(INDEX(入力!$E$9:$E$58,$AA4)<>"",INDEX(入力!$E$9:$E$58,$AA4),IF(ISNUMBER(INDEX(入力!$C$9:$C$58,$AA4)),INDEX(入力!$C$9:$C$58,$AA4),INDEX(入力!$D$9:$D$58,$AA4)))) -> 3.9 | M4: =IF($AA4="","",IF(INDEX(入力!$I$9:$I$58,$AA4)<>"",INDEX(入力!$I$9:$I$58,$AA4),IF(ISNUMBER(INDEX(入力!$C$9:$C$58,$AA4)),INDEX(入力!$C$9:$C$58,$AA4)-入力!$B$5,INDEX(入力!$D$9:$D$58,$AA4)-入力!$C$5))) -> 0.7 | N4: =IF($AA4="","",INDEX(入力!$J$9:$J$58,$AA4)) -> 要改善（両方遅い） | O4: =IF($AA4="","",IF(INDEX(入力!$K$9:$K$58,$AA4)<>"",INDEX(入力!$K$9:$K$58,$AA4),IF(ISNUMBER(INDEX(入力!$C$9:$C$58,$AA4)),IF(INDEX(入力!$C$9:$C$58,$AA4)-入力!$B$5>0,"ピッキング改善（梱包未入力）","良好（梱包未入力）"),IF(INDEX(入力!$D$9:$D$58,$AA4)-入力!$C$5>0,"梱包改善（ピッキング未入力）","良好（ピッキング未入力）")))) -> 両工程を見直し | Q4: =IF($AB4="","",INDEX(入力!$B$9:$B$58,$AB4)) -> 河野 忠 | R4: =IF($AB4="","",INDEX(入力!$F$9:$F$58,$AB4)) -> 1.4545455 | S4: =IF($AB4="","",INDEX(入力!$C$9:$C$58,$AB4)) -> 1.2 | T4: =IF($AB4="","",INDEX(入力!$D$9:$D$58,$AB4)) -> 1 | U4: =IF($AB4="","",INDEX(入力!$E$9:$E$58,$AB4)) -> 2.2 | V4: =IF($Z4="","",IF($B4<>"",$B4,IF($C4<>"",入力!$B$5,""))) -> 1.3 | W4: =IF($Z4="","",IF($C4<>"",$C4,IF($B4<>"",入力!$C$5,""))) -> 2.1 | Z4: =IFERROR(MATCH(ROW()-1,入力!$N$9:$N$58,0),"") -> 3 | AA4: =IF(ROW()-1>COUNTIF(入力!$L$9:$L$58,">-9.9E+98"),"",IFERROR(MATCH(LARGE(入力!$L$9:$L$58,ROW()-1),入力!$L$9:$L$58,0),"")) -> 12 | AB4: =IF(ROW()-1>COUNTIF(入力!$M$9:$M$58,">-9.9E+98"),"",IFERROR(MATCH(LARGE(入力!$M$9:$M$58,ROW()-1),入力!$M$9:$M$58,0),"")) -> 2 | AC4: =入力!$B$5 -> 1.6 | AD4: =入力!$C$5 -> 1.6
A5: =IF($Z5="","",INDEX(入力!$B$9:$B$58,$Z5)) -> 澤田 凌 | B5: =IF($Z5="","",IF(INDEX(入力!$C$9:$C$58,$Z5)="","",INDEX(入力!$C$9:$C$58,$Z5))) -> 1.6 | C5: =IF($Z5="","",IF(INDEX(入力!$D$9:$D$58,$Z5)="","",INDEX(入力!$D$9:$D$58,$Z5))) -> 1.6 | D5: =IF($Z5="","",INDEX(入力!$E$9:$E$58,$Z5)) -> 3.2 | E5: =IF($Z5="","",INDEX(入力!$F$9:$F$58,$Z5)) -> 1 | F5: =IF($Z5="","",INDEX(入力!$J$9:$J$58,$Z5)) -> 良好 | G5: =IF($Z5="","",INDEX(入力!$K$9:$K$58,$Z5)) -> 目標達成 | I5: =IF($AA5="","",INDEX(入力!$B$9:$B$58,$AA5)) -> 片岡 達也 | J5: =IF($AA5="","",INDEX(入力!$C$9:$C$58,$AA5)) -> 3.1 | K5: =IF($AA5="","",INDEX(入力!$D$9:$D$58,$AA5)) -> 0.6 | L5: =IF($AA5="","",IF(INDEX(入力!$E$9:$E$58,$AA5)<>"",INDEX(入力!$E$9:$E$58,$AA5),IF(ISNUMBER(INDEX(入力!$C$9:$C$58,$AA5)),INDEX(入力!$C$9:$C$58,$AA5),INDEX(入力!$D$9:$D$58,$AA5)))) -> 3.7 | M5: =IF($AA5="","",IF(INDEX(入力!$I$9:$I$58,$AA5)<>"",INDEX(入力!$I$9:$I$58,$AA5),IF(ISNUMBER(INDEX(入力!$C$9:$C$58,$AA5)),INDEX(入力!$C$9:$C$58,$AA5)-入力!$B$5,INDEX(入力!$D$9:$D$58,$AA5)-入力!$C$5))) -> 0.5 | N5: =IF($AA5="","",INDEX(入力!$J$9:$J$58,$AA5)) -> ピッキング改善 | O5: =IF($AA5="","",IF(INDEX(入力!$K$9:$K$58,$AA5)<>"",INDEX(入力!$K$9:$K$58,$AA5),IF(ISNUMBER(INDEX(入力!$C$9:$C$58,$AA5)),IF(INDEX(入力!$C$9:$C$58,$AA5)-入力!$B$5>0,"ピッキング改善（梱包未入力）","良好（梱包未入力）"),IF(INDEX(入力!$D$9:$D$58,$AA5)-入力!$C$5>0,"梱包改善（ピッキング未入力）","良好（ピッキング未入力）")))) -> ピック導線を改善 | Q5: =IF($AB5="","",INDEX(入力!$B$9:$B$58,$AB5)) -> 佐々木 千恵 | R5: =IF($AB5="","",INDEX(入力!$F$9:$F$58,$AB5)) -> 1.3913043 | S5: =IF($AB5="","",INDEX(入力!$C$9:$C$58,$AB5)) -> 1.7 | T5: =IF($AB5="","",INDEX(入力!$D$9:$D$58,$AB5)) -> 0.6 | U5: =IF($AB5="","",INDEX(入力!$E$9:$E$58,$AB5)) -> 2.3 | V5: =IF($Z5="","",IF($B5<>"",$B5,IF($C5<>"",入力!$B$5,""))) -> 1.6 | W5: =IF($Z5="","",IF($C5<>"",$C5,IF($B5<>"",入力!$C$5,""))) -> 1.6 | Z5: =IFERROR(MATCH(ROW()-1,入力!$N$9:$N$58,0),"") -> 4 | AA5: =IF(ROW()-1>COUNTIF(入力!$L$9:$L$58,">-9.9E+98"),"",IFERROR(MATCH(LARGE(入力!$L$9:$L$58,ROW()-1),入力!$L$9:$L$58,0),"")) -> 6 | AB5: =IF(ROW()-1>COUNTIF(入力!$M$9:$M$58,">-9.9E+98"),"",IFERROR(MATCH(LARGE(入力!$M$9:$M$58,ROW()-1),入力!$M$9:$M$58,0),"")) -> 5 | AC5: =入力!$B$5 -> 1.6 | AD5: =入力!$C$5 -> 1.6
A6: =IF($Z6="","",INDEX(入力!$B$9:$B$58,$Z6)) -> 佐々木 千恵 | B6: =IF($Z6="","",IF(INDEX(入力!$C$9:$C$58,$Z6)="","",INDEX(入力!$C$9:$C$58,$Z6))) -> 1.7 | C6: =IF($Z6="","",IF(INDEX(入力!$D$9:$D$58,$Z6)="","",INDEX(入力!$D$9:$D$58,$Z6))) -> 0.6 | D6: =IF($Z6="","",INDEX(入力!$E$9:$E$58,$Z6)) -> 2.3 | E6: =IF($Z6="","",INDEX(入力!$F$9:$F$58,$Z6)) -> 1.3913043 | F6: =IF($Z6="","",INDEX(入力!$J$9:$J$58,$Z6)) -> ピッキング改善 | G6: =IF($Z6="","",INDEX(入力!$K$9:$K$58,$Z6)) -> 目標達成 | I6: =IF($AA6="","",INDEX(入力!$B$9:$B$58,$AA6)) -> 廣瀬 こずえ | J6: =IF($AA6="","",INDEX(入力!$C$9:$C$58,$AA6)) -> 2 | K6: =IF($AA6="","",INDEX(入力!$D$9:$D$58,$AA6)) -> 0 | L6: =IF($AA6="","",IF(INDEX(入力!$E$9:$E$58,$AA6)<>"",INDEX(入力!$E$9:$E$58,$AA6),IF(ISNUMBER(INDEX(入力!$C$9:$C$58,$AA6)),INDEX(入力!$C$9:$C$58,$AA6),INDEX(入力!$D$9:$D$58,$AA6)))) -> 2 | M6: =IF($AA6="","",IF(INDEX(入力!$I$9:$I$58,$AA6)<>"",INDEX(入力!$I$9:$I$58,$AA6),IF(ISNUMBER(INDEX(入力!$C$9:$C$58,$AA6)),INDEX(入力!$C$9:$C$58,$AA6)-入力!$B$5,INDEX(入力!$D$9:$D$58,$AA6)-入力!$C$5))) -> 0.4 | N6: =IF($AA6="","",INDEX(入力!$J$9:$J$58,$AA6)) | O6: =IF($AA6="","",IF(INDEX(入力!$K$9:$K$58,$AA6)<>"",INDEX(入力!$K$9:$K$58,$AA6),IF(ISNUMBER(INDEX(入力!$C$9:$C$58,$AA6)),IF(INDEX(入力!$C$9:$C$58,$AA6)-入力!$B$5>0,"ピッキング改善（梱包未入力）","良好（梱包未入力）"),IF(INDEX(入力!$D$9:$D$58,$AA6)-入力!$C$5>0,"梱包改善（ピッキング未入力）","良好（ピッキング未入力）")))) -> ピッキング改善（梱包未入力） | Q6: =IF($AB6="","",INDEX(入力!$B$9:$B$58,$AB6)) -> 大江 美記子 | R6: =IF($AB6="","",INDEX(入力!$F$9:$F$58,$AB6)) -> 1.3333333 | S6: =IF($AB6="","",INDEX(入力!$C$9:$C$58,$AB6)) -> 1.2 | T6: =IF($AB6="","",INDEX(入力!$D$9:$D$58,$AB6)) -> 1.2 | U6: =IF($AB6="","",INDEX(入力!$E$9:$E$58,$AB6)) -> 2.4 | V6: =IF($Z6="","",IF($B6<>"",$B6,IF($C6<>"",入力!$B$5,""))) -> 1.7 | W6: =IF($Z6="","",IF($C6<>"",$C6,IF($B6<>"",入力!$C$5,""))) -> 0.6 | Z6: =IFERROR(MATCH(ROW()-1,入力!$N$9:$N$58,0),"") -> 5 | AA6: =IF(ROW()-1>COUNTIF(入力!$L$9:$L$58,">-9.9E+98"),"",IFERROR(MATCH(LARGE(入力!$L$9:$L$58,ROW()-1),入力!$L$9:$L$58,0),"")) -> 25 | AB6: =IF(ROW()-1>COUNTIF(入力!$M$9:$M$58,">-9.9E+98"),"",IFERROR(MATCH(LARGE(入力!$M$9:$M$58,ROW()-1),入力!$M$9:$M$58,0),"")) -> 11 | AC6: =入力!$B$5 -> 1.6 | AD6: =入力!$C$5 -> 1.6
A7: =IF($Z7="","",INDEX(入力!$B$9:$B$58,$Z7)) -> 片岡 達也 | B7: =IF($Z7="","",IF(INDEX(入力!$C$9:$C$58,$Z7)="","",INDEX(入力!$C$9:$C$58,$Z7))) -> 3.1 | C7: =IF($Z7="","",IF(INDEX(入力!$D$9:$D$58,$Z7)="","",INDEX(入力!$D$9:$D$58,$Z7))) -> 0.6 | D7: =IF($Z7="","",INDEX(入力!$E$9:$E$58,$Z7)) -> 3.7 | E7: =IF($Z7="","",INDEX(入力!$F$9:$F$58,$Z7)) -> 0.86486486 | F7: =IF($Z7="","",INDEX(入力!$J$9:$J$58,$Z7)) -> ピッキング改善 | G7: =IF($Z7="","",INDEX(入力!$K$9:$K$58,$Z7)) -> ピック導線を改善 | I7: =IF($AA7="","",INDEX(入力!$B$9:$B$58,$AA7)) -> 高橋 正美 | J7: =IF($AA7="","",INDEX(入力!$C$9:$C$58,$AA7)) -> 1.9 | K7: =IF($AA7="","",INDEX(入力!$D$9:$D$58,$AA7)) -> 0 | L7: =IF($AA7="","",IF(INDEX(入力!$E$9:$E$58,$AA7)<>"",INDEX(入力!$E$9:$E$58,$AA7),IF(ISNUMBER(INDEX(入力!$C$9:$C$58,$AA7)),INDEX(入力!$C$9:$C$58,$AA7),INDEX(入力!$D$9:$D$58,$AA7)))) -> 1.9 | M7: =IF($AA7="","",IF(INDEX(入力!$I$9:$I$58,$AA7)<>"",INDEX(入力!$I$9:$I$58,$AA7),IF(ISNUMBER(INDEX(入力!$C$9:$C$58,$AA7)),INDEX(入力!$C$9:$C$58,$AA7)-入力!$B$5,INDEX(入力!$D$9:$D$58,$AA7)-入力!$C$5))) -> 0.3 | N7: =IF($AA7="","",INDEX(入力!$J$9:$J$58,$AA7)) | O7: =IF($AA7="","",IF(INDEX(入力!$K$9:$K$58,$AA7)<>"",INDEX(入力!$K$9:$K$58,$AA7),IF(ISNUMBER(INDEX(入力!$C$9:$C$58,$AA7)),IF(INDEX(入力!$C$9:$C$58,$AA7)-入力!$B$5>0,"ピッキング改善（梱包未入力）","良好（梱包未入力）"),IF(INDEX(入力!$D$9:$D$58,$AA7)-入力!$C$5>0,"梱包改善（ピッキング未入力）","良好（ピッキング未入力）")))) -> ピッキング改善（梱包未入力） | Q7: =IF($AB7="","",INDEX(入力!$B$9:$B$58,$AB7)) -> 晩田 恵美 | R7: =IF($AB7="","",INDEX(入力!$F$9:$F$58,$AB7)) -> 1.28 | S7: =IF($AB7="","",INDEX(入力!$C$9:$C$58,$AB7)) -> 1.1 | T7: =IF($AB7="","",INDEX(入力!$D$9:$D$58,$AB7)) -> 1.4 | U7: =IF($AB7="","",INDEX(入力!$E$9:$E$58,$AB7)) -> 2.5 | V7: =IF($Z7="","",IF($B7<>"",$B7,IF($C7<>"",入力!$B$5,""))) -> 3.1 | W7: =IF($Z7="","",IF($C7<>"",$C7,IF($B7<>"",入力!$C$5,""))) -> 0.6 | Z7: =IFERROR(MATCH(ROW()-1,入力!$N$9:$N$58,0),"") -> 6 | AA7: =IF(ROW()-1>COUNTIF(入力!$L$9:$L$58,">-9.9E+98"),"",IFERROR(MATCH(LARGE(入力!$L$9:$L$58,ROW()-1),入力!$L$9:$L$58,0),"")) -> 24 | AB7: =IF(ROW()-1>COUNTIF(入力!$M$9:$M$58,">-9.9E+98"),"",IFERROR(MATCH(LARGE(入力!$M$9:$M$58,ROW()-1),入力!$M$9:$M$58,0),"")) -> 13 | AC7: =入力!$B$5 -> 1.6 | AD7: =入力!$C$5 -> 1.6
A8: =IF($Z8="","",INDEX(入力!$B$9:$B$58,$Z8)) -> 後藤 克行 | B8: =IF($Z8="","",IF(INDEX(入力!$C$9:$C$58,$Z8)="","",INDEX(入力!$C$9:$C$58,$Z8))) -> 1.5 | C8: =IF($Z8="","",IF(INDEX(入力!$D$9:$D$58,$Z8)="","",INDEX(入力!$D$9:$D$58,$Z8))) -> 1.9 | D8: =IF($Z8="","",INDEX(入力!$E$9:$E$58,$Z8)) -> 3.4 | E8: =IF($Z8="","",INDEX(入力!$F$9:$F$58,$Z8)) -> 0.94117647 | F8: =IF($Z8="","",INDEX(入力!$J$9:$J$58,$Z8)) -> 梱包改善 | G8: =IF($Z8="","",INDEX(入力!$K$9:$K$58,$Z8)) -> 梱包手順を改善 | I8: =IF($AA8="","",INDEX(入力!$B$9:$B$58,$AA8)) -> 高橋 佐織 | J8: =IF($AA8="","",INDEX(入力!$C$9:$C$58,$AA8)) -> 1.8 | K8: =IF($AA8="","",INDEX(入力!$D$9:$D$58,$AA8)) -> 1.7 | L8: =IF($AA8="","",IF(INDEX(入力!$E$9:$E$58,$AA8)<>"",INDEX(入力!$E$9:$E$58,$AA8),IF(ISNUMBER(INDEX(入力!$C$9:$C$58,$AA8)),INDEX(入力!$C$9:$C$58,$AA8),INDEX(入力!$D$9:$D$58,$AA8)))) -> 3.5 | M8: =IF($AA8="","",IF(INDEX(入力!$I$9:$I$58,$AA8)<>"",INDEX(入力!$I$9:$I$58,$AA8),IF(ISNUMBER(INDEX(入力!$C$9:$C$58,$AA8)),INDEX(入力!$C$9:$C$58,$AA8)-入力!$B$5,INDEX(入力!$D$9:$D$58,$AA8)-入力!$C$5))) -> 0.3 | N8: =IF($AA8="","",INDEX(入力!$J$9:$J$58,$AA8)) -> 要改善（両方遅い） | O8: =IF($AA8="","",IF(INDEX(入力!$K$9:$K$58,$AA8)<>"",INDEX(入力!$K$9:$K$58,$AA8),IF(ISNUMBER(INDEX(入力!$C$9:$C$58,$AA8)),IF(INDEX(入力!$C$9:$C$58,$AA8)-入力!$B$5>0,"ピッキング改善（梱包未入力）","良好（梱包未入力）"),IF(INDEX(入力!$D$9:$D$58,$AA8)-入力!$C$5>0,"梱包改善（ピッキング未入力）","良好（ピッキング未入力）")))) -> 両工程を見直し | Q8: =IF($AB8="","",INDEX(入力!$B$9:$B$58,$AB8)) -> 北田 倫子 | R8: =IF($AB8="","",INDEX(入力!$F$9:$F$58,$AB8)) -> 1.1428571 | S8: =IF($AB8="","",INDEX(入力!$C$9:$C$58,$AB8)) -> 1.6 | T8: =IF($AB8="","",INDEX(入力!$D$9:$D$58,$AB8)) -> 1.2 | U8: =IF($AB8="","",INDEX(入力!$E$9:$E$58,$AB8)) -> 2.8 | V8: =IF($Z8="","",IF($B8<>"",$B8,IF($C8<>"",入力!$B$5,""))) -> 1.5 | W8: =IF($Z8="","",IF($C8<>"",$C8,IF($B8<>"",入力!$C$5,""))) -> 1.9 | Z8: =IFERROR(MATCH(ROW()-1,入力!$N$9:$N$58,0),"") -> 7 | AA8: =IF(ROW()-1>COUNTIF(入力!$L$9:$L$58,">-9.9E+98"),"",IFERROR(MATCH(LARGE(入力!$L$9:$L$58,ROW()-1),入力!$L$9:$L$58,0),"")) -> 17 | AB8: =IF(ROW()-1>COUNTIF(入力!$M$9:$M$58,">-9.9E+98"),"",IFERROR(MATCH(LARGE(入力!$M$9:$M$58,ROW()-1),入力!$M$9:$M$58,0),"")) -> 18 | AC8: =入力!$B$5 -> 1.6 | AD8: =入力!$C$5 -> 1.6
A9: =IF($Z9="","",INDEX(入力!$B$9:$B$58,$Z9)) -> 山本 祥吉 | B9: =IF($Z9="","",IF(INDEX(入力!$C$9:$C$58,$Z9)="","",INDEX(入力!$C$9:$C$58,$Z9))) -> 1.4 | C9: =IF($Z9="","",IF(INDEX(入力!$D$9:$D$58,$Z9)="","",INDEX(入力!$D$9:$D$58,$Z9))) -> 1.8 | D9: =IF($Z9="","",INDEX(入力!$E$9:$E$58,$Z9)) -> 3.2 | E9: =IF($Z9="","",INDEX(入力!$F$9:$F$58,$Z9)) -> 1 | F9: =IF($Z9="","",INDEX(入力!$J$9:$J$58,$Z9)) -> 梱包改善 | G9: =IF($Z9="","",INDEX(入力!$K$9:$K$58,$Z9)) -> 目標達成 | I9: =IF($AA9="","",INDEX(入力!$B$9:$B$58,$AA9)) -> 秋草 文恵 | J9: =IF($AA9="","",INDEX(入力!$C$9:$C$58,$AA9)) -> 1.8 | K9: =IF($AA9="","",INDEX(入力!$D$9:$D$58,$AA9)) -> 0 | L9: =IF($AA9="","",IF(INDEX(入力!$E$9:$E$58,$AA9)<>"",INDEX(入力!$E$9:$E$58,$AA9),IF(ISNUMBER(INDEX(入力!$C$9:$C$58,$AA9)),INDEX(入力!$C$9:$C$58,$AA9),INDEX(入力!$D$9:$D$58,$AA9)))) -> 1.8 | M9: =IF($AA9="","",IF(INDEX(入力!$I$9:$I$58,$AA9)<>"",INDEX(入力!$I$9:$I$58,$AA9),IF(ISNUMBER(INDEX(入力!$C$9:$C$58,$AA9)),INDEX(入力!$C$9:$C$58,$AA9)-入力!$B$5,INDEX(入力!$D$9:$D$58,$AA9)-入力!$C$5))) -> 0.2 | N9: =IF($AA9="","",INDEX(入力!$J$9:$J$58,$AA9)) | O9: =IF($AA9="","",IF(INDEX(入力!$K$9:$K$58,$AA9)<>"",INDEX(入力!$K$9:$K$58,$AA9),IF(ISNUMBER(INDEX(入力!$C$9:$C$58,$AA9)),IF(INDEX(入力!$C$9:$C$58,$AA9)-入力!$B$5>0,"ピッキング改善（梱包未入力）","良好（梱包未入力）"),IF(INDEX(入力!$D$9:$D$58,$AA9)-入力!$C$5>0,"梱包改善（ピッキング未入力）","良好（ピッキング未入力）")))) -> ピッキング改善（梱包未入力） | Q9: =IF($AB9="","",INDEX(入力!$B$9:$B$58,$AB9)) -> 森本 久美 | R9: =IF($AB9="","",INDEX(入力!$F$9:$F$58,$AB9)) -> 1.0666667 | S9: =IF($AB9="","",INDEX(入力!$C$9:$C$58,$AB9)) -> 1.4 | T9: =IF($AB9="","",INDEX(入力!$D$9:$D$58,$AB9)) -> 1.6 | U9: =IF($AB9="","",INDEX(入力!$E$9:$E$58,$AB9)) -> 3 | V9: =IF($Z9="","",IF($B9<>"",$B9,IF($C9<>"",入力!$B$5,""))) -> 1.4 | W9: =IF($Z9="","",IF($C9<>"",$C9,IF($B9<>"",入力!$C$5,""))) -> 1.8 | Z9: =IFERROR(MATCH(ROW()-1,入力!$N$9:$N$58,0),"") -> 8 | AA9: =IF(ROW()-1>COUNTIF(入力!$L$9:$L$58,">-9.9E+98"),"",IFERROR(MATCH(LARGE(入力!$L$9:$L$58,ROW()-1),入力!$L$9:$L$58,0),"")) -> 22 | AB9: =IF(ROW()-1>COUNTIF(入力!$M$9:$M$58,">-9.9E+98"),"",IFERROR(MATCH(LARGE(入力!$M$9:$M$58,ROW()-1),入力!$M$9:$M$58,0),"")) -> 16 | AC9: =入力!$B$5 -> 1.6 | AD9: =入力!$C$5 -> 1.6
A10: =IF($Z10="","",INDEX(入力!$B$9:$B$58,$Z10)) -> 本吉 有美子 | B10: =IF($Z10="","",IF(INDEX(入力!$C$9:$C$58,$Z10)="","",INDEX(入力!$C$9:$C$58,$Z10))) -> 1.1 | C10: =IF($Z10="","",IF(INDEX(入力!$D$9:$D$58,$Z10)="","",INDEX(入力!$D$9:$D$58,$Z10))) -> 1 | D10: =IF($Z10="","",INDEX(入力!$E$9:$E$58,$Z10)) -> 2.1 | E10: =IF($Z10="","",INDEX(入力!$F$9:$F$58,$Z10)) -> 1.5238095 | F10: =IF($Z10="","",INDEX(入力!$J$9:$J$58,$Z10)) -> 良好 | G10: =IF($Z10="","",INDEX(入力!$K$9:$K$58,$Z10)) -> 良好 | I10: =IF($AA10="","",INDEX(入力!$B$9:$B$58,$AA10)) -> 上村 和恵 | J10: =IF($AA10="","",INDEX(入力!$C$9:$C$58,$AA10)) -> 1.8 | K10: =IF($AA10="","",INDEX(入力!$D$9:$D$58,$AA10)) -> 0 | L10: =IF($AA10="","",IF(INDEX(入力!$E$9:$E$58,$AA10)<>"",INDEX(入力!$E$9:$E$58,$AA10),IF(ISNUMBER(INDEX(入力!$C$9:$C$58,$AA10)),INDEX(入力!$C$9:$C$58,$AA10),INDEX(入力!$D$9:$D$58,$AA10)))) -> 1.8 | M10: =IF($AA10="","",IF(INDEX(入力!$I$9:$I$58,$AA10)<>"",INDEX(入力!$I$9:$I$58,$AA10),IF(ISNUMBER(INDEX(入力!$C$9:$C$58,$AA10)),INDEX(入力!$C$9:$C$58,$AA10)-入力!$B$5,INDEX(入力!$D$9:$D$58,$AA10)-入力!$C$5))) -> 0.2 | N10: =IF($AA10="","",INDEX(入力!$J$9:$J$58,$AA10)) | O10: =IF($AA10="","",IF(INDEX(入力!$K$9:$K$58,$AA10)<>"",INDEX(入力!$K$9:$K$58,$AA10),IF(ISNUMBER(INDEX(入力!$C$9:$C$58,$AA10)),IF(INDEX(入力!$C$9:$C$58,$AA10)-入力!$B$5>0,"ピッキング改善（梱包未入力）","良好（梱包未入力）"),IF(INDEX(入力!$D$9:$D$58,$AA10)-入力!$C$5>0,"梱包改善（ピッキング未入力）","良好（ピッキング未入力）")))) -> ピッキング改善（梱包未入力） | Q10: =IF($AB10="","",INDEX(入力!$B$9:$B$58,$AB10)) -> 鈴木 香織 | R10: =IF($AB10="","",INDEX(入力!$F$9:$F$58,$AB10)) -> 1.0666667 | S10: =IF($AB10="","",INDEX(入力!$C$9:$C$58,$AB10)) -> 1.2 | T10: =IF($AB10="","",INDEX(入力!$D$9:$D$58,$AB10)) -> 1.8 | U10: =IF($AB10="","",INDEX(入力!$E$9:$E$58,$AB10)) -> 3 | V10: =IF($Z10="","",IF($B10<>"",$B10,IF($C10<>"",入力!$B$5,""))) -> 1.1 | W10: =IF($Z10="","",IF($C10<>"",$C10,IF($B10<>"",入力!$C$5,""))) -> 1 | Z10: =IFERROR(MATCH(ROW()-1,入力!$N$9:$N$58,0),"") -> 9 | AA10: =IF(ROW()-1>COUNTIF(入力!$L$9:$L$58,">-9.9E+98"),"",IFERROR(MATCH(LARGE(入力!$L$9:$L$58,ROW()-1),入力!$L$9:$L$58,0),"")) -> 21 | AB10: =IF(ROW()-1>COUNTIF(入力!$M$9:$M$58,">-9.9E+98"),"",IFERROR(MATCH(LARGE(入力!$M$9:$M$58,ROW()-1),入力!$M$9:$M$58,0),"")) -> 19 | AC10: =入力!$B$5 -> 1.6 | AD10: =入力!$C$5 -> 1.6
A11: =IF($Z11="","",INDEX(入力!$B$9:$B$58,$Z11)) -> 屋宮 敬子 | B11: =IF($Z11="","",IF(INDEX(入力!$C$9:$C$58,$Z11)="","",INDEX(入力!$C$9:$C$58,$Z11))) | C11: =IF($Z11="","",IF(INDEX(入力!$D$9:$D$58,$Z11)="","",INDEX(入力!$D$9:$D$58,$Z11))) | D11: =IF($Z11="","",INDEX(入力!$E$9:$E$58,$Z11)) | E11: =IF($Z11="","",INDEX(入力!$F$9:$F$58,$Z11)) | F11: =IF($Z11="","",INDEX(入力!$J$9:$J$58,$Z11)) | G11: =IF($Z11="","",INDEX(入力!$K$9:$K$58,$Z11)) | I11: =IF($AA11="","",INDEX(入力!$B$9:$B$58,$AA11)) -> 後藤 克行 | J11: =IF($AA11="","",INDEX(入力!$C$9:$C$58,$AA11)) -> 1.5 | K11: =IF($AA11="","",INDEX(入力!$D$9:$D$58,$AA11)) -> 1.9 | L11: =IF($AA11="","",IF(INDEX(入力!$E$9:$E$58,$AA11)<>"",INDEX(入力!$E$9:$E$58,$AA11),IF(ISNUMBER(INDEX(入力!$C$9:$C$58,$AA11)),INDEX(入力!$C$9:$C$58,$AA11),INDEX(入力!$D$9:$D$58,$AA11)))) -> 3.4 | M11: =IF($AA11="","",IF(INDEX(入力!$I$9:$I$58,$AA11)<>"",INDEX(入力!$I$9:$I$58,$AA11),IF(ISNUMBER(INDEX(入力!$C$9:$C$58,$AA11)),INDEX(入力!$C$9:$C$58,$AA11)-入力!$B$5,INDEX(入力!$D$9:$D$58,$AA11)-入力!$C$5))) -> 0.2 | N11: =IF($AA11="","",INDEX(入力!$J$9:$J$58,$AA11)) -> 梱包改善 | O11: =IF($AA11="","",IF(INDEX(入力!$K$9:$K$58,$AA11)<>"",INDEX(入力!$K$9:$K$58,$AA11),IF(ISNUMBER(INDEX(入力!$C$9:$C$58,$AA11)),IF(INDEX(入力!$C$9:$C$58,$AA11)-入力!$B$5>0,"ピッキング改善（梱包未入力）","良好（梱包未入力）"),IF(INDEX(入力!$D$9:$D$58,$AA11)-入力!$C$5>0,"梱包改善（ピッキング未入力）","良好（ピッキング未入力）")))) -> 梱包手順を改善 | Q11: =IF($AB11="","",INDEX(入力!$B$9:$B$58,$AB11)) -> 澤田 凌 | R11: =IF($AB11="","",INDEX(入力!$F$9:$F$58,$AB11)) -> 1 | S11: =IF($AB11="","",INDEX(入力!$C$9:$C$58,$AB11)) -> 1.6 | T11: =IF($AB11="","",INDEX(入力!$D$9:$D$58,$AB11)) -> 1.6 | U11: =IF($AB11="","",INDEX(入力!$E$9:$E$58,$AB11)) -> 3.2 | V11: =IF($Z11="","",IF($B11<>"",$B11,IF($C11<>"",入力!$B$5,""))) | W11: =IF($Z11="","",IF($C11<>"",$C11,IF($B11<>"",入力!$C$5,""))) | Z11: =IFERROR(MATCH(ROW()-1,入力!$N$9:$N$58,0),"") -> 10 | AA11: =IF(ROW()-1>COUNTIF(入力!$L$9:$L$58,">-9.9E+98"),"",IFERROR(MATCH(LARGE(入力!$L$9:$L$58,ROW()-1),入力!$L$9:$L$58,0),"")) -> 7 | AB11: =IF(ROW()-1>COUNTIF(入力!$M$9:$M$58,">-9.9E+98"),"",IFERROR(MATCH(LARGE(入力!$M$9:$M$58,ROW()-1),入力!$M$9:$M$58,0),"")) -> 4 | AC11: =入力!$B$5 -> 1.6 | AD11: =入力!$C$5 -> 1.6
A12: =IF($Z12="","",INDEX(入力!$B$9:$B$58,$Z12)) -> 大江 美記子 | B12: =IF($Z12="","",IF(INDEX(入力!$C$9:$C$58,$Z12)="","",INDEX(入力!$C$9:$C$58,$Z12))) -> 1.2 | C12: =IF($Z12="","",IF(INDEX(入力!$D$9:$D$58,$Z12)="","",INDEX(入力!$D$9:$D$58,$Z12))) -> 1.2 | D12: =IF($Z12="","",INDEX(入力!$E$9:$E$58,$Z12)) -> 2.4 | E12: =IF($Z12="","",INDEX(入力!$F$9:$F$58,$Z12)) -> 1.3333333 | F12: =IF($Z12="","",INDEX(入力!$J$9:$J$58,$Z12)) -> 良好 | G12: =IF($Z12="","",INDEX(入力!$K$9:$K$58,$Z12)) -> 良好 | I12: =IF($AA12="","",INDEX(入力!$B$9:$B$58,$AA12)) -> 中納 沙織 | J12: =IF($AA12="","",INDEX(入力!$C$9:$C$58,$AA12)) -> 1.3 | K12: =IF($AA12="","",INDEX(入力!$D$9:$D$58,$AA12)) -> 2.1 | L12: =IF($AA12="","",IF(INDEX(入力!$E$9:$E$58,$AA12)<>"",INDEX(入力!$E$9:$E$58,$AA12),IF(ISNUMBER(INDEX(入力!$C$9:$C$58,$AA12)),INDEX(入力!$C$9:$C$58,$AA12),INDEX(入力!$D$9:$D$58,$AA12)))) -> 3.4 | M12: =IF($AA12="","",IF(INDEX(入力!$I$9:$I$58,$AA12)<>"",INDEX(入力!$I$9:$I$58,$AA12),IF(ISNUMBER(INDEX(入力!$C$9:$C$58,$AA12)),INDEX(入力!$C$9:$C$58,$AA12)-入力!$B$5,INDEX(入力!$D$9:$D$58,$AA12)-入力!$C$5))) -> 0.2 | N12: =IF($AA12="","",INDEX(入力!$J$9:$J$58,$AA12)) -> 梱包改善 | O12: =IF($AA12="","",IF(INDEX(入力!$K$9:$K$58,$AA12)<>"",INDEX(入力!$K$9:$K$58,$AA12),IF(ISNUMBER(INDEX(入力!$C$9:$C$58,$AA12)),IF(INDEX(入力!$C$9:$C$58,$AA12)-入力!$B$5>0,"ピッキング改善（梱包未入力）","良好（梱包未入力）"),IF(INDEX(入力!$D$9:$D$58,$AA12)-入力!$C$5>0,"梱包改善（ピッキング未入力）","良好（ピッキング未入力）")))) -> 梱包手順を改善 | Q12: =IF($AB12="","",INDEX(入力!$B$9:$B$58,$AB12)) -> 山本 祥吉 | R12: =IF($AB12="","",INDEX(入力!$F$9:$F$58,$AB12)) -> 1 | S12: =IF($AB12="","",INDEX(入力!$C$9:$C$58,$AB12)) -> 1.4 | T12: =IF($AB12="","",INDEX(入力!$D$9:$D$58,$AB12)) -> 1.8 | U12: =IF($AB12="","",INDEX(入力!$E$9:$E$58,$AB12)) -> 3.2 | V12: =IF($Z12="","",IF($B12<>"",$B12,IF($C12<>"",入力!$B$5,""))) -> 1.2 | W12: =IF($Z12="","",IF($C12<>"",$C12,IF($B12<>"",入力!$C$5,""))) -> 1.2 | Z12: =IFERROR(MATCH(ROW()-1,入力!$N$9:$N$58,0),"") -> 11 | AA12: =IF(ROW()-1>COUNTIF(入力!$L$9:$L$58,">-9.9E+98"),"",IFERROR(MATCH(LARGE(入力!$L$9:$L$58,ROW()-1),入力!$L$9:$L$58,0),"")) -> 3 | AB12: =IF(ROW()-1>COUNTIF(入力!$M$9:$M$58,">-9.9E+98"),"",IFERROR(MATCH(LARGE(入力!$M$9:$M$58,ROW()-1),入力!$M$9:$M$58,0),"")) -> 8 | AC12: =入力!$B$5 -> 1.6 | AD12: =入力!$C$5 -> 1.6
