Workbook

Sheet 集計表
A1: 作業者名 | B1: バラ検品 | C1: バラ検品即 | D1: 梱包 | E1: 合計
A2: 佐藤 辰成 | B2: =COUNTIFS('20260401'!$C$2:$C$1000,B$1,'20260401'!$E$2:$E$1000,$A2)+COUNTIFS('20260401'!$C$2:$C$1000,B$1,'20260401'!$E$2:$E$1000,SUBSTITUTE($A2," "," "))+COUNTIFS('20260402'!$C$2:$C$1000,B$1,'20260402'!$E$2:$E$1000,$A2)+COUNTIFS('20260402'!$C$2:$C$1000,B$1,'20260402'!$E$2:$E$1000,SUBSTITUTE($A2," "," "))+COUNTIFS('20260403'!$C$2:$C$1000,B$1,'20260403'!$E$2:$E$1000,$A2)+COUNTIFS('20260403'!$C$2:$C$1000,B$1,'20260403'!$E$2:$E$1000,SUBSTITUTE($A2," "," "))+COUNTIFS('20260406'!$C$2:$C$1000,B$1,'20260406'!$E$2:$E$1000,$A2)+COUNTIFS('20260406'!$C$2:$C$1000,B$1,'20260406'!$E$2:$E$1000,SUBSTITUTE($A2," "," "))+COUNTIFS('20260407'!$C$2:$C$1000,B$1,'20260407'!$E$2:$E$1000,$A2)+COUNTIFS('20260407'!$C$2:$C$1000,B$1,'20260407'!$E$2:$E$1000,SUBSTITUTE($A2," "," "))+COUNTIFS('20260408'!$C$2:$C$1000,B$1,'20260408'!$E$2:$E$1000,$A2)+COUNTIFS('20260408'!$C$2:$C$1000,B$1,'20260408'!$E$2:$E$1000,SUBSTITUTE($A2," "," "))+COUNTIFS('20260409'!$C$2:$C$1000,B$1,'20260409'!$E$2:$E$1000,$A2)+COUNTIFS('20260409'!$C$2:$C$1000,B$1,'20260409'!$E$2:$E$1000,SUBSTITUTE($A2," "," "))+COUNTIFS('20260410'!$C$2:$C$1000,B$1,'20260410'!$E$2:$E$1000,$A2)+COUNTIFS('20260410'!$C$2:$C$1000,B$1,'20260410'!$E$2:$E$1000,SUBSTITUTE($A2," "," "))+COUNTIFS('20260413'!$C$2:$C$1000,B$1,'20260413'!$E$2:$E$1000,$A2)+COUNTIFS('20260413'!$C$2:$C$1000,B$1,'20260413'!$E$2:$E$1000,SUBSTITUTE($A2," "," "))+COUNTIFS('20260414'!$C$2:$C$1000,B$1,'20260414'!$E$2:$E$1000,$A2)+COUNTIFS('20260414'!$C$2:$C$1000,B$1,'20260414'!$E$2:$E$1000,SUBSTITUTE($A2," "," "))+COUNTIFS('20260415'!$C$2:$C$1000,B$1,'20260415'!$E$2:$E$1000,$A2)+COUNTIFS('20260415'!$C$2:$C$1000,B$1,'20260415'!$E$2:$E$1000,SUBSTITUTE($A2," "," "))+COUNTIFS('20260416'!$C$2:$C$1000,B$1,'20260416'!$E$2:$E$1000,$A2)+COUNTIFS('20260416'!$C$2:$C$1000,B$1,'20260416'!$E$2:$E$1000,SUBSTITUTE($A2," "," "))+COUNTIFS('20260417'!$C$2:$C$1000,B$1,'20260417'!$E$2:$E$1000,$A2)+COUNTIFS('20260417'!$C$2:$C$1000,B$1,'20260417'!$E$2:$E$1000,SUBSTITUTE($A2," "," "))+COUNTIFS('20260420'!$C$2:$C$1000,B$1,'20260420'!$E$2:$E$1000,$A2)+COUNTIFS('20260420'!$C$2:$C$1000,B$1,'20260420'!$E$2:$E$1000,SUBSTITUTE($A2," "," "))+COUNTIFS('20260421'!$C$2:$C$1000,B$1,'20260421'!$E$2:$E$1000,$A2)+COUNTIFS('20260421'!$C$2:$C$1000,B$1,'20260421'!$E$2:$E$1000,SUBSTITUTE($A2," "," "))+COUNTIFS('20260422'!$C$2:$C$1000,B$1,'20260422'!$E$2:$E$1000,$A2)+COUNTIFS('20260422'!$C$2:$C$1000,B$1,'20260422'!$E$2:$E$1000,SUBSTITUTE($A2," "," "))+COUNTIFS('20260423'!$C$2:$C$1000,B$1,'20260423'!$E$2:$E$1000,$A2)+COUNTIFS('20260423'!$C$2:$C$1000,B$1,'20260423'!$E$2:$E$1000,SUBSTITUTE($A2," "," "))+COUNTIFS('20260424'!$C$2:$C$1000,B$1,'20260424'!$E$2:$E$1000,$A2)+COUNTIFS('20260424'!$C$2:$C$1000,B$1,'20260424'!$E$2:$E$1000,SUBSTITUTE($A2," "," "))+COUNTIFS('20260427'!$C$2:$C$1000,B$1,'20260427'!$E$2:$E$1000,$A2)+COUNTIFS('20260427'!$C$2:$C$1000,B$1,'20260427'!$E$2:$E$1000,SUBSTITUTE($A2," "," "))+COUNTIFS('20260428'!$C$2:$C$1000,B$1,'20260428'!$E$2:$E$1000,$A2)+COUNTIFS('20260428'!$C$2:$C$1000,B$1,'20260428'!$E$2:$E$1000,SUBSTITUTE($A2," "," "))+COUNTIFS('20260430'!$C$2:$C$1000,B$1,'20260430'!$E$2:$E$1000,$A2)+COUNTIFS('20260430'!$C$2:$C$1000,B$1,'20260430'!$E$2:$E$1000,SUBSTITUTE($A2," "," ")) | C2: =COUNTIFS('20260401'!$C$2:$C$1000,C$1,'20260401'!$E$2:$E$1000,$A2)+COUNTIFS('20260401'!$C$2:$C$1000,C$1,'20260401'!$E$2:$E$1000,SUBSTITUTE($A2," "," "))+COUNTIFS('20260402'!$C$2:$C$1000,C$1,'20260402'!$E$2:$E$1000,$A2)+COUNTIFS('20260402'!$C$2:$C$1000,C$1,'20260402'!$E$2:$E$1000,SUBSTITUTE($A2," "," "))+COUNTIFS('20260403'!$C$2:$C$1000,C$1,'20260403'!$E$2:$E$1000,$A2)+COUNTIFS('20260403'!$C$2:$C$1000,C$1,'20260403'!$E$2:$E$1000,SUBSTITUTE($A2," "," "))+COUNTIFS('20260406'!$C$2:$C$1000,C$1,'20260406'!$E$2:$E$1000,$A2)+COUNTIFS('20260406'!$C$2:$C$1000,C$1,'20260406'!$E$2:$E$1000,SUBSTITUTE($A2," "," "))+COUNTIFS('20260407'!$C$2:$C$1000,C$1,'20260407'!$E$2:$E$1000,$A2)+COUNTIFS('20260407'!$C$2:$C$1000,C$1,'20260407'!$E$2:$E$1000,SUBSTITUTE($A2," "," "))+COUNTIFS('20260408'!$C$2:$C$1000,C$1,'20260408'!$E$2:$E$1000,$A2)+COUNTIFS('20260408'!$C$2:$C$1000,C$1,'20260408'!$E$2:$E$1000,SUBSTITUTE($A2," "," "))+COUNTIFS('20260409'!$C$2:$C$1000,C$1,'20260409'!$E$2:$E$1000,$A2)+COUNTIFS('20260409'!$C$2:$C$1000,C$1,'20260409'!$E$2:$E$1000,SUBSTITUTE($A2," "," "))+COUNTIFS('20260410'!$C$2:$C$1000,C$1,'20260410'!$E$2:$E$1000,$A2)+COUNTIFS('20260410'!$C$2:$C$1000,C$1,'20260410'!$E$2:$E$1000,SUBSTITUTE($A2," "," "))+COUNTIFS('20260413'!$C$2:$C$1000,C$1,'20260413'!$E$2:$E$1000,$A2)+COUNTIFS('20260413'!$C$2:$C$1000,C$1,'20260413'!$E$2:$E$1000,SUBSTITUTE($A2," "," "))+COUNTIFS('20260414'!$C$2:$C$1000,C$1,'20260414'!$E$2:$E$1000,$A2)+COUNTIFS('20260414'!$C$2:$C$1000,C$1,'20260414'!$E$2:$E$1000,SUBSTITUTE($A2," "," "))+COUNTIFS('20260415'!$C$2:$C$1000,C$1,'20260415'!$E$2:$E$1000,$A2)+COUNTIFS('20260415'!$C$2:$C$1000,C$1,'20260415'!$E$2:$E$1000,SUBSTITUTE($A2," "," "))+COUNTIFS('20260416'!$C$2:$C$1000,C$1,'20260416'!$E$2:$E$1000,$A2)+COUNTIFS('20260416'!$C$2:$C$1000,C$1,'20260416'!$E$2:$E$1000,SUBSTITUTE($A2," "," "))+COUNTIFS('20260417'!$C$2:$C$1000,C$1,'20260417'!$E$2:$E$1000,$A2)+COUNTIFS('20260417'!$C$2:$C$1000,C$1,'20260417'!$E$2:$E$1000,SUBSTITUTE($A2," "," "))+COUNTIFS('20260420'!$C$2:$C$1000,C$1,'20260420'!$E$2:$E$1000,$A2)+COUNTIFS('20260420'!$C$2:$C$1000,C$1,'20260420'!$E$2:$E$1000,SUBSTITUTE($A2," "," "))+COUNTIFS('20260421'!$C$2:$C$1000,C$1,'20260421'!$E$2:$E$1000,$A2)+COUNTIFS('20260421'!$C$2:$C$1000,C$1,'20260421'!$E$2:$E$1000,SUBSTITUTE($A2," "," "))+COUNTIFS('20260422'!$C$2:$C$1000,C$1,'20260422'!$E$2:$E$1000,$A2)+COUNTIFS('20260422'!$C$2:$C$1000,C$1,'20260422'!$E$2:$E$1000,SUBSTITUTE($A2," "," "))+COUNTIFS('20260423'!$C$2:$C$1000,C$1,'20260423'!$E$2:$E$1000,$A2)+COUNTIFS('20260423'!$C$2:$C$1000,C$1,'20260423'!$E$2:$E$1000,SUBSTITUTE($A2," "," "))+COUNTIFS('20260424'!$C$2:$C$1000,C$1,'20260424'!$E$2:$E$1000,$A2)+COUNTIFS('20260424'!$C$2:$C$1000,C$1,'20260424'!$E$2:$E$1000,SUBSTITUTE($A2," "," "))+COUNTIFS('20260427'!$C$2:$C$1000,C$1,'20260427'!$E$2:$E$1000,$A2)+COUNTIFS('20260427'!$C$2:$C$1000,C$1,'20260427'!$E$2:$E$1000,SUBSTITUTE($A2," "," "))+COUNTIFS('20260428'!$C$2:$C$1000,C$1,'20260428'!$E$2:$E$1000,$A2)+COUNTIFS('20260428'!$C$2:$C$1000,C$1,'20260428'!$E$2:$E$1000,SUBSTITUTE($A2," "," "))+COUNTIFS('20260430'!$C$2:$C$1000,C$1,'20260430'!$E$2:$E$1000,$A2)+COUNTIFS('20260430'!$C$2:$C$1000,C$1,'20260430'!$E$2:$E$1000,SUBSTITUTE($A2," "," ")) | D2: =COUNTIFS('20260401'!$C$2:$C$1000,D$1,'20260401'!$E$2:$E$1000,$A2)+COUNTIFS('20260401'!$C$2:$C$1000,D$1,'20260401'!$E$2:$E$1000,SUBSTITUTE($A2," "," "))+COUNTIFS('20260402'!$C$2:$C$1000,D$1,'20260402'!$E$2:$E$1000,$A2)+COUNTIFS('20260402'!$C$2:$C$1000,D$1,'20260402'!$E$2:$E$1000,SUBSTITUTE($A2," "," "))+COUNTIFS('20260403'!$C$2:$C$1000,D$1,'20260403'!$E$2:$E$1000,$A2)+COUNTIFS('20260403'!$C$2:$C$1000,D$1,'20260403'!$E$2:$E$1000,SUBSTITUTE($A2," "," "))+COUNTIFS('20260406'!$C$2:$C$1000,D$1,'20260406'!$E$2:$E$1000,$A2)+COUNTIFS('20260406'!$C$2:$C$1000,D$1,'20260406'!$E$2:$E$1000,SUBSTITUTE($A2," "," "))+COUNTIFS('20260407'!$C$2:$C$1000,D$1,'20260407'!$E$2:$E$1000,$A2)+COUNTIFS('20260407'!$C$2:$C$1000,D$1,'20260407'!$E$2:$E$1000,SUBSTITUTE($A2," "," "))+COUNTIFS('20260408'!$C$2:$C$1000,D$1,'20260408'!$E$2:$E$1000,$A2)+COUNTIFS('20260408'!$C$2:$C$1000,D$1,'20260408'!$E$2:$E$1000,SUBSTITUTE($A2," "," "))+COUNTIFS('20260409'!$C$2:$C$1000,D$1,'20260409'!$E$2:$E$1000,$A2)+COUNTIFS('20260409'!$C$2:$C$1000,D$1,'20260409'!$E$2:$E$1000,SUBSTITUTE($A2," "," "))+COUNTIFS('20260410'!$C$2:$C$1000,D$1,'20260410'!$E$2:$E$1000,$A2)+COUNTIFS('20260410'!$C$2:$C$1000,D$1,'20260410'!$E$2:$E$1000,SUBSTITUTE($A2," "," "))+COUNTIFS('20260413'!$C$2:$C$1000,D$1,'20260413'!$E$2:$E$1000,$A2)+COUNTIFS('20260413'!$C$2:$C$1000,D$1,'20260413'!$E$2:$E$1000,SUBSTITUTE($A2," "," "))+COUNTIFS('20260414'!$C$2:$C$1000,D$1,'20260414'!$E$2:$E$1000,$A2)+COUNTIFS('20260414'!$C$2:$C$1000,D$1,'20260414'!$E$2:$E$1000,SUBSTITUTE($A2," "," "))+COUNTIFS('20260415'!$C$2:$C$1000,D$1,'20260415'!$E$2:$E$1000,$A2)+COUNTIFS('20260415'!$C$2:$C$1000,D$1,'20260415'!$E$2:$E$1000,SUBSTITUTE($A2," "," "))+COUNTIFS('20260416'!$C$2:$C$1000,D$1,'20260416'!$E$2:$E$1000,$A2)+COUNTIFS('20260416'!$C$2:$C$1000,D$1,'20260416'!$E$2:$E$1000,SUBSTITUTE($A2," "," "))+COUNTIFS('20260417'!$C$2:$C$1000,D$1,'20260417'!$E$2:$E$1000,$A2)+COUNTIFS('20260417'!$C$2:$C$1000,D$1,'20260417'!$E$2:$E$1000,SUBSTITUTE($A2," "," "))+COUNTIFS('20260420'!$C$2:$C$1000,D$1,'20260420'!$E$2:$E$1000,$A2)+COUNTIFS('20260420'!$C$2:$C$1000,D$1,'20260420'!$E$2:$E$1000,SUBSTITUTE($A2," "," "))+COUNTIFS('20260421'!$C$2:$C$1000,D$1,'20260421'!$E$2:$E$1000,$A2)+COUNTIFS('20260421'!$C$2:$C$1000,D$1,'20260421'!$E$2:$E$1000,SUBSTITUTE($A2," "," "))+COUNTIFS('20260422'!$C$2:$C$1000,D$1,'20260422'!$E$2:$E$1000,$A2)+COUNTIFS('20260422'!$C$2:$C$1000,D$1,'20260422'!$E$2:$E$1000,SUBSTITUTE($A2," "," "))+COUNTIFS('20260423'!$C$2:$C$1000,D$1,'20260423'!$E$2:$E$1000,$A2)+COUNTIFS('20260423'!$C$2:$C$1000,D$1,'20260423'!$E$2:$E$1000,SUBSTITUTE($A2," "," "))+COUNTIFS('20260424'!$C$2:$C$1000,D$1,'20260424'!$E$2:$E$1000,$A2)+COUNTIFS('20260424'!$C$2:$C$1000,D$1,'20260424'!$E$2:$E$1000,SUBSTITUTE($A2," "," "))+COUNTIFS('20260427'!$C$2:$C$1000,D$1,'20260427'!$E$2:$E$1000,$A2)+COUNTIFS('20260427'!$C$2:$C$1000,D$1,'20260427'!$E$2:$E$1000,SUBSTITUTE($A2," "," "))+COUNTIFS('20260428'!$C$2:$C$1000,D$1,'20260428'!$E$2:$E$1000,$A2)+COUNTIFS('20260428'!$C$2:$C$1000,D$1,'20260428'!$E$2:$E$1000,SUBSTITUTE($A2," "," "))+COUNTIFS('20260430'!$C$2:$C$1000,D$1,'20260430'!$E$2:$E$1000,$A2)+COUNTIFS('20260430'!$C$2:$C$1000,D$1,'20260430'!$E$2:$E$1000,SUBSTITUTE($A2," "," ")) | E2: =SUM(B2:D2)
A3: 河野 忠 | B3: =COUNTIFS('20260401'!$C$2:$C$1000,B$1,'20260401'!$E$2:$E$1000,$A3)+COUNTIFS('20260401'!$C$2:$C$1000,B$1,'20260401'!$E$2:$E$1000,SUBSTITUTE($A3," "," "))+COUNTIFS('20260402'!$C$2:$C$1000,B$1,'20260402'!$E$2:$E$1000,$A3)+COUNTIFS('20260402'!$C$2:$C$1000,B$1,'20260402'!$E$2:$E$1000,SUBSTITUTE($A3," "," "))+COUNTIFS('20260403'!$C$2:$C$1000,B$1,'20260403'!$E$2:$E$1000,$A3)+COUNTIFS('20260403'!$C$2:$C$1000,B$1,'20260403'!$E$2:$E$1000,SUBSTITUTE($A3," "," "))+COUNTIFS('20260406'!$C$2:$C$1000,B$1,'20260406'!$E$2:$E$1000,$A3)+COUNTIFS('20260406'!$C$2:$C$1000,B$1,'20260406'!$E$2:$E$1000,SUBSTITUTE($A3," "," "))+COUNTIFS('20260407'!$C$2:$C$1000,B$1,'20260407'!$E$2:$E$1000,$A3)+COUNTIFS('20260407'!$C$2:$C$1000,B$1,'20260407'!$E$2:$E$1000,SUBSTITUTE($A3," "," "))+COUNTIFS('20260408'!$C$2:$C$1000,B$1,'20260408'!$E$2:$E$1000,$A3)+COUNTIFS('20260408'!$C$2:$C$1000,B$1,'20260408'!$E$2:$E$1000,SUBSTITUTE($A3," "," "))+COUNTIFS('20260409'!$C$2:$C$1000,B$1,'20260409'!$E$2:$E$1000,$A3)+COUNTIFS('20260409'!$C$2:$C$1000,B$1,'20260409'!$E$2:$E$1000,SUBSTITUTE($A3," "," "))+COUNTIFS('20260410'!$C$2:$C$1000,B$1,'20260410'!$E$2:$E$1000,$A3)+COUNTIFS('20260410'!$C$2:$C$1000,B$1,'20260410'!$E$2:$E$1000,SUBSTITUTE($A3," "," "))+COUNTIFS('20260413'!$C$2:$C$1000,B$1,'20260413'!$E$2:$E$1000,$A3)+COUNTIFS('20260413'!$C$2:$C$1000,B$1,'20260413'!$E$2:$E$1000,SUBSTITUTE($A3," "," "))+COUNTIFS('20260414'!$C$2:$C$1000,B$1,'20260414'!$E$2:$E$1000,$A3)+COUNTIFS('20260414'!$C$2:$C$1000,B$1,'20260414'!$E$2:$E$1000,SUBSTITUTE($A3," "," "))+COUNTIFS('20260415'!$C$2:$C$1000,B$1,'20260415'!$E$2:$E$1000,$A3)+COUNTIFS('20260415'!$C$2:$C$1000,B$1,'20260415'!$E$2:$E$1000,SUBSTITUTE($A3," "," "))+COUNTIFS('20260416'!$C$2:$C$1000,B$1,'20260416'!$E$2:$E$1000,$A3)+COUNTIFS('20260416'!$C$2:$C$1000,B$1,'20260416'!$E$2:$E$1000,SUBSTITUTE($A3," "," "))+COUNTIFS('20260417'!$C$2:$C$1000,B$1,'20260417'!$E$2:$E$1000,$A3)+COUNTIFS('20260417'!$C$2:$C$1000,B$1,'20260417'!$E$2:$E$1000,SUBSTITUTE($A3," "," "))+COUNTIFS('20260420'!$C$2:$C$1000,B$1,'20260420'!$E$2:$E$1000,$A3)+COUNTIFS('20260420'!$C$2:$C$1000,B$1,'20260420'!$E$2:$E$1000,SUBSTITUTE($A3," "," "))+COUNTIFS('20260421'!$C$2:$C$1000,B$1,'20260421'!$E$2:$E$1000,$A3)+COUNTIFS('20260421'!$C$2:$C$1000,B$1,'20260421'!$E$2:$E$1000,SUBSTITUTE($A3," "," "))+COUNTIFS('20260422'!$C$2:$C$1000,B$1,'20260422'!$E$2:$E$1000,$A3)+COUNTIFS('20260422'!$C$2:$C$1000,B$1,'20260422'!$E$2:$E$1000,SUBSTITUTE($A3," "," "))+COUNTIFS('20260423'!$C$2:$C$1000,B$1,'20260423'!$E$2:$E$1000,$A3)+COUNTIFS('20260423'!$C$2:$C$1000,B$1,'20260423'!$E$2:$E$1000,SUBSTITUTE($A3," "," "))+COUNTIFS('20260424'!$C$2:$C$1000,B$1,'20260424'!$E$2:$E$1000,$A3)+COUNTIFS('20260424'!$C$2:$C$1000,B$1,'20260424'!$E$2:$E$1000,SUBSTITUTE($A3," "," "))+COUNTIFS('20260427'!$C$2:$C$1000,B$1,'20260427'!$E$2:$E$1000,$A3)+COUNTIFS('20260427'!$C$2:$C$1000,B$1,'20260427'!$E$2:$E$1000,SUBSTITUTE($A3," "," "))+COUNTIFS('20260428'!$C$2:$C$1000,B$1,'20260428'!$E$2:$E$1000,$A3)+COUNTIFS('20260428'!$C$2:$C$1000,B$1,'20260428'!$E$2:$E$1000,SUBSTITUTE($A3," "," "))+COUNTIFS('20260430'!$C$2:$C$1000,B$1,'20260430'!$E$2:$E$1000,$A3)+COUNTIFS('20260430'!$C$2:$C$1000,B$1,'20260430'!$E$2:$E$1000,SUBSTITUTE($A3," "," ")) | C3: =COUNTIFS('20260401'!$C$2:$C$1000,C$1,'20260401'!$E$2:$E$1000,$A3)+COUNTIFS('20260401'!$C$2:$C$1000,C$1,'20260401'!$E$2:$E$1000,SUBSTITUTE($A3," "," "))+COUNTIFS('20260402'!$C$2:$C$1000,C$1,'20260402'!$E$2:$E$1000,$A3)+COUNTIFS('20260402'!$C$2:$C$1000,C$1,'20260402'!$E$2:$E$1000,SUBSTITUTE($A3," "," "))+COUNTIFS('20260403'!$C$2:$C$1000,C$1,'20260403'!$E$2:$E$1000,$A3)+COUNTIFS('20260403'!$C$2:$C$1000,C$1,'20260403'!$E$2:$E$1000,SUBSTITUTE($A3," "," "))+COUNTIFS('20260406'!$C$2:$C$1000,C$1,'20260406'!$E$2:$E$1000,$A3)+COUNTIFS('20260406'!$C$2:$C$1000,C$1,'20260406'!$E$2:$E$1000,SUBSTITUTE($A3," "," "))+COUNTIFS('20260407'!$C$2:$C$1000,C$1,'20260407'!$E$2:$E$1000,$A3)+COUNTIFS('20260407'!$C$2:$C$1000,C$1,'20260407'!$E$2:$E$1000,SUBSTITUTE($A3," "," "))+COUNTIFS('20260408'!$C$2:$C$1000,C$1,'20260408'!$E$2:$E$1000,$A3)+COUNTIFS('20260408'!$C$2:$C$1000,C$1,'20260408'!$E$2:$E$1000,SUBSTITUTE($A3," "," "))+COUNTIFS('20260409'!$C$2:$C$1000,C$1,'20260409'!$E$2:$E$1000,$A3)+COUNTIFS('20260409'!$C$2:$C$1000,C$1,'20260409'!$E$2:$E$1000,SUBSTITUTE($A3," "," "))+COUNTIFS('20260410'!$C$2:$C$1000,C$1,'20260410'!$E$2:$E$1000,$A3)+COUNTIFS('20260410'!$C$2:$C$1000,C$1,'20260410'!$E$2:$E$1000,SUBSTITUTE($A3," "," "))+COUNTIFS('20260413'!$C$2:$C$1000,C$1,'20260413'!$E$2:$E$1000,$A3)+COUNTIFS('20260413'!$C$2:$C$1000,C$1,'20260413'!$E$2:$E$1000,SUBSTITUTE($A3," "," "))+COUNTIFS('20260414'!$C$2:$C$1000,C$1,'20260414'!$E$2:$E$1000,$A3)+COUNTIFS('20260414'!$C$2:$C$1000,C$1,'20260414'!$E$2:$E$1000,SUBSTITUTE($A3," "," "))+COUNTIFS('20260415'!$C$2:$C$1000,C$1,'20260415'!$E$2:$E$1000,$A3)+COUNTIFS('20260415'!$C$2:$C$1000,C$1,'20260415'!$E$2:$E$1000,SUBSTITUTE($A3," "," "))+COUNTIFS('20260416'!$C$2:$C$1000,C$1,'20260416'!$E$2:$E$1000,$A3)+COUNTIFS('20260416'!$C$2:$C$1000,C$1,'20260416'!$E$2:$E$1000,SUBSTITUTE($A3," "," "))+COUNTIFS('20260417'!$C$2:$C$1000,C$1,'20260417'!$E$2:$E$1000,$A3)+COUNTIFS('20260417'!$C$2:$C$1000,C$1,'20260417'!$E$2:$E$1000,SUBSTITUTE($A3," "," "))+COUNTIFS('20260420'!$C$2:$C$1000,C$1,'20260420'!$E$2:$E$1000,$A3)+COUNTIFS('20260420'!$C$2:$C$1000,C$1,'20260420'!$E$2:$E$1000,SUBSTITUTE($A3," "," "))+COUNTIFS('20260421'!$C$2:$C$1000,C$1,'20260421'!$E$2:$E$1000,$A3)+COUNTIFS('20260421'!$C$2:$C$1000,C$1,'20260421'!$E$2:$E$1000,SUBSTITUTE($A3," "," "))+COUNTIFS('20260422'!$C$2:$C$1000,C$1,'20260422'!$E$2:$E$1000,$A3)+COUNTIFS('20260422'!$C$2:$C$1000,C$1,'20260422'!$E$2:$E$1000,SUBSTITUTE($A3," "," "))+COUNTIFS('20260423'!$C$2:$C$1000,C$1,'20260423'!$E$2:$E$1000,$A3)+COUNTIFS('20260423'!$C$2:$C$1000,C$1,'20260423'!$E$2:$E$1000,SUBSTITUTE($A3," "," "))+COUNTIFS('20260424'!$C$2:$C$1000,C$1,'20260424'!$E$2:$E$1000,$A3)+COUNTIFS('20260424'!$C$2:$C$1000,C$1,'20260424'!$E$2:$E$1000,SUBSTITUTE($A3," "," "))+COUNTIFS('20260427'!$C$2:$C$1000,C$1,'20260427'!$E$2:$E$1000,$A3)+COUNTIFS('20260427'!$C$2:$C$1000,C$1,'20260427'!$E$2:$E$1000,SUBSTITUTE($A3," "," "))+COUNTIFS('20260428'!$C$2:$C$1000,C$1,'20260428'!$E$2:$E$1000,$A3)+COUNTIFS('20260428'!$C$2:$C$1000,C$1,'20260428'!$E$2:$E$1000,SUBSTITUTE($A3," "," "))+COUNTIFS('20260430'!$C$2:$C$1000,C$1,'20260430'!$E$2:$E$1000,$A3)+COUNTIFS('20260430'!$C$2:$C$1000,C$1,'20260430'!$E$2:$E$1000,SUBSTITUTE($A3," "," ")) | D3: =COUNTIFS('20260401'!$C$2:$C$1000,D$1,'20260401'!$E$2:$E$1000,$A3)+COUNTIFS('20260401'!$C$2:$C$1000,D$1,'20260401'!$E$2:$E$1000,SUBSTITUTE($A3," "," "))+COUNTIFS('20260402'!$C$2:$C$1000,D$1,'20260402'!$E$2:$E$1000,$A3)+COUNTIFS('20260402'!$C$2:$C$1000,D$1,'20260402'!$E$2:$E$1000,SUBSTITUTE($A3," "," "))+COUNTIFS('20260403'!$C$2:$C$1000,D$1,'20260403'!$E$2:$E$1000,$A3)+COUNTIFS('20260403'!$C$2:$C$1000,D$1,'20260403'!$E$2:$E$1000,SUBSTITUTE($A3," "," "))+COUNTIFS('20260406'!$C$2:$C$1000,D$1,'20260406'!$E$2:$E$1000,$A3)+COUNTIFS('20260406'!$C$2:$C$1000,D$1,'20260406'!$E$2:$E$1000,SUBSTITUTE($A3," "," "))+COUNTIFS('20260407'!$C$2:$C$1000,D$1,'20260407'!$E$2:$E$1000,$A3)+COUNTIFS('20260407'!$C$2:$C$1000,D$1,'20260407'!$E$2:$E$1000,SUBSTITUTE($A3," "," "))+COUNTIFS('20260408'!$C$2:$C$1000,D$1,'20260408'!$E$2:$E$1000,$A3)+COUNTIFS('20260408'!$C$2:$C$1000,D$1,'20260408'!$E$2:$E$1000,SUBSTITUTE($A3," "," "))+COUNTIFS('20260409'!$C$2:$C$1000,D$1,'20260409'!$E$2:$E$1000,$A3)+COUNTIFS('20260409'!$C$2:$C$1000,D$1,'20260409'!$E$2:$E$1000,SUBSTITUTE($A3," "," "))+COUNTIFS('20260410'!$C$2:$C$1000,D$1,'20260410'!$E$2:$E$1000,$A3)+COUNTIFS('20260410'!$C$2:$C$1000,D$1,'20260410'!$E$2:$E$1000,SUBSTITUTE($A3," "," "))+COUNTIFS('20260413'!$C$2:$C$1000,D$1,'20260413'!$E$2:$E$1000,$A3)+COUNTIFS('20260413'!$C$2:$C$1000,D$1,'20260413'!$E$2:$E$1000,SUBSTITUTE($A3," "," "))+COUNTIFS('20260414'!$C$2:$C$1000,D$1,'20260414'!$E$2:$E$1000,$A3)+COUNTIFS('20260414'!$C$2:$C$1000,D$1,'20260414'!$E$2:$E$1000,SUBSTITUTE($A3," "," "))+COUNTIFS('20260415'!$C$2:$C$1000,D$1,'20260415'!$E$2:$E$1000,$A3)+COUNTIFS('20260415'!$C$2:$C$1000,D$1,'20260415'!$E$2:$E$1000,SUBSTITUTE($A3," "," "))+COUNTIFS('20260416'!$C$2:$C$1000,D$1,'20260416'!$E$2:$E$1000,$A3)+COUNTIFS('20260416'!$C$2:$C$1000,D$1,'20260416'!$E$2:$E$1000,SUBSTITUTE($A3," "," "))+COUNTIFS('20260417'!$C$2:$C$1000,D$1,'20260417'!$E$2:$E$1000,$A3)+COUNTIFS('20260417'!$C$2:$C$1000,D$1,'20260417'!$E$2:$E$1000,SUBSTITUTE($A3," "," "))+COUNTIFS('20260420'!$C$2:$C$1000,D$1,'20260420'!$E$2:$E$1000,$A3)+COUNTIFS('20260420'!$C$2:$C$1000,D$1,'20260420'!$E$2:$E$1000,SUBSTITUTE($A3," "," "))+COUNTIFS('20260421'!$C$2:$C$1000,D$1,'20260421'!$E$2:$E$1000,$A3)+COUNTIFS('20260421'!$C$2:$C$1000,D$1,'20260421'!$E$2:$E$1000,SUBSTITUTE($A3," "," "))+COUNTIFS('20260422'!$C$2:$C$1000,D$1,'20260422'!$E$2:$E$1000,$A3)+COUNTIFS('20260422'!$C$2:$C$1000,D$1,'20260422'!$E$2:$E$1000,SUBSTITUTE($A3," "," "))+COUNTIFS('20260423'!$C$2:$C$1000,D$1,'20260423'!$E$2:$E$1000,$A3)+COUNTIFS('20260423'!$C$2:$C$1000,D$1,'20260423'!$E$2:$E$1000,SUBSTITUTE($A3," "," "))+COUNTIFS('20260424'!$C$2:$C$1000,D$1,'20260424'!$E$2:$E$1000,$A3)+COUNTIFS('20260424'!$C$2:$C$1000,D$1,'20260424'!$E$2:$E$1000,SUBSTITUTE($A3," "," "))+COUNTIFS('20260427'!$C$2:$C$1000,D$1,'20260427'!$E$2:$E$1000,$A3)+COUNTIFS('20260427'!$C$2:$C$1000,D$1,'20260427'!$E$2:$E$1000,SUBSTITUTE($A3," "," "))+COUNTIFS('20260428'!$C$2:$C$1000,D$1,'20260428'!$E$2:$E$1000,$A3)+COUNTIFS('20260428'!$C$2:$C$1000,D$1,'20260428'!$E$2:$E$1000,SUBSTITUTE($A3," "," "))+COUNTIFS('20260430'!$C$2:$C$1000,D$1,'20260430'!$E$2:$E$1000,$A3)+COUNTIFS('20260430'!$C$2:$C$1000,D$1,'20260430'!$E$2:$E$1000,SUBSTITUTE($A3," "," ")) | E3: =SUM(B3:D3)
A4: 中納 沙織 | B4: =COUNTIFS('20260401'!$C$2:$C$1000,B$1,'20260401'!$E$2:$E$1000,$A4)+COUNTIFS('20260401'!$C$2:$C$1000,B$1,'20260401'!$E$2:$E$1000,SUBSTITUTE($A4," "," "))+COUNTIFS('20260402'!$C$2:$C$1000,B$1,'20260402'!$E$2:$E$1000,$A4)+COUNTIFS('20260402'!$C$2:$C$1000,B$1,'20260402'!$E$2:$E$1000,SUBSTITUTE($A4," "," "))+COUNTIFS('20260403'!$C$2:$C$1000,B$1,'20260403'!$E$2:$E$1000,$A4)+COUNTIFS('20260403'!$C$2:$C$1000,B$1,'20260403'!$E$2:$E$1000,SUBSTITUTE($A4," "," "))+COUNTIFS('20260406'!$C$2:$C$1000,B$1,'20260406'!$E$2:$E$1000,$A4)+COUNTIFS('20260406'!$C$2:$C$1000,B$1,'20260406'!$E$2:$E$1000,SUBSTITUTE($A4," "," "))+COUNTIFS('20260407'!$C$2:$C$1000,B$1,'20260407'!$E$2:$E$1000,$A4)+COUNTIFS('20260407'!$C$2:$C$1000,B$1,'20260407'!$E$2:$E$1000,SUBSTITUTE($A4," "," "))+COUNTIFS('20260408'!$C$2:$C$1000,B$1,'20260408'!$E$2:$E$1000,$A4)+COUNTIFS('20260408'!$C$2:$C$1000,B$1,'20260408'!$E$2:$E$1000,SUBSTITUTE($A4," "," "))+COUNTIFS('20260409'!$C$2:$C$1000,B$1,'20260409'!$E$2:$E$1000,$A4)+COUNTIFS('20260409'!$C$2:$C$1000,B$1,'20260409'!$E$2:$E$1000,SUBSTITUTE($A4," "," "))+COUNTIFS('20260410'!$C$2:$C$1000,B$1,'20260410'!$E$2:$E$1000,$A4)+COUNTIFS('20260410'!$C$2:$C$1000,B$1,'20260410'!$E$2:$E$1000,SUBSTITUTE($A4," "," "))+COUNTIFS('20260413'!$C$2:$C$1000,B$1,'20260413'!$E$2:$E$1000,$A4)+COUNTIFS('20260413'!$C$2:$C$1000,B$1,'20260413'!$E$2:$E$1000,SUBSTITUTE($A4," "," "))+COUNTIFS('20260414'!$C$2:$C$1000,B$1,'20260414'!$E$2:$E$1000,$A4)+COUNTIFS('20260414'!$C$2:$C$1000,B$1,'20260414'!$E$2:$E$1000,SUBSTITUTE($A4," "," "))+COUNTIFS('20260415'!$C$2:$C$1000,B$1,'20260415'!$E$2:$E$1000,$A4)+COUNTIFS('20260415'!$C$2:$C$1000,B$1,'20260415'!$E$2:$E$1000,SUBSTITUTE($A4," "," "))+COUNTIFS('20260416'!$C$2:$C$1000,B$1,'20260416'!$E$2:$E$1000,$A4)+COUNTIFS('20260416'!$C$2:$C$1000,B$1,'20260416'!$E$2:$E$1000,SUBSTITUTE($A4," "," "))+COUNTIFS('20260417'!$C$2:$C$1000,B$1,'20260417'!$E$2:$E$1000,$A4)+COUNTIFS('20260417'!$C$2:$C$1000,B$1,'20260417'!$E$2:$E$1000,SUBSTITUTE($A4," "," "))+COUNTIFS('20260420'!$C$2:$C$1000,B$1,'20260420'!$E$2:$E$1000,$A4)+COUNTIFS('20260420'!$C$2:$C$1000,B$1,'20260420'!$E$2:$E$1000,SUBSTITUTE($A4," "," "))+COUNTIFS('20260421'!$C$2:$C$1000,B$1,'20260421'!$E$2:$E$1000,$A4)+COUNTIFS('20260421'!$C$2:$C$1000,B$1,'20260421'!$E$2:$E$1000,SUBSTITUTE($A4," "," "))+COUNTIFS('20260422'!$C$2:$C$1000,B$1,'20260422'!$E$2:$E$1000,$A4)+COUNTIFS('20260422'!$C$2:$C$1000,B$1,'20260422'!$E$2:$E$1000,SUBSTITUTE($A4," "," "))+COUNTIFS('20260423'!$C$2:$C$1000,B$1,'20260423'!$E$2:$E$1000,$A4)+COUNTIFS('20260423'!$C$2:$C$1000,B$1,'20260423'!$E$2:$E$1000,SUBSTITUTE($A4," "," "))+COUNTIFS('20260424'!$C$2:$C$1000,B$1,'20260424'!$E$2:$E$1000,$A4)+COUNTIFS('20260424'!$C$2:$C$1000,B$1,'20260424'!$E$2:$E$1000,SUBSTITUTE($A4," "," "))+COUNTIFS('20260427'!$C$2:$C$1000,B$1,'20260427'!$E$2:$E$1000,$A4)+COUNTIFS('20260427'!$C$2:$C$1000,B$1,'20260427'!$E$2:$E$1000,SUBSTITUTE($A4," "," "))+COUNTIFS('20260428'!$C$2:$C$1000,B$1,'20260428'!$E$2:$E$1000,$A4)+COUNTIFS('20260428'!$C$2:$C$1000,B$1,'20260428'!$E$2:$E$1000,SUBSTITUTE($A4," "," "))+COUNTIFS('20260430'!$C$2:$C$1000,B$1,'20260430'!$E$2:$E$1000,$A4)+COUNTIFS('20260430'!$C$2:$C$1000,B$1,'20260430'!$E$2:$E$1000,SUBSTITUTE($A4," "," ")) | C4: =COUNTIFS('20260401'!$C$2:$C$1000,C$1,'20260401'!$E$2:$E$1000,$A4)+COUNTIFS('20260401'!$C$2:$C$1000,C$1,'20260401'!$E$2:$E$1000,SUBSTITUTE($A4," "," "))+COUNTIFS('20260402'!$C$2:$C$1000,C$1,'20260402'!$E$2:$E$1000,$A4)+COUNTIFS('20260402'!$C$2:$C$1000,C$1,'20260402'!$E$2:$E$1000,SUBSTITUTE($A4," "," "))+COUNTIFS('20260403'!$C$2:$C$1000,C$1,'20260403'!$E$2:$E$1000,$A4)+COUNTIFS('20260403'!$C$2:$C$1000,C$1,'20260403'!$E$2:$E$1000,SUBSTITUTE($A4," "," "))+COUNTIFS('20260406'!$C$2:$C$1000,C$1,'20260406'!$E$2:$E$1000,$A4)+COUNTIFS('20260406'!$C$2:$C$1000,C$1,'20260406'!$E$2:$E$1000,SUBSTITUTE($A4," "," "))+COUNTIFS('20260407'!$C$2:$C$1000,C$1,'20260407'!$E$2:$E$1000,$A4)+COUNTIFS('20260407'!$C$2:$C$1000,C$1,'20260407'!$E$2:$E$1000,SUBSTITUTE($A4," "," "))+COUNTIFS('20260408'!$C$2:$C$1000,C$1,'20260408'!$E$2:$E$1000,$A4)+COUNTIFS('20260408'!$C$2:$C$1000,C$1,'20260408'!$E$2:$E$1000,SUBSTITUTE($A4," "," "))+COUNTIFS('20260409'!$C$2:$C$1000,C$1,'20260409'!$E$2:$E$1000,$A4)+COUNTIFS('20260409'!$C$2:$C$1000,C$1,'20260409'!$E$2:$E$1000,SUBSTITUTE($A4," "," "))+COUNTIFS('20260410'!$C$2:$C$1000,C$1,'20260410'!$E$2:$E$1000,$A4)+COUNTIFS('20260410'!$C$2:$C$1000,C$1,'20260410'!$E$2:$E$1000,SUBSTITUTE($A4," "," "))+COUNTIFS('20260413'!$C$2:$C$1000,C$1,'20260413'!$E$2:$E$1000,$A4)+COUNTIFS('20260413'!$C$2:$C$1000,C$1,'20260413'!$E$2:$E$1000,SUBSTITUTE($A4," "," "))+COUNTIFS('20260414'!$C$2:$C$1000,C$1,'20260414'!$E$2:$E$1000,$A4)+COUNTIFS('20260414'!$C$2:$C$1000,C$1,'20260414'!$E$2:$E$1000,SUBSTITUTE($A4," "," "))+COUNTIFS('20260415'!$C$2:$C$1000,C$1,'20260415'!$E$2:$E$1000,$A4)+COUNTIFS('20260415'!$C$2:$C$1000,C$1,'20260415'!$E$2:$E$1000,SUBSTITUTE($A4," "," "))+COUNTIFS('20260416'!$C$2:$C$1000,C$1,'20260416'!$E$2:$E$1000,$A4)+COUNTIFS('20260416'!$C$2:$C$1000,C$1,'20260416'!$E$2:$E$1000,SUBSTITUTE($A4," "," "))+COUNTIFS('20260417'!$C$2:$C$1000,C$1,'20260417'!$E$2:$E$1000,$A4)+COUNTIFS('20260417'!$C$2:$C$1000,C$1,'20260417'!$E$2:$E$1000,SUBSTITUTE($A4," "," "))+COUNTIFS('20260420'!$C$2:$C$1000,C$1,'20260420'!$E$2:$E$1000,$A4)+COUNTIFS('20260420'!$C$2:$C$1000,C$1,'20260420'!$E$2:$E$1000,SUBSTITUTE($A4," "," "))+COUNTIFS('20260421'!$C$2:$C$1000,C$1,'20260421'!$E$2:$E$1000,$A4)+COUNTIFS('20260421'!$C$2:$C$1000,C$1,'20260421'!$E$2:$E$1000,SUBSTITUTE($A4," "," "))+COUNTIFS('20260422'!$C$2:$C$1000,C$1,'20260422'!$E$2:$E$1000,$A4)+COUNTIFS('20260422'!$C$2:$C$1000,C$1,'20260422'!$E$2:$E$1000,SUBSTITUTE($A4," "," "))+COUNTIFS('20260423'!$C$2:$C$1000,C$1,'20260423'!$E$2:$E$1000,$A4)+COUNTIFS('20260423'!$C$2:$C$1000,C$1,'20260423'!$E$2:$E$1000,SUBSTITUTE($A4," "," "))+COUNTIFS('20260424'!$C$2:$C$1000,C$1,'20260424'!$E$2:$E$1000,$A4)+COUNTIFS('20260424'!$C$2:$C$1000,C$1,'20260424'!$E$2:$E$1000,SUBSTITUTE($A4," "," "))+COUNTIFS('20260427'!$C$2:$C$1000,C$1,'20260427'!$E$2:$E$1000,$A4)+COUNTIFS('20260427'!$C$2:$C$1000,C$1,'20260427'!$E$2:$E$1000,SUBSTITUTE($A4," "," "))+COUNTIFS('20260428'!$C$2:$C$1000,C$1,'20260428'!$E$2:$E$1000,$A4)+COUNTIFS('20260428'!$C$2:$C$1000,C$1,'20260428'!$E$2:$E$1000,SUBSTITUTE($A4," "," "))+COUNTIFS('20260430'!$C$2:$C$1000,C$1,'20260430'!$E$2:$E$1000,$A4)+COUNTIFS('20260430'!$C$2:$C$1000,C$1,'20260430'!$E$2:$E$1000,SUBSTITUTE($A4," "," ")) | D4: =COUNTIFS('20260401'!$C$2:$C$1000,D$1,'20260401'!$E$2:$E$1000,$A4)+COUNTIFS('20260401'!$C$2:$C$1000,D$1,'20260401'!$E$2:$E$1000,SUBSTITUTE($A4," "," "))+COUNTIFS('20260402'!$C$2:$C$1000,D$1,'20260402'!$E$2:$E$1000,$A4)+COUNTIFS('20260402'!$C$2:$C$1000,D$1,'20260402'!$E$2:$E$1000,SUBSTITUTE($A4," "," "))+COUNTIFS('20260403'!$C$2:$C$1000,D$1,'20260403'!$E$2:$E$1000,$A4)+COUNTIFS('20260403'!$C$2:$C$1000,D$1,'20260403'!$E$2:$E$1000,SUBSTITUTE($A4," "," "))+COUNTIFS('20260406'!$C$2:$C$1000,D$1,'20260406'!$E$2:$E$1000,$A4)+COUNTIFS('20260406'!$C$2:$C$1000,D$1,'20260406'!$E$2:$E$1000,SUBSTITUTE($A4," "," "))+COUNTIFS('20260407'!$C$2:$C$1000,D$1,'20260407'!$E$2:$E$1000,$A4)+COUNTIFS('20260407'!$C$2:$C$1000,D$1,'20260407'!$E$2:$E$1000,SUBSTITUTE($A4," "," "))+COUNTIFS('20260408'!$C$2:$C$1000,D$1,'20260408'!$E$2:$E$1000,$A4)+COUNTIFS('20260408'!$C$2:$C$1000,D$1,'20260408'!$E$2:$E$1000,SUBSTITUTE($A4," "," "))+COUNTIFS('20260409'!$C$2:$C$1000,D$1,'20260409'!$E$2:$E$1000,$A4)+COUNTIFS('20260409'!$C$2:$C$1000,D$1,'20260409'!$E$2:$E$1000,SUBSTITUTE($A4," "," "))+COUNTIFS('20260410'!$C$2:$C$1000,D$1,'20260410'!$E$2:$E$1000,$A4)+COUNTIFS('20260410'!$C$2:$C$1000,D$1,'20260410'!$E$2:$E$1000,SUBSTITUTE($A4," "," "))+COUNTIFS('20260413'!$C$2:$C$1000,D$1,'20260413'!$E$2:$E$1000,$A4)+COUNTIFS('20260413'!$C$2:$C$1000,D$1,'20260413'!$E$2:$E$1000,SUBSTITUTE($A4," "," "))+COUNTIFS('20260414'!$C$2:$C$1000,D$1,'20260414'!$E$2:$E$1000,$A4)+COUNTIFS('20260414'!$C$2:$C$1000,D$1,'20260414'!$E$2:$E$1000,SUBSTITUTE($A4," "," "))+COUNTIFS('20260415'!$C$2:$C$1000,D$1,'20260415'!$E$2:$E$1000,$A4)+COUNTIFS('20260415'!$C$2:$C$1000,D$1,'20260415'!$E$2:$E$1000,SUBSTITUTE($A4," "," "))+COUNTIFS('20260416'!$C$2:$C$1000,D$1,'20260416'!$E$2:$E$1000,$A4)+COUNTIFS('20260416'!$C$2:$C$1000,D$1,'20260416'!$E$2:$E$1000,SUBSTITUTE($A4," "," "))+COUNTIFS('20260417'!$C$2:$C$1000,D$1,'20260417'!$E$2:$E$1000,$A4)+COUNTIFS('20260417'!$C$2:$C$1000,D$1,'20260417'!$E$2:$E$1000,SUBSTITUTE($A4," "," "))+COUNTIFS('20260420'!$C$2:$C$1000,D$1,'20260420'!$E$2:$E$1000,$A4)+COUNTIFS('20260420'!$C$2:$C$1000,D$1,'20260420'!$E$2:$E$1000,SUBSTITUTE($A4," "," "))+COUNTIFS('20260421'!$C$2:$C$1000,D$1,'20260421'!$E$2:$E$1000,$A4)+COUNTIFS('20260421'!$C$2:$C$1000,D$1,'20260421'!$E$2:$E$1000,SUBSTITUTE($A4," "," "))+COUNTIFS('20260422'!$C$2:$C$1000,D$1,'20260422'!$E$2:$E$1000,$A4)+COUNTIFS('20260422'!$C$2:$C$1000,D$1,'20260422'!$E$2:$E$1000,SUBSTITUTE($A4," "," "))+COUNTIFS('20260423'!$C$2:$C$1000,D$1,'20260423'!$E$2:$E$1000,$A4)+COUNTIFS('20260423'!$C$2:$C$1000,D$1,'20260423'!$E$2:$E$1000,SUBSTITUTE($A4," "," "))+COUNTIFS('20260424'!$C$2:$C$1000,D$1,'20260424'!$E$2:$E$1000,$A4)+COUNTIFS('20260424'!$C$2:$C$1000,D$1,'20260424'!$E$2:$E$1000,SUBSTITUTE($A4," "," "))+COUNTIFS('20260427'!$C$2:$C$1000,D$1,'20260427'!$E$2:$E$1000,$A4)+COUNTIFS('20260427'!$C$2:$C$1000,D$1,'20260427'!$E$2:$E$1000,SUBSTITUTE($A4," "," "))+COUNTIFS('20260428'!$C$2:$C$1000,D$1,'20260428'!$E$2:$E$1000,$A4)+COUNTIFS('20260428'!$C$2:$C$1000,D$1,'20260428'!$E$2:$E$1000,SUBSTITUTE($A4," "," "))+COUNTIFS('20260430'!$C$2:$C$1000,D$1,'20260430'!$E$2:$E$1000,$A4)+COUNTIFS('20260430'!$C$2:$C$1000,D$1,'20260430'!$E$2:$E$1000,SUBSTITUTE($A4," "," ")) | E4: =SUM(B4:D4)
A5: 高梨 江里子 | B5: =COUNTIFS('20260401'!$C$2:$C$1000,B$1,'20260401'!$E$2:$E$1000,$A5)+COUNTIFS('20260401'!$C$2:$C$1000,B$1,'20260401'!$E$2:$E$1000,SUBSTITUTE($A5," "," "))+COUNTIFS('20260402'!$C$2:$C$1000,B$1,'20260402'!$E$2:$E$1000,$A5)+COUNTIFS('20260402'!$C$2:$C$1000,B$1,'20260402'!$E$2:$E$1000,SUBSTITUTE($A5," "," "))+COUNTIFS('20260403'!$C$2:$C$1000,B$1,'20260403'!$E$2:$E$1000,$A5)+COUNTIFS('20260403'!$C$2:$C$1000,B$1,'20260403'!$E$2:$E$1000,SUBSTITUTE($A5," "," "))+COUNTIFS('20260406'!$C$2:$C$1000,B$1,'20260406'!$E$2:$E$1000,$A5)+COUNTIFS('20260406'!$C$2:$C$1000,B$1,'20260406'!$E$2:$E$1000,SUBSTITUTE($A5," "," "))+COUNTIFS('20260407'!$C$2:$C$1000,B$1,'20260407'!$E$2:$E$1000,$A5)+COUNTIFS('20260407'!$C$2:$C$1000,B$1,'20260407'!$E$2:$E$1000,SUBSTITUTE($A5," "," "))+COUNTIFS('20260408'!$C$2:$C$1000,B$1,'20260408'!$E$2:$E$1000,$A5)+COUNTIFS('20260408'!$C$2:$C$1000,B$1,'20260408'!$E$2:$E$1000,SUBSTITUTE($A5," "," "))+COUNTIFS('20260409'!$C$2:$C$1000,B$1,'20260409'!$E$2:$E$1000,$A5)+COUNTIFS('20260409'!$C$2:$C$1000,B$1,'20260409'!$E$2:$E$1000,SUBSTITUTE($A5," "," "))+COUNTIFS('20260410'!$C$2:$C$1000,B$1,'20260410'!$E$2:$E$1000,$A5)+COUNTIFS('20260410'!$C$2:$C$1000,B$1,'20260410'!$E$2:$E$1000,SUBSTITUTE($A5," "," "))+COUNTIFS('20260413'!$C$2:$C$1000,B$1,'20260413'!$E$2:$E$1000,$A5)+COUNTIFS('20260413'!$C$2:$C$1000,B$1,'20260413'!$E$2:$E$1000,SUBSTITUTE($A5," "," "))+COUNTIFS('20260414'!$C$2:$C$1000,B$1,'20260414'!$E$2:$E$1000,$A5)+COUNTIFS('20260414'!$C$2:$C$1000,B$1,'20260414'!$E$2:$E$1000,SUBSTITUTE($A5," "," "))+COUNTIFS('20260415'!$C$2:$C$1000,B$1,'20260415'!$E$2:$E$1000,$A5)+COUNTIFS('20260415'!$C$2:$C$1000,B$1,'20260415'!$E$2:$E$1000,SUBSTITUTE($A5," "," "))+COUNTIFS('20260416'!$C$2:$C$1000,B$1,'20260416'!$E$2:$E$1000,$A5)+COUNTIFS('20260416'!$C$2:$C$1000,B$1,'20260416'!$E$2:$E$1000,SUBSTITUTE($A5," "," "))+COUNTIFS('20260417'!$C$2:$C$1000,B$1,'20260417'!$E$2:$E$1000,$A5)+COUNTIFS('20260417'!$C$2:$C$1000,B$1,'20260417'!$E$2:$E$1000,SUBSTITUTE($A5," "," "))+COUNTIFS('20260420'!$C$2:$C$1000,B$1,'20260420'!$E$2:$E$1000,$A5)+COUNTIFS('20260420'!$C$2:$C$1000,B$1,'20260420'!$E$2:$E$1000,SUBSTITUTE($A5," "," "))+COUNTIFS('20260421'!$C$2:$C$1000,B$1,'20260421'!$E$2:$E$1000,$A5)+COUNTIFS('20260421'!$C$2:$C$1000,B$1,'20260421'!$E$2:$E$1000,SUBSTITUTE($A5," "," "))+COUNTIFS('20260422'!$C$2:$C$1000,B$1,'20260422'!$E$2:$E$1000,$A5)+COUNTIFS('20260422'!$C$2:$C$1000,B$1,'20260422'!$E$2:$E$1000,SUBSTITUTE($A5," "," "))+COUNTIFS('20260423'!$C$2:$C$1000,B$1,'20260423'!$E$2:$E$1000,$A5)+COUNTIFS('20260423'!$C$2:$C$1000,B$1,'20260423'!$E$2:$E$1000,SUBSTITUTE($A5," "," "))+COUNTIFS('20260424'!$C$2:$C$1000,B$1,'20260424'!$E$2:$E$1000,$A5)+COUNTIFS('20260424'!$C$2:$C$1000,B$1,'20260424'!$E$2:$E$1000,SUBSTITUTE($A5," "," "))+COUNTIFS('20260427'!$C$2:$C$1000,B$1,'20260427'!$E$2:$E$1000,$A5)+COUNTIFS('20260427'!$C$2:$C$1000,B$1,'20260427'!$E$2:$E$1000,SUBSTITUTE($A5," "," "))+COUNTIFS('20260428'!$C$2:$C$1000,B$1,'20260428'!$E$2:$E$1000,$A5)+COUNTIFS('20260428'!$C$2:$C$1000,B$1,'20260428'!$E$2:$E$1000,SUBSTITUTE($A5," "," "))+COUNTIFS('20260430'!$C$2:$C$1000,B$1,'20260430'!$E$2:$E$1000,$A5)+COUNTIFS('20260430'!$C$2:$C$1000,B$1,'20260430'!$E$2:$E$1000,SUBSTITUTE($A5," "," ")) | C5: =COUNTIFS('20260401'!$C$2:$C$1000,C$1,'20260401'!$E$2:$E$1000,$A5)+COUNTIFS('20260401'!$C$2:$C$1000,C$1,'20260401'!$E$2:$E$1000,SUBSTITUTE($A5," "," "))+COUNTIFS('20260402'!$C$2:$C$1000,C$1,'20260402'!$E$2:$E$1000,$A5)+COUNTIFS('20260402'!$C$2:$C$1000,C$1,'20260402'!$E$2:$E$1000,SUBSTITUTE($A5," "," "))+COUNTIFS('20260403'!$C$2:$C$1000,C$1,'20260403'!$E$2:$E$1000,$A5)+COUNTIFS('20260403'!$C$2:$C$1000,C$1,'20260403'!$E$2:$E$1000,SUBSTITUTE($A5," "," "))+COUNTIFS('20260406'!$C$2:$C$1000,C$1,'20260406'!$E$2:$E$1000,$A5)+COUNTIFS('20260406'!$C$2:$C$1000,C$1,'20260406'!$E$2:$E$1000,SUBSTITUTE($A5," "," "))+COUNTIFS('20260407'!$C$2:$C$1000,C$1,'20260407'!$E$2:$E$1000,$A5)+COUNTIFS('20260407'!$C$2:$C$1000,C$1,'20260407'!$E$2:$E$1000,SUBSTITUTE($A5," "," "))+COUNTIFS('20260408'!$C$2:$C$1000,C$1,'20260408'!$E$2:$E$1000,$A5)+COUNTIFS('20260408'!$C$2:$C$1000,C$1,'20260408'!$E$2:$E$1000,SUBSTITUTE($A5," "," "))+COUNTIFS('20260409'!$C$2:$C$1000,C$1,'20260409'!$E$2:$E$1000,$A5)+COUNTIFS('20260409'!$C$2:$C$1000,C$1,'20260409'!$E$2:$E$1000,SUBSTITUTE($A5," "," "))+COUNTIFS('20260410'!$C$2:$C$1000,C$1,'20260410'!$E$2:$E$1000,$A5)+COUNTIFS('20260410'!$C$2:$C$1000,C$1,'20260410'!$E$2:$E$1000,SUBSTITUTE($A5," "," "))+COUNTIFS('20260413'!$C$2:$C$1000,C$1,'20260413'!$E$2:$E$1000,$A5)+COUNTIFS('20260413'!$C$2:$C$1000,C$1,'20260413'!$E$2:$E$1000,SUBSTITUTE($A5," "," "))+COUNTIFS('20260414'!$C$2:$C$1000,C$1,'20260414'!$E$2:$E$1000,$A5)+COUNTIFS('20260414'!$C$2:$C$1000,C$1,'20260414'!$E$2:$E$1000,SUBSTITUTE($A5," "," "))+COUNTIFS('20260415'!$C$2:$C$1000,C$1,'20260415'!$E$2:$E$1000,$A5)+COUNTIFS('20260415'!$C$2:$C$1000,C$1,'20260415'!$E$2:$E$1000,SUBSTITUTE($A5," "," "))+COUNTIFS('20260416'!$C$2:$C$1000,C$1,'20260416'!$E$2:$E$1000,$A5)+COUNTIFS('20260416'!$C$2:$C$1000,C$1,'20260416'!$E$2:$E$1000,SUBSTITUTE($A5," "," "))+COUNTIFS('20260417'!$C$2:$C$1000,C$1,'20260417'!$E$2:$E$1000,$A5)+COUNTIFS('20260417'!$C$2:$C$1000,C$1,'20260417'!$E$2:$E$1000,SUBSTITUTE($A5," "," "))+COUNTIFS('20260420'!$C$2:$C$1000,C$1,'20260420'!$E$2:$E$1000,$A5)+COUNTIFS('20260420'!$C$2:$C$1000,C$1,'20260420'!$E$2:$E$1000,SUBSTITUTE($A5," "," "))+COUNTIFS('20260421'!$C$2:$C$1000,C$1,'20260421'!$E$2:$E$1000,$A5)+COUNTIFS('20260421'!$C$2:$C$1000,C$1,'20260421'!$E$2:$E$1000,SUBSTITUTE($A5," "," "))+COUNTIFS('20260422'!$C$2:$C$1000,C$1,'20260422'!$E$2:$E$1000,$A5)+COUNTIFS('20260422'!$C$2:$C$1000,C$1,'20260422'!$E$2:$E$1000,SUBSTITUTE($A5," "," "))+COUNTIFS('20260423'!$C$2:$C$1000,C$1,'20260423'!$E$2:$E$1000,$A5)+COUNTIFS('20260423'!$C$2:$C$1000,C$1,'20260423'!$E$2:$E$1000,SUBSTITUTE($A5," "," "))+COUNTIFS('20260424'!$C$2:$C$1000,C$1,'20260424'!$E$2:$E$1000,$A5)+COUNTIFS('20260424'!$C$2:$C$1000,C$1,'20260424'!$E$2:$E$1000,SUBSTITUTE($A5," "," "))+COUNTIFS('20260427'!$C$2:$C$1000,C$1,'20260427'!$E$2:$E$1000,$A5)+COUNTIFS('20260427'!$C$2:$C$1000,C$1,'20260427'!$E$2:$E$1000,SUBSTITUTE($A5," "," "))+COUNTIFS('20260428'!$C$2:$C$1000,C$1,'20260428'!$E$2:$E$1000,$A5)+COUNTIFS('20260428'!$C$2:$C$1000,C$1,'20260428'!$E$2:$E$1000,SUBSTITUTE($A5," "," "))+COUNTIFS('20260430'!$C$2:$C$1000,C$1,'20260430'!$E$2:$E$1000,$A5)+COUNTIFS('20260430'!$C$2:$C$1000,C$1,'20260430'!$E$2:$E$1000,SUBSTITUTE($A5," "," ")) | D5: =COUNTIFS('20260401'!$C$2:$C$1000,D$1,'20260401'!$E$2:$E$1000,$A5)+COUNTIFS('20260401'!$C$2:$C$1000,D$1,'20260401'!$E$2:$E$1000,SUBSTITUTE($A5," "," "))+COUNTIFS('20260402'!$C$2:$C$1000,D$1,'20260402'!$E$2:$E$1000,$A5)+COUNTIFS('20260402'!$C$2:$C$1000,D$1,'20260402'!$E$2:$E$1000,SUBSTITUTE($A5," "," "))+COUNTIFS('20260403'!$C$2:$C$1000,D$1,'20260403'!$E$2:$E$1000,$A5)+COUNTIFS('20260403'!$C$2:$C$1000,D$1,'20260403'!$E$2:$E$1000,SUBSTITUTE($A5," "," "))+COUNTIFS('20260406'!$C$2:$C$1000,D$1,'20260406'!$E$2:$E$1000,$A5)+COUNTIFS('20260406'!$C$2:$C$1000,D$1,'20260406'!$E$2:$E$1000,SUBSTITUTE($A5," "," "))+COUNTIFS('20260407'!$C$2:$C$1000,D$1,'20260407'!$E$2:$E$1000,$A5)+COUNTIFS('20260407'!$C$2:$C$1000,D$1,'20260407'!$E$2:$E$1000,SUBSTITUTE($A5," "," "))+COUNTIFS('20260408'!$C$2:$C$1000,D$1,'20260408'!$E$2:$E$1000,$A5)+COUNTIFS('20260408'!$C$2:$C$1000,D$1,'20260408'!$E$2:$E$1000,SUBSTITUTE($A5," "," "))+COUNTIFS('20260409'!$C$2:$C$1000,D$1,'20260409'!$E$2:$E$1000,$A5)+COUNTIFS('20260409'!$C$2:$C$1000,D$1,'20260409'!$E$2:$E$1000,SUBSTITUTE($A5," "," "))+COUNTIFS('20260410'!$C$2:$C$1000,D$1,'20260410'!$E$2:$E$1000,$A5)+COUNTIFS('20260410'!$C$2:$C$1000,D$1,'20260410'!$E$2:$E$1000,SUBSTITUTE($A5," "," "))+COUNTIFS('20260413'!$C$2:$C$1000,D$1,'20260413'!$E$2:$E$1000,$A5)+COUNTIFS('20260413'!$C$2:$C$1000,D$1,'20260413'!$E$2:$E$1000,SUBSTITUTE($A5," "," "))+COUNTIFS('20260414'!$C$2:$C$1000,D$1,'20260414'!$E$2:$E$1000,$A5)+COUNTIFS('20260414'!$C$2:$C$1000,D$1,'20260414'!$E$2:$E$1000,SUBSTITUTE($A5," "," "))+COUNTIFS('20260415'!$C$2:$C$1000,D$1,'20260415'!$E$2:$E$1000,$A5)+COUNTIFS('20260415'!$C$2:$C$1000,D$1,'20260415'!$E$2:$E$1000,SUBSTITUTE($A5," "," "))+COUNTIFS('20260416'!$C$2:$C$1000,D$1,'20260416'!$E$2:$E$1000,$A5)+COUNTIFS('20260416'!$C$2:$C$1000,D$1,'20260416'!$E$2:$E$1000,SUBSTITUTE($A5," "," "))+COUNTIFS('20260417'!$C$2:$C$1000,D$1,'20260417'!$E$2:$E$1000,$A5)+COUNTIFS('20260417'!$C$2:$C$1000,D$1,'20260417'!$E$2:$E$1000,SUBSTITUTE($A5," "," "))+COUNTIFS('20260420'!$C$2:$C$1000,D$1,'20260420'!$E$2:$E$1000,$A5)+COUNTIFS('20260420'!$C$2:$C$1000,D$1,'20260420'!$E$2:$E$1000,SUBSTITUTE($A5," "," "))+COUNTIFS('20260421'!$C$2:$C$1000,D$1,'20260421'!$E$2:$E$1000,$A5)+COUNTIFS('20260421'!$C$2:$C$1000,D$1,'20260421'!$E$2:$E$1000,SUBSTITUTE($A5," "," "))+COUNTIFS('20260422'!$C$2:$C$1000,D$1,'20260422'!$E$2:$E$1000,$A5)+COUNTIFS('20260422'!$C$2:$C$1000,D$1,'20260422'!$E$2:$E$1000,SUBSTITUTE($A5," "," "))+COUNTIFS('20260423'!$C$2:$C$1000,D$1,'20260423'!$E$2:$E$1000,$A5)+COUNTIFS('20260423'!$C$2:$C$1000,D$1,'20260423'!$E$2:$E$1000,SUBSTITUTE($A5," "," "))+COUNTIFS('20260424'!$C$2:$C$1000,D$1,'20260424'!$E$2:$E$1000,$A5)+COUNTIFS('20260424'!$C$2:$C$1000,D$1,'20260424'!$E$2:$E$1000,SUBSTITUTE($A5," "," "))+COUNTIFS('20260427'!$C$2:$C$1000,D$1,'20260427'!$E$2:$E$1000,$A5)+COUNTIFS('20260427'!$C$2:$C$1000,D$1,'20260427'!$E$2:$E$1000,SUBSTITUTE($A5," "," "))+COUNTIFS('20260428'!$C$2:$C$1000,D$1,'20260428'!$E$2:$E$1000,$A5)+COUNTIFS('20260428'!$C$2:$C$1000,D$1,'20260428'!$E$2:$E$1000,SUBSTITUTE($A5," "," "))+COUNTIFS('20260430'!$C$2:$C$1000,D$1,'20260430'!$E$2:$E$1000,$A5)+COUNTIFS('20260430'!$C$2:$C$1000,D$1,'20260430'!$E$2:$E$1000,SUBSTITUTE($A5," "," ")) | E5: =SUM(B5:D5)
A6: 澤田 凌 | B6: =COUNTIFS('20260401'!$C$2:$C$1000,B$1,'20260401'!$E$2:$E$1000,$A6)+COUNTIFS('20260401'!$C$2:$C$1000,B$1,'20260401'!$E$2:$E$1000,SUBSTITUTE($A6," "," "))+COUNTIFS('20260402'!$C$2:$C$1000,B$1,'20260402'!$E$2:$E$1000,$A6)+COUNTIFS('20260402'!$C$2:$C$1000,B$1,'20260402'!$E$2:$E$1000,SUBSTITUTE($A6," "," "))+COUNTIFS('20260403'!$C$2:$C$1000,B$1,'20260403'!$E$2:$E$1000,$A6)+COUNTIFS('20260403'!$C$2:$C$1000,B$1,'20260403'!$E$2:$E$1000,SUBSTITUTE($A6," "," "))+COUNTIFS('20260406'!$C$2:$C$1000,B$1,'20260406'!$E$2:$E$1000,$A6)+COUNTIFS('20260406'!$C$2:$C$1000,B$1,'20260406'!$E$2:$E$1000,SUBSTITUTE($A6," "," "))+COUNTIFS('20260407'!$C$2:$C$1000,B$1,'20260407'!$E$2:$E$1000,$A6)+COUNTIFS('20260407'!$C$2:$C$1000,B$1,'20260407'!$E$2:$E$1000,SUBSTITUTE($A6," "," "))+COUNTIFS('20260408'!$C$2:$C$1000,B$1,'20260408'!$E$2:$E$1000,$A6)+COUNTIFS('20260408'!$C$2:$C$1000,B$1,'20260408'!$E$2:$E$1000,SUBSTITUTE($A6," "," "))+COUNTIFS('20260409'!$C$2:$C$1000,B$1,'20260409'!$E$2:$E$1000,$A6)+COUNTIFS('20260409'!$C$2:$C$1000,B$1,'20260409'!$E$2:$E$1000,SUBSTITUTE($A6," "," "))+COUNTIFS('20260410'!$C$2:$C$1000,B$1,'20260410'!$E$2:$E$1000,$A6)+COUNTIFS('20260410'!$C$2:$C$1000,B$1,'20260410'!$E$2:$E$1000,SUBSTITUTE($A6," "," "))+COUNTIFS('20260413'!$C$2:$C$1000,B$1,'20260413'!$E$2:$E$1000,$A6)+COUNTIFS('20260413'!$C$2:$C$1000,B$1,'20260413'!$E$2:$E$1000,SUBSTITUTE($A6," "," "))+COUNTIFS('20260414'!$C$2:$C$1000,B$1,'20260414'!$E$2:$E$1000,$A6)+COUNTIFS('20260414'!$C$2:$C$1000,B$1,'20260414'!$E$2:$E$1000,SUBSTITUTE($A6," "," "))+COUNTIFS('20260415'!$C$2:$C$1000,B$1,'20260415'!$E$2:$E$1000,$A6)+COUNTIFS('20260415'!$C$2:$C$1000,B$1,'20260415'!$E$2:$E$1000,SUBSTITUTE($A6," "," "))+COUNTIFS('20260416'!$C$2:$C$1000,B$1,'20260416'!$E$2:$E$1000,$A6)+COUNTIFS('20260416'!$C$2:$C$1000,B$1,'20260416'!$E$2:$E$1000,SUBSTITUTE($A6," "," "))+COUNTIFS('20260417'!$C$2:$C$1000,B$1,'20260417'!$E$2:$E$1000,$A6)+COUNTIFS('20260417'!$C$2:$C$1000,B$1,'20260417'!$E$2:$E$1000,SUBSTITUTE($A6," "," "))+COUNTIFS('20260420'!$C$2:$C$1000,B$1,'20260420'!$E$2:$E$1000,$A6)+COUNTIFS('20260420'!$C$2:$C$1000,B$1,'20260420'!$E$2:$E$1000,SUBSTITUTE($A6," "," "))+COUNTIFS('20260421'!$C$2:$C$1000,B$1,'20260421'!$E$2:$E$1000,$A6)+COUNTIFS('20260421'!$C$2:$C$1000,B$1,'20260421'!$E$2:$E$1000,SUBSTITUTE($A6," "," "))+COUNTIFS('20260422'!$C$2:$C$1000,B$1,'20260422'!$E$2:$E$1000,$A6)+COUNTIFS('20260422'!$C$2:$C$1000,B$1,'20260422'!$E$2:$E$1000,SUBSTITUTE($A6," "," "))+COUNTIFS('20260423'!$C$2:$C$1000,B$1,'20260423'!$E$2:$E$1000,$A6)+COUNTIFS('20260423'!$C$2:$C$1000,B$1,'20260423'!$E$2:$E$1000,SUBSTITUTE($A6," "," "))+COUNTIFS('20260424'!$C$2:$C$1000,B$1,'20260424'!$E$2:$E$1000,$A6)+COUNTIFS('20260424'!$C$2:$C$1000,B$1,'20260424'!$E$2:$E$1000,SUBSTITUTE($A6," "," "))+COUNTIFS('20260427'!$C$2:$C$1000,B$1,'20260427'!$E$2:$E$1000,$A6)+COUNTIFS('20260427'!$C$2:$C$1000,B$1,'20260427'!$E$2:$E$1000,SUBSTITUTE($A6," "," "))+COUNTIFS('20260428'!$C$2:$C$1000,B$1,'20260428'!$E$2:$E$1000,$A6)+COUNTIFS('20260428'!$C$2:$C$1000,B$1,'20260428'!$E$2:$E$1000,SUBSTITUTE($A6," "," "))+COUNTIFS('20260430'!$C$2:$C$1000,B$1,'20260430'!$E$2:$E$1000,$A6)+COUNTIFS('20260430'!$C$2:$C$1000,B$1,'20260430'!$E$2:$E$1000,SUBSTITUTE($A6," "," ")) | C6: =COUNTIFS('20260401'!$C$2:$C$1000,C$1,'20260401'!$E$2:$E$1000,$A6)+COUNTIFS('20260401'!$C$2:$C$1000,C$1,'20260401'!$E$2:$E$1000,SUBSTITUTE($A6," "," "))+COUNTIFS('20260402'!$C$2:$C$1000,C$1,'20260402'!$E$2:$E$1000,$A6)+COUNTIFS('20260402'!$C$2:$C$1000,C$1,'20260402'!$E$2:$E$1000,SUBSTITUTE($A6," "," "))+COUNTIFS('20260403'!$C$2:$C$1000,C$1,'20260403'!$E$2:$E$1000,$A6)+COUNTIFS('20260403'!$C$2:$C$1000,C$1,'20260403'!$E$2:$E$1000,SUBSTITUTE($A6," "," "))+COUNTIFS('20260406'!$C$2:$C$1000,C$1,'20260406'!$E$2:$E$1000,$A6)+COUNTIFS('20260406'!$C$2:$C$1000,C$1,'20260406'!$E$2:$E$1000,SUBSTITUTE($A6," "," "))+COUNTIFS('20260407'!$C$2:$C$1000,C$1,'20260407'!$E$2:$E$1000,$A6)+COUNTIFS('20260407'!$C$2:$C$1000,C$1,'20260407'!$E$2:$E$1000,SUBSTITUTE($A6," "," "))+COUNTIFS('20260408'!$C$2:$C$1000,C$1,'20260408'!$E$2:$E$1000,$A6)+COUNTIFS('20260408'!$C$2:$C$1000,C$1,'20260408'!$E$2:$E$1000,SUBSTITUTE($A6," "," "))+COUNTIFS('20260409'!$C$2:$C$1000,C$1,'20260409'!$E$2:$E$1000,$A6)+COUNTIFS('20260409'!$C$2:$C$1000,C$1,'20260409'!$E$2:$E$1000,SUBSTITUTE($A6," "," "))+COUNTIFS('20260410'!$C$2:$C$1000,C$1,'20260410'!$E$2:$E$1000,$A6)+COUNTIFS('20260410'!$C$2:$C$1000,C$1,'20260410'!$E$2:$E$1000,SUBSTITUTE($A6," "," "))+COUNTIFS('20260413'!$C$2:$C$1000,C$1,'20260413'!$E$2:$E$1000,$A6)+COUNTIFS('20260413'!$C$2:$C$1000,C$1,'20260413'!$E$2:$E$1000,SUBSTITUTE($A6," "," "))+COUNTIFS('20260414'!$C$2:$C$1000,C$1,'20260414'!$E$2:$E$1000,$A6)+COUNTIFS('20260414'!$C$2:$C$1000,C$1,'20260414'!$E$2:$E$1000,SUBSTITUTE($A6," "," "))+COUNTIFS('20260415'!$C$2:$C$1000,C$1,'20260415'!$E$2:$E$1000,$A6)+COUNTIFS('20260415'!$C$2:$C$1000,C$1,'20260415'!$E$2:$E$1000,SUBSTITUTE($A6," "," "))+COUNTIFS('20260416'!$C$2:$C$1000,C$1,'20260416'!$E$2:$E$1000,$A6)+COUNTIFS('20260416'!$C$2:$C$1000,C$1,'20260416'!$E$2:$E$1000,SUBSTITUTE($A6," "," "))+COUNTIFS('20260417'!$C$2:$C$1000,C$1,'20260417'!$E$2:$E$1000,$A6)+COUNTIFS('20260417'!$C$2:$C$1000,C$1,'20260417'!$E$2:$E$1000,SUBSTITUTE($A6," "," "))+COUNTIFS('20260420'!$C$2:$C$1000,C$1,'20260420'!$E$2:$E$1000,$A6)+COUNTIFS('20260420'!$C$2:$C$1000,C$1,'20260420'!$E$2:$E$1000,SUBSTITUTE($A6," "," "))+COUNTIFS('20260421'!$C$2:$C$1000,C$1,'20260421'!$E$2:$E$1000,$A6)+COUNTIFS('20260421'!$C$2:$C$1000,C$1,'20260421'!$E$2:$E$1000,SUBSTITUTE($A6," "," "))+COUNTIFS('20260422'!$C$2:$C$1000,C$1,'20260422'!$E$2:$E$1000,$A6)+COUNTIFS('20260422'!$C$2:$C$1000,C$1,'20260422'!$E$2:$E$1000,SUBSTITUTE($A6," "," "))+COUNTIFS('20260423'!$C$2:$C$1000,C$1,'20260423'!$E$2:$E$1000,$A6)+COUNTIFS('20260423'!$C$2:$C$1000,C$1,'20260423'!$E$2:$E$1000,SUBSTITUTE($A6," "," "))+COUNTIFS('20260424'!$C$2:$C$1000,C$1,'20260424'!$E$2:$E$1000,$A6)+COUNTIFS('20260424'!$C$2:$C$1000,C$1,'20260424'!$E$2:$E$1000,SUBSTITUTE($A6," "," "))+COUNTIFS('20260427'!$C$2:$C$1000,C$1,'20260427'!$E$2:$E$1000,$A6)+COUNTIFS('20260427'!$C$2:$C$1000,C$1,'20260427'!$E$2:$E$1000,SUBSTITUTE($A6," "," "))+COUNTIFS('20260428'!$C$2:$C$1000,C$1,'20260428'!$E$2:$E$1000,$A6)+COUNTIFS('20260428'!$C$2:$C$1000,C$1,'20260428'!$E$2:$E$1000,SUBSTITUTE($A6," "," "))+COUNTIFS('20260430'!$C$2:$C$1000,C$1,'20260430'!$E$2:$E$1000,$A6)+COUNTIFS('20260430'!$C$2:$C$1000,C$1,'20260430'!$E$2:$E$1000,SUBSTITUTE($A6," "," ")) | D6: =COUNTIFS('20260401'!$C$2:$C$1000,D$1,'20260401'!$E$2:$E$1000,$A6)+COUNTIFS('20260401'!$C$2:$C$1000,D$1,'20260401'!$E$2:$E$1000,SUBSTITUTE($A6," "," "))+COUNTIFS('20260402'!$C$2:$C$1000,D$1,'20260402'!$E$2:$E$1000,$A6)+COUNTIFS('20260402'!$C$2:$C$1000,D$1,'20260402'!$E$2:$E$1000,SUBSTITUTE($A6," "," "))+COUNTIFS('20260403'!$C$2:$C$1000,D$1,'20260403'!$E$2:$E$1000,$A6)+COUNTIFS('20260403'!$C$2:$C$1000,D$1,'20260403'!$E$2:$E$1000,SUBSTITUTE($A6," "," "))+COUNTIFS('20260406'!$C$2:$C$1000,D$1,'20260406'!$E$2:$E$1000,$A6)+COUNTIFS('20260406'!$C$2:$C$1000,D$1,'20260406'!$E$2:$E$1000,SUBSTITUTE($A6," "," "))+COUNTIFS('20260407'!$C$2:$C$1000,D$1,'20260407'!$E$2:$E$1000,$A6)+COUNTIFS('20260407'!$C$2:$C$1000,D$1,'20260407'!$E$2:$E$1000,SUBSTITUTE($A6," "," "))+COUNTIFS('20260408'!$C$2:$C$1000,D$1,'20260408'!$E$2:$E$1000,$A6)+COUNTIFS('20260408'!$C$2:$C$1000,D$1,'20260408'!$E$2:$E$1000,SUBSTITUTE($A6," "," "))+COUNTIFS('20260409'!$C$2:$C$1000,D$1,'20260409'!$E$2:$E$1000,$A6)+COUNTIFS('20260409'!$C$2:$C$1000,D$1,'20260409'!$E$2:$E$1000,SUBSTITUTE($A6," "," "))+COUNTIFS('20260410'!$C$2:$C$1000,D$1,'20260410'!$E$2:$E$1000,$A6)+COUNTIFS('20260410'!$C$2:$C$1000,D$1,'20260410'!$E$2:$E$1000,SUBSTITUTE($A6," "," "))+COUNTIFS('20260413'!$C$2:$C$1000,D$1,'20260413'!$E$2:$E$1000,$A6)+COUNTIFS('20260413'!$C$2:$C$1000,D$1,'20260413'!$E$2:$E$1000,SUBSTITUTE($A6," "," "))+COUNTIFS('20260414'!$C$2:$C$1000,D$1,'20260414'!$E$2:$E$1000,$A6)+COUNTIFS('20260414'!$C$2:$C$1000,D$1,'20260414'!$E$2:$E$1000,SUBSTITUTE($A6," "," "))+COUNTIFS('20260415'!$C$2:$C$1000,D$1,'20260415'!$E$2:$E$1000,$A6)+COUNTIFS('20260415'!$C$2:$C$1000,D$1,'20260415'!$E$2:$E$1000,SUBSTITUTE($A6," "," "))+COUNTIFS('20260416'!$C$2:$C$1000,D$1,'20260416'!$E$2:$E$1000,$A6)+COUNTIFS('20260416'!$C$2:$C$1000,D$1,'20260416'!$E$2:$E$1000,SUBSTITUTE($A6," "," "))+COUNTIFS('20260417'!$C$2:$C$1000,D$1,'20260417'!$E$2:$E$1000,$A6)+COUNTIFS('20260417'!$C$2:$C$1000,D$1,'20260417'!$E$2:$E$1000,SUBSTITUTE($A6," "," "))+COUNTIFS('20260420'!$C$2:$C$1000,D$1,'20260420'!$E$2:$E$1000,$A6)+COUNTIFS('20260420'!$C$2:$C$1000,D$1,'20260420'!$E$2:$E$1000,SUBSTITUTE($A6," "," "))+COUNTIFS('20260421'!$C$2:$C$1000,D$1,'20260421'!$E$2:$E$1000,$A6)+COUNTIFS('20260421'!$C$2:$C$1000,D$1,'20260421'!$E$2:$E$1000,SUBSTITUTE($A6," "," "))+COUNTIFS('20260422'!$C$2:$C$1000,D$1,'20260422'!$E$2:$E$1000,$A6)+COUNTIFS('20260422'!$C$2:$C$1000,D$1,'20260422'!$E$2:$E$1000,SUBSTITUTE($A6," "," "))+COUNTIFS('20260423'!$C$2:$C$1000,D$1,'20260423'!$E$2:$E$1000,$A6)+COUNTIFS('20260423'!$C$2:$C$1000,D$1,'20260423'!$E$2:$E$1000,SUBSTITUTE($A6," "," "))+COUNTIFS('20260424'!$C$2:$C$1000,D$1,'20260424'!$E$2:$E$1000,$A6)+COUNTIFS('20260424'!$C$2:$C$1000,D$1,'20260424'!$E$2:$E$1000,SUBSTITUTE($A6," "," "))+COUNTIFS('20260427'!$C$2:$C$1000,D$1,'20260427'!$E$2:$E$1000,$A6)+COUNTIFS('20260427'!$C$2:$C$1000,D$1,'20260427'!$E$2:$E$1000,SUBSTITUTE($A6," "," "))+COUNTIFS('20260428'!$C$2:$C$1000,D$1,'20260428'!$E$2:$E$1000,$A6)+COUNTIFS('20260428'!$C$2:$C$1000,D$1,'20260428'!$E$2:$E$1000,SUBSTITUTE($A6," "," "))+COUNTIFS('20260430'!$C$2:$C$1000,D$1,'20260430'!$E$2:$E$1000,$A6)+COUNTIFS('20260430'!$C$2:$C$1000,D$1,'20260430'!$E$2:$E$1000,SUBSTITUTE($A6," "," ")) | E6: =SUM(B6:D6)
A7: 佐々木 千恵 | B7: =COUNTIFS('20260401'!$C$2:$C$1000,B$1,'20260401'!$E$2:$E$1000,$A7)+COUNTIFS('20260401'!$C$2:$C$1000,B$1,'20260401'!$E$2:$E$1000,SUBSTITUTE($A7," "," "))+COUNTIFS('20260402'!$C$2:$C$1000,B$1,'20260402'!$E$2:$E$1000,$A7)+COUNTIFS('20260402'!$C$2:$C$1000,B$1,'20260402'!$E$2:$E$1000,SUBSTITUTE($A7," "," "))+COUNTIFS('20260403'!$C$2:$C$1000,B$1,'20260403'!$E$2:$E$1000,$A7)+COUNTIFS('20260403'!$C$2:$C$1000,B$1,'20260403'!$E$2:$E$1000,SUBSTITUTE($A7," "," "))+COUNTIFS('20260406'!$C$2:$C$1000,B$1,'20260406'!$E$2:$E$1000,$A7)+COUNTIFS('20260406'!$C$2:$C$1000,B$1,'20260406'!$E$2:$E$1000,SUBSTITUTE($A7," "," "))+COUNTIFS('20260407'!$C$2:$C$1000,B$1,'20260407'!$E$2:$E$1000,$A7)+COUNTIFS('20260407'!$C$2:$C$1000,B$1,'20260407'!$E$2:$E$1000,SUBSTITUTE($A7," "," "))+COUNTIFS('20260408'!$C$2:$C$1000,B$1,'20260408'!$E$2:$E$1000,$A7)+COUNTIFS('20260408'!$C$2:$C$1000,B$1,'20260408'!$E$2:$E$1000,SUBSTITUTE($A7," "," "))+COUNTIFS('20260409'!$C$2:$C$1000,B$1,'20260409'!$E$2:$E$1000,$A7)+COUNTIFS('20260409'!$C$2:$C$1000,B$1,'20260409'!$E$2:$E$1000,SUBSTITUTE($A7," "," "))+COUNTIFS('20260410'!$C$2:$C$1000,B$1,'20260410'!$E$2:$E$1000,$A7)+COUNTIFS('20260410'!$C$2:$C$1000,B$1,'20260410'!$E$2:$E$1000,SUBSTITUTE($A7," "," "))+COUNTIFS('20260413'!$C$2:$C$1000,B$1,'20260413'!$E$2:$E$1000,$A7)+COUNTIFS('20260413'!$C$2:$C$1000,B$1,'20260413'!$E$2:$E$1000,SUBSTITUTE($A7," "," "))+COUNTIFS('20260414'!$C$2:$C$1000,B$1,'20260414'!$E$2:$E$1000,$A7)+COUNTIFS('20260414'!$C$2:$C$1000,B$1,'20260414'!$E$2:$E$1000,SUBSTITUTE($A7," "," "))+COUNTIFS('20260415'!$C$2:$C$1000,B$1,'20260415'!$E$2:$E$1000,$A7)+COUNTIFS('20260415'!$C$2:$C$1000,B$1,'20260415'!$E$2:$E$1000,SUBSTITUTE($A7," "," "))+COUNTIFS('20260416'!$C$2:$C$1000,B$1,'20260416'!$E$2:$E$1000,$A7)+COUNTIFS('20260416'!$C$2:$C$1000,B$1,'20260416'!$E$2:$E$1000,SUBSTITUTE($A7," "," "))+COUNTIFS('20260417'!$C$2:$C$1000,B$1,'20260417'!$E$2:$E$1000,$A7)+COUNTIFS('20260417'!$C$2:$C$1000,B$1,'20260417'!$E$2:$E$1000,SUBSTITUTE($A7," "," "))+COUNTIFS('20260420'!$C$2:$C$1000,B$1,'20260420'!$E$2:$E$1000,$A7)+COUNTIFS('20260420'!$C$2:$C$1000,B$1,'20260420'!$E$2:$E$1000,SUBSTITUTE($A7," "," "))+COUNTIFS('20260421'!$C$2:$C$1000,B$1,'20260421'!$E$2:$E$1000,$A7)+COUNTIFS('20260421'!$C$2:$C$1000,B$1,'20260421'!$E$2:$E$1000,SUBSTITUTE($A7," "," "))+COUNTIFS('20260422'!$C$2:$C$1000,B$1,'20260422'!$E$2:$E$1000,$A7)+COUNTIFS('20260422'!$C$2:$C$1000,B$1,'20260422'!$E$2:$E$1000,SUBSTITUTE($A7," "," "))+COUNTIFS('20260423'!$C$2:$C$1000,B$1,'20260423'!$E$2:$E$1000,$A7)+COUNTIFS('20260423'!$C$2:$C$1000,B$1,'20260423'!$E$2:$E$1000,SUBSTITUTE($A7," "," "))+COUNTIFS('20260424'!$C$2:$C$1000,B$1,'20260424'!$E$2:$E$1000,$A7)+COUNTIFS('20260424'!$C$2:$C$1000,B$1,'20260424'!$E$2:$E$1000,SUBSTITUTE($A7," "," "))+COUNTIFS('20260427'!$C$2:$C$1000,B$1,'20260427'!$E$2:$E$1000,$A7)+COUNTIFS('20260427'!$C$2:$C$1000,B$1,'20260427'!$E$2:$E$1000,SUBSTITUTE($A7," "," "))+COUNTIFS('20260428'!$C$2:$C$1000,B$1,'20260428'!$E$2:$E$1000,$A7)+COUNTIFS('20260428'!$C$2:$C$1000,B$1,'20260428'!$E$2:$E$1000,SUBSTITUTE($A7," "," "))+COUNTIFS('20260430'!$C$2:$C$1000,B$1,'20260430'!$E$2:$E$1000,$A7)+COUNTIFS('20260430'!$C$2:$C$1000,B$1,'20260430'!$E$2:$E$1000,SUBSTITUTE($A7," "," ")) | C7: =COUNTIFS('20260401'!$C$2:$C$1000,C$1,'20260401'!$E$2:$E$1000,$A7)+COUNTIFS('20260401'!$C$2:$C$1000,C$1,'20260401'!$E$2:$E$1000,SUBSTITUTE($A7," "," "))+COUNTIFS('20260402'!$C$2:$C$1000,C$1,'20260402'!$E$2:$E$1000,$A7)+COUNTIFS('20260402'!$C$2:$C$1000,C$1,'20260402'!$E$2:$E$1000,SUBSTITUTE($A7," "," "))+COUNTIFS('20260403'!$C$2:$C$1000,C$1,'20260403'!$E$2:$E$1000,$A7)+COUNTIFS('20260403'!$C$2:$C$1000,C$1,'20260403'!$E$2:$E$1000,SUBSTITUTE($A7," "," "))+COUNTIFS('20260406'!$C$2:$C$1000,C$1,'20260406'!$E$2:$E$1000,$A7)+COUNTIFS('20260406'!$C$2:$C$1000,C$1,'20260406'!$E$2:$E$1000,SUBSTITUTE($A7," "," "))+COUNTIFS('20260407'!$C$2:$C$1000,C$1,'20260407'!$E$2:$E$1000,$A7)+COUNTIFS('20260407'!$C$2:$C$1000,C$1,'20260407'!$E$2:$E$1000,SUBSTITUTE($A7," "," "))+COUNTIFS('20260408'!$C$2:$C$1000,C$1,'20260408'!$E$2:$E$1000,$A7)+COUNTIFS('20260408'!$C$2:$C$1000,C$1,'20260408'!$E$2:$E$1000,SUBSTITUTE($A7," "," "))+COUNTIFS('20260409'!$C$2:$C$1000,C$1,'20260409'!$E$2:$E$1000,$A7)+COUNTIFS('20260409'!$C$2:$C$1000,C$1,'20260409'!$E$2:$E$1000,SUBSTITUTE($A7," "," "))+COUNTIFS('20260410'!$C$2:$C$1000,C$1,'20260410'!$E$2:$E$1000,$A7)+COUNTIFS('20260410'!$C$2:$C$1000,C$1,'20260410'!$E$2:$E$1000,SUBSTITUTE($A7," "," "))+COUNTIFS('20260413'!$C$2:$C$1000,C$1,'20260413'!$E$2:$E$1000,$A7)+COUNTIFS('20260413'!$C$2:$C$1000,C$1,'20260413'!$E$2:$E$1000,SUBSTITUTE($A7," "," "))+COUNTIFS('20260414'!$C$2:$C$1000,C$1,'20260414'!$E$2:$E$1000,$A7)+COUNTIFS('20260414'!$C$2:$C$1000,C$1,'20260414'!$E$2:$E$1000,SUBSTITUTE($A7," "," "))+COUNTIFS('20260415'!$C$2:$C$1000,C$1,'20260415'!$E$2:$E$1000,$A7)+COUNTIFS('20260415'!$C$2:$C$1000,C$1,'20260415'!$E$2:$E$1000,SUBSTITUTE($A7," "," "))+COUNTIFS('20260416'!$C$2:$C$1000,C$1,'20260416'!$E$2:$E$1000,$A7)+COUNTIFS('20260416'!$C$2:$C$1000,C$1,'20260416'!$E$2:$E$1000,SUBSTITUTE($A7," "," "))+COUNTIFS('20260417'!$C$2:$C$1000,C$1,'20260417'!$E$2:$E$1000,$A7)+COUNTIFS('20260417'!$C$2:$C$1000,C$1,'20260417'!$E$2:$E$1000,SUBSTITUTE($A7," "," "))+COUNTIFS('20260420'!$C$2:$C$1000,C$1,'20260420'!$E$2:$E$1000,$A7)+COUNTIFS('20260420'!$C$2:$C$1000,C$1,'20260420'!$E$2:$E$1000,SUBSTITUTE($A7," "," "))+COUNTIFS('20260421'!$C$2:$C$1000,C$1,'20260421'!$E$2:$E$1000,$A7)+COUNTIFS('20260421'!$C$2:$C$1000,C$1,'20260421'!$E$2:$E$1000,SUBSTITUTE($A7," "," "))+COUNTIFS('20260422'!$C$2:$C$1000,C$1,'20260422'!$E$2:$E$1000,$A7)+COUNTIFS('20260422'!$C$2:$C$1000,C$1,'20260422'!$E$2:$E$1000,SUBSTITUTE($A7," "," "))+COUNTIFS('20260423'!$C$2:$C$1000,C$1,'20260423'!$E$2:$E$1000,$A7)+COUNTIFS('20260423'!$C$2:$C$1000,C$1,'20260423'!$E$2:$E$1000,SUBSTITUTE($A7," "," "))+COUNTIFS('20260424'!$C$2:$C$1000,C$1,'20260424'!$E$2:$E$1000,$A7)+COUNTIFS('20260424'!$C$2:$C$1000,C$1,'20260424'!$E$2:$E$1000,SUBSTITUTE($A7," "," "))+COUNTIFS('20260427'!$C$2:$C$1000,C$1,'20260427'!$E$2:$E$1000,$A7)+COUNTIFS('20260427'!$C$2:$C$1000,C$1,'20260427'!$E$2:$E$1000,SUBSTITUTE($A7," "," "))+COUNTIFS('20260428'!$C$2:$C$1000,C$1,'20260428'!$E$2:$E$1000,$A7)+COUNTIFS('20260428'!$C$2:$C$1000,C$1,'20260428'!$E$2:$E$1000,SUBSTITUTE($A7," "," "))+COUNTIFS('20260430'!$C$2:$C$1000,C$1,'20260430'!$E$2:$E$1000,$A7)+COUNTIFS('20260430'!$C$2:$C$1000,C$1,'20260430'!$E$2:$E$1000,SUBSTITUTE($A7," "," ")) | D7: =COUNTIFS('20260401'!$C$2:$C$1000,D$1,'20260401'!$E$2:$E$1000,$A7)+COUNTIFS('20260401'!$C$2:$C$1000,D$1,'20260401'!$E$2:$E$1000,SUBSTITUTE($A7," "," "))+COUNTIFS('20260402'!$C$2:$C$1000,D$1,'20260402'!$E$2:$E$1000,$A7)+COUNTIFS('20260402'!$C$2:$C$1000,D$1,'20260402'!$E$2:$E$1000,SUBSTITUTE($A7," "," "))+COUNTIFS('20260403'!$C$2:$C$1000,D$1,'20260403'!$E$2:$E$1000,$A7)+COUNTIFS('20260403'!$C$2:$C$1000,D$1,'20260403'!$E$2:$E$1000,SUBSTITUTE($A7," "," "))+COUNTIFS('20260406'!$C$2:$C$1000,D$1,'20260406'!$E$2:$E$1000,$A7)+COUNTIFS('20260406'!$C$2:$C$1000,D$1,'20260406'!$E$2:$E$1000,SUBSTITUTE($A7," "," "))+COUNTIFS('20260407'!$C$2:$C$1000,D$1,'20260407'!$E$2:$E$1000,$A7)+COUNTIFS('20260407'!$C$2:$C$1000,D$1,'20260407'!$E$2:$E$1000,SUBSTITUTE($A7," "," "))+COUNTIFS('20260408'!$C$2:$C$1000,D$1,'20260408'!$E$2:$E$1000,$A7)+COUNTIFS('20260408'!$C$2:$C$1000,D$1,'20260408'!$E$2:$E$1000,SUBSTITUTE($A7," "," "))+COUNTIFS('20260409'!$C$2:$C$1000,D$1,'20260409'!$E$2:$E$1000,$A7)+COUNTIFS('20260409'!$C$2:$C$1000,D$1,'20260409'!$E$2:$E$1000,SUBSTITUTE($A7," "," "))+COUNTIFS('20260410'!$C$2:$C$1000,D$1,'20260410'!$E$2:$E$1000,$A7)+COUNTIFS('20260410'!$C$2:$C$1000,D$1,'20260410'!$E$2:$E$1000,SUBSTITUTE($A7," "," "))+COUNTIFS('20260413'!$C$2:$C$1000,D$1,'20260413'!$E$2:$E$1000,$A7)+COUNTIFS('20260413'!$C$2:$C$1000,D$1,'20260413'!$E$2:$E$1000,SUBSTITUTE($A7," "," "))+COUNTIFS('20260414'!$C$2:$C$1000,D$1,'20260414'!$E$2:$E$1000,$A7)+COUNTIFS('20260414'!$C$2:$C$1000,D$1,'20260414'!$E$2:$E$1000,SUBSTITUTE($A7," "," "))+COUNTIFS('20260415'!$C$2:$C$1000,D$1,'20260415'!$E$2:$E$1000,$A7)+COUNTIFS('20260415'!$C$2:$C$1000,D$1,'20260415'!$E$2:$E$1000,SUBSTITUTE($A7," "," "))+COUNTIFS('20260416'!$C$2:$C$1000,D$1,'20260416'!$E$2:$E$1000,$A7)+COUNTIFS('20260416'!$C$2:$C$1000,D$1,'20260416'!$E$2:$E$1000,SUBSTITUTE($A7," "," "))+COUNTIFS('20260417'!$C$2:$C$1000,D$1,'20260417'!$E$2:$E$1000,$A7)+COUNTIFS('20260417'!$C$2:$C$1000,D$1,'20260417'!$E$2:$E$1000,SUBSTITUTE($A7," "," "))+COUNTIFS('20260420'!$C$2:$C$1000,D$1,'20260420'!$E$2:$E$1000,$A7)+COUNTIFS('20260420'!$C$2:$C$1000,D$1,'20260420'!$E$2:$E$1000,SUBSTITUTE($A7," "," "))+COUNTIFS('20260421'!$C$2:$C$1000,D$1,'20260421'!$E$2:$E$1000,$A7)+COUNTIFS('20260421'!$C$2:$C$1000,D$1,'20260421'!$E$2:$E$1000,SUBSTITUTE($A7," "," "))+COUNTIFS('20260422'!$C$2:$C$1000,D$1,'20260422'!$E$2:$E$1000,$A7)+COUNTIFS('20260422'!$C$2:$C$1000,D$1,'20260422'!$E$2:$E$1000,SUBSTITUTE($A7," "," "))+COUNTIFS('20260423'!$C$2:$C$1000,D$1,'20260423'!$E$2:$E$1000,$A7)+COUNTIFS('20260423'!$C$2:$C$1000,D$1,'20260423'!$E$2:$E$1000,SUBSTITUTE($A7," "," "))+COUNTIFS('20260424'!$C$2:$C$1000,D$1,'20260424'!$E$2:$E$1000,$A7)+COUNTIFS('20260424'!$C$2:$C$1000,D$1,'20260424'!$E$2:$E$1000,SUBSTITUTE($A7," "," "))+COUNTIFS('20260427'!$C$2:$C$1000,D$1,'20260427'!$E$2:$E$1000,$A7)+COUNTIFS('20260427'!$C$2:$C$1000,D$1,'20260427'!$E$2:$E$1000,SUBSTITUTE($A7," "," "))+COUNTIFS('20260428'!$C$2:$C$1000,D$1,'20260428'!$E$2:$E$1000,$A7)+COUNTIFS('20260428'!$C$2:$C$1000,D$1,'20260428'!$E$2:$E$1000,SUBSTITUTE($A7," "," "))+COUNTIFS('20260430'!$C$2:$C$1000,D$1,'20260430'!$E$2:$E$1000,$A7)+COUNTIFS('20260430'!$C$2:$C$1000,D$1,'20260430'!$E$2:$E$1000,SUBSTITUTE($A7," "," ")) | E7: =SUM(B7:D7)
